Workbook

Sheet Introduction
D8: RESULT PROCESSING SYSTEM Developed by ALI HOSSAIN
D9: BSc. in Computer Science & Enginnering, University of Chittagong
D10: Lecturer in Information & Communication Technology, Bamni Degree College

Sheet Inputs
A2: Title of Exam | C2: First Year - Term Exam 2024
A4: Number of Science Students
A6: Number of Commerce Students
A8: Number of Arts Students
A10: Total Number of Students | C10: =C4+C6+C8 -> 0
A12: MCQ Mark | C12: 25
A14: CQ Mark | C14: 50
A16: Practical Mark | C16: 25
A18: Total Marks | C18: =C12+C14+C16 -> 100

Sheet Sheet1
A1: Group | B1: Roll | C1: Subject1 | D1: Subject2 | E1: Subject3 | F1: Subject4
A2: Science | B2: 701
A3: Science | B3: 702
A4: Science | B4: 703
A5: Science | B5: 704
A6: Science | B6: 705
A7: Science | B7: 706
A8: Science | B8: 707
A9: Science | B9: 708
A10: Science | B10: 709
A11: Science | B11: 710
A12: Commerce
A13: Commerce
A14: Commerce
A15: Commerce
A16: Commerce
A17: Arts
A18: Arts
A19: Arts
A20: Arts
A21: Arts

Sheet Student Basic Info
A1: ID | B1: Group | C1: Name | D1: Father | E1: Mother | F1: Gender | G1: Religion | H1: Address | I1: Contact | J1: Session | K1: Remarks
A2: 101 | B2: Humanities | C2: Sazzad Hossain | D2: Sana Ullah | E2: Jesmin Aktar | F2: Male | G2: Islam | H2: Bamni Bank Road, Companiganj, Noakhali | I2: 1837251716 | J2: 2023-24
A3: 102 | B3: Humanities | C3: Bibi Marium | D3: Kamal Hossain | E3: Osima Begum | F3: Female | G3: Islam | H3: Bamni Bank Road, Companiganj, Noakhali | I3: 1822723930 | J3: 2023-24
A4: 103 | B4: Humanities | C4: Razib Hossain Raju | D4: Kamal Uddin | E4: Zahanara Begum | F4: Male | G4: Islam | H4: Bamni Bank Road, Companiganj, Noakhali | I4: 1879445931 | J4: 2023-24
A5: 104 | B5: Humanities | C5: Bibi Fatema | D5: Oli Ullah | E5: Rokeya Begum | F5: Female | G5: Islam | H5: Bamni Bank Road, Companiganj, Noakhali | I5: 1817409545 | J5: 2023-24
A6: 105 | B6: Humanities | C6: Bibi Kulsum | D6: Saleh Ahmed | E6: Anjuman Ara Begum | F6: Female | G6: Islam | H6: Bamni Bank Road, Companiganj, Noakhali | I6: 1859507326 | J6: 2023-24
A7: 106 | B7: Humanities | C7: Nowshin Sultana | D7: Md. Mohshin | E7: Nahid Sultana | F7: Female | G7: Islam | H7: Bamni Bank Road, Companiganj, Noakhali | I7: 1717090400 | J7: 2023-24
A8: 107 | B8: Humanities | C8: Imtiaj Islam | D8: Rafiqul Islam | E8: Nur Nahar | F8: Male | G8: Islam | H8: Bamni Bank Road, Companiganj, Noakhali | I8: 186988607 | J8: 2023-24
A9: 108 | B9: Humanities | C9: Tanjila Zahan | D9: Nur Mommad | E9: Marzahan Begum | F9: Female | G9: Islam | H9: Bamni Bank Road, Companiganj, Noakhali | I9: 1740047174 | J9: 2023-24
A10: 109 | B10: Humanities | C10: Hajera Khatun | D10: Md. Ismail | E10: Sultana Aktar | F10: Female | G10: Islam | H10: Bamni Bank Road, Companiganj, Noakhali | J10: 2023-24
A11: 110 | B11: Humanities | C11: Israt Ara Tumpa | D11: Md. Zohir Uddin | E11: Zannatul Ferdaus Ara | F11: Female | G11: Islam | H11: Bamni Bank Road, Companiganj, Noakhali | I11: 1840636907 | J11: 2023-24
A12: 111 | B12: Humanities | C12: Faojia Nowshin Tisha | D12: Zahangir Alom | E12: Nasima Aktar Banu | F12: Female | G12: Islam | H12: Bamni Bank Road, Companiganj, Noakhali | I12: 1818416684 | J12: 2023-24
A13: 112 | B13: Humanities | C13: Bibi Rohima Khatun | D13: Md. Belal Hossain | E13: Fatema Khatun | F13: Female | G13: Islam | H13: Bamni Bank Road, Companiganj, Noakhali | I13: 1858154588 | J13: 2023-24
A14: 113 | B14: Humanities | C14: Sarmina Aktar Aalma | D14: Golam Mowla | E14: Anowara Begum | F14: Female | G14: Islam | H14: Bamni Bank Road, Companiganj, Noakhali | I14: 1880636919 | J14: 2023-24
A15: 114 | B15: Humanities | C15: Belayet Hossain | D15: Aiyub Ali | E15: Bodra Begum | F15: Male | G15: Islam | H15: Bamni Bank Road, Companiganj, Noakhali | I15: 1832881444 | J15: 2023-24
A16: 115 | B16: Humanities | C16: Nur Zahan Aktar | D16: Abu Taher | E16: Fatema Begum | F16: Female | G16: Islam | H16: Bamni Bank Road, Companiganj, Noakhali | I16: 1819782369 | J16: 2023-24
A17: 116 | B17: Humanities | C17: Sabrina Lor Maha | D17: Shahab Uddin | E17: Sokina Khatun Sheuly | F17: Female | G17: Islam | H17: Bamni Bank Road, Companiganj, Noakhali | I17: 1612940023 | J17: 2023-24
A18: 117 | B18: Humanities | C18: Saima Islam | D18: Saiful Islam | E18: Ismot Zahan | F18: Female | G18: Islam | H18: Bamni Bank Road, Companiganj, Noakhali | I18: 1850711042 | J18: 2023-24
A19: 118 | B19: Humanities | C19: Sanzida Siddik Nitu | D19: Kamruzzaman Siddik | E19: Shamsunnahar Bokul | F19: Female | G19: Islam | H19: Bamni Bank Road, Companiganj, Noakhali | I19: 18317051404 | J19: 2023-24
A20: 119 | B20: Humanities | C20: Khaja Nazim Uddin Haidar | D20: Zohirul Haidar | E20: Hosne Ara Begum | F20: Male | G20: Islam | H20: Bamni Bank Road, Companiganj, Noakhali | I20: 1822213362 | J20: 2023-24
A21: 120 | B21: Humanities | C21: Imran Farhad Shakil | D21: Ahsan Ullah | E21: Khotiza Khatun | F21: Male | G21: Islam | H21: Bamni Bank Road, Companiganj, Noakhali | I21: 1873749023 | J21: 2023-24
A22: 121 | B22: Humanities | C22: Nur Hasan | D22: Nur Uddin | E22: Rahela Aktar | F22: Male | G22: Islam | H22: Bamni Bank Road, Companiganj, Noakhali | I22: 1878012390 | J22: 2023-25
... A77: 176 | B77: Humanities | C77: Fawzia Hossain Payel | D77: Mohammad Belal Hossain | E77: Parvin Aktar | F77: Female | G77: Islam | H77: Bamni Bank Road, Companiganj, Noakhali | I77: 1799881922 | J77: 2023-24
A78: 177 | B78: Humanities | C78: Sadia Sultana Iqra | D78: Sala Uddin | E78: Anjumanara Begum | F78: Female | G78: Islam | H78: Bamni Bank Road, Companiganj, Noakhali | I78: 01859-687342 | J78: 2023-24
A79: 178 | B79: Humanities | C79: Ahammad Zariful Islam | D79: Md. Main Uddin | E79: Shirin Aktar | F79: Male | G79: Islam | H79: Bamni Bank Road, Companiganj, Noakhali | I79: 1823851566 | J79: 2023-24
A80: 179 | B80: Humanities | C80: Tanha Farzin Siddik | D80: Kawsar Ahmed | E80: Jesmin Aktar | F80: Female | G80: Islam | H80: Bamni Bank Road, Companiganj, Noakhali | I80: 1612849441 | J80: 2023-24
A81: 180 | B81: Humanities | C81: Arafat Sultana | D81: Rafiq Ullah | E81: Nazmun Nahar | F81: Female | G81: Islam | H81: Bamni Bank Road, Companiganj, Noakhali | I81: 1833264076 | J81: 2023-24
A82: 181 | B82: Humanities | C82: Sanzida Sultana | D82: Abdul Malek | E82: Shahena Aktar | F82: Female | G82: Islam | H82: Bamni Bank Road, Companiganj, Noakhali | I82: 1612846643 | J82: 2023-24
A83: 182 | B83: Humanities | C83: Samiya Mehanaz | D83: Saiful Islam | E83: Halima Khatun | F83: Female | G83: Islam | H83: Bamni Bank Road, Companiganj, Noakhali | I83: 1882099435 | J83: 2023-24
A84: 183 | B84: Humanities | C84: Zannatul Tanzila | D84: Mohammad Moin Uddin | E84: Zannatul Ferdous | F84: Female | G84: Islam | H84: Bamni Bank Road, Companiganj, Noakhali | J84: 2023-24
A85: 184 | B85: Humanities | C85: Zoinob Aktar | D85: Ahammal Ullah | E85: Nur Zahan Begum | F85: Female | G85: Islam | H85: Bamni Bank Road, Companiganj, Noakhali | J85: 2023-24
A86: 185 | B86: Humanities | C86: Zannatul Nayem | D86: Mohammad Delower Hossain | E86: Kohinur Begum | F86: Female | G86: Islam | H86: Bamni Bank Road, Companiganj, Noakhali | J86: 2023-24
A87: 186 | B87: Humanities | C87: Hamida Aktar | D87: Md. Harun Roshid | E87: Hasina Aktar | F87: Female | G87: Islam | H87: Bamni Bank Road, Companiganj, Noakhali | I87: 1856794206 | J87: 2023-24
A88: 187 | B88: Humanities | C88: Bibi Kulsum | D88: Anamul Haque | E88: Amena Khatun | F88: Female | G88: Islam | H88: Bamni Bank Road, Companiganj, Noakhali | I88: 1865214378 | J88: 2023-24
A89: 188 | B89: Humanities | C89: Ziko Aktar | D89: Md. Belal HOssain | E89: Zananara Begum | F89: Female | G89: Islam | H89: Bamni Bank Road, Companiganj, Noakhali | I89: 1852041885 | J89: 2023-24
A90: 189 | B90: Humanities | C90: Nadia Begum | D90: Golam Faruk | E90: Bilkis Ara Begum | F90: Female | G90: Islam | H90: Bamni Bank Road, Companiganj, Noakhali | I90: 1832469909 | J90: 2023-24
A91: 190 | B91: Humanities | C91: Abdul Aziz | D91: Abdus Sattar | E91: Fatema Khatun | F91: Male | G91: Islam | H91: Bamni Bank Road, Companiganj, Noakhali | I91: 1879489221 | J91: 2023-24
A92: 191 | B92: Humanities | C92: Nazrul Islam | D92: Md. Abdullah | E92: Kamrun Nahar | F92: Male | G92: Islam | H92: Bamni Bank Road, Companiganj, Noakhali | I92: 1815258464 | J92: 2023-24
A93: 192 | B93: Humanities | C93: Ripat Hossain | D93: Shahjahan | E93: Bibi Kulsum | F93: Male | G93: Islam | H93: Bamni Bank Road, Companiganj, Noakhali | I93: 1719540649 | J93: 2023-24
A94: 193 | B94: Humanities | C94: Amdadul Haque | D94: Akramul Haque | E94: Ferdaus Ara Begum | F94: Male | G94: Islam | H94: Bamni Bank Road, Companiganj, Noakhali | I94: 1824710498 | J94: 2023-24
...

Sheet Prev. Academic
A1: ID | B1: Institution Name | C1: Group | D1: Session | E1: GPA | F1: Board Name | G1: Roll | H1: Reg No
A2: ='Student Basic Info'!A2 -> 101 | B2: Bamni High School | C2: Arts | D2: 2022-23 | E2: 5 | F2: Cumilla | H2: 2111897195
A3: ='Student Basic Info'!A3 -> 102 | B3: Bamni High School | C3: Arts | D3: 2022-24 | E3: 5 | F3: Cumilla | H3: 2111897230
A4: ='Student Basic Info'!A4 -> 103 | B4: Bamni High School | C4: Arts | D4: 2022-25 | E4: 5 | F4: Cumilla | H4: 2111896557
A5: ='Student Basic Info'!A5 -> 104 | B5: Bamni High School | C5: Arts | D5: 2022-26 | E5: 5 | F5: Cumilla | H5: 2011600400
A6: ='Student Basic Info'!A6 -> 105 | B6: Bamni High School | C6: Arts | D6: 2022-27 | E6: 5 | F6: Cumilla | H6: 2111896454
A7: ='Student Basic Info'!A7 -> 106 | B7: Bamni High School | C7: Arts | D7: 2022-28 | E7: 5 | F7: Cumilla | H7: 2111897040
A8: ='Student Basic Info'!A8 -> 107 | B8: Bamni High School | C8: Arts | D8: 2022-29 | E8: 5 | F8: Cumilla | H8: 2111895023
A9: ='Student Basic Info'!A9 -> 108 | B9: Bamni High School | C9: Arts | D9: 2022-30 | E9: 5 | F9: Cumilla | H9: 2011602371
A10: ='Student Basic Info'!A10 -> 109 | B10: Bamni High School | C10: Arts | D10: 2022-31 | E10: 5 | F10: Cumilla | H10: 2011600444
A11: ='Student Basic Info'!A11 -> 110 | B11: Bamni High School | C11: Arts | D11: 2022-32 | E11: 5 | F11: Cumilla | H11: 2111895048
A12: ='Student Basic Info'!A12 -> 111 | B12: Bamni High School | C12: Arts | D12: 2022-33 | E12: 5 | F12: Cumilla | H12: 2011600142
A13: ='Student Basic Info'!A13 -> 112 | B13: Bamni High School | C13: Arts | D13: 2022-34 | E13: 5 | F13: Cumilla | H13: 2111897198
... A88: ='Student Basic Info'!A88 -> 187 | B88: Bamni High School | C88: Arts | D88: 2022-109 | E88: 5 | F88: Cumilla | H88: 2011601550
A89: ='Student Basic Info'!A89 -> 188 | C89: Arts | H89: 2011601552
A90: ='Student Basic Info'!A90 -> 189 | C90: Arts | H90: 2011601562
A91: ='Student Basic Info'!A91 -> 190 | C91: Arts | H91: 2111897242
A92: ='Student Basic Info'!A92 -> 191 | C92: Arts | H92: 2011599834
A93: ='Student Basic Info'!A93 -> 192 | C93: Arts | H93: 2111897172
A94: ='Student Basic Info'!A94 -> 193 | C94: Arts | H94: 2111896300
A95: ='Student Basic Info'!A95 -> 194 | C95: Arts | H95: 2011602370
A96: ='Student Basic Info'!A96 -> 195 | C96: Arts | H96: 2011600458
A97: ='Student Basic Info'!A97 -> 196 | C97: Arts | H97: 2111896294
A98: ='Student Basic Info'!A98 -> 197 | C98: Arts | H98: 2111849077
A99: ='Student Basic Info'!A99 -> 198 | C99: Arts | H99: 2111897012
A100: ='Student Basic Info'!A100 -> 199 | C100: Arts | H100: 2011602540
... A130: ='Student Basic Info'!A130 -> 229 | C130: Arts | H130: 2011602105
A131: ='Student Basic Info'!A131 -> 230 | C131: Arts
A132: ='Student Basic Info'!A132 -> 231 | C132: Arts
A133: ='Student Basic Info'!A133 -> 232 | C133: Arts
A134: ='Student Basic Info'!A134 -> 233 | C134: Arts
A135: ='Student Basic Info'!A135 -> 234 | C135: Arts
A136: ='Student Basic Info'!A136 -> 235 | C136: Arts
A137: ='Student Basic Info'!A137 -> 236 | C137: Arts
A138: ='Student Basic Info'!A138 -> 237 | C138: Arts
A139: ='Student Basic Info'!A139 -> 238 | C139: Arts
A140: ='Student Basic Info'!A140 -> 239 | C140: Arts
A141: ='Student Basic Info'!A141 -> 240 | C141: Arts
A142: ='Student Basic Info'!A142 -> 241 | C142: Arts
... A306: ='Student Basic Info'!A306 -> 1392 | C306: Arts

Sheet SubjectList
A1: ID | B1: Compulsory1 | C1: Compulsory2 | D1: Compulsory3 | E1: Subject1 | F1: Subject2 | G1: Subject3 | H1: Subject4 | I1: Optioinal | J1: C1_Code | K1: C2_Code | L1: C3_Code | M1: S1_Code | N1: S2_Code | O1: S3_Code | P1: S4_Code
A2: ='Student Basic Info'!A2 -> 101 | B2: Bangla | C2: English | D2: ICT | E2: Civics | F2: Islamic History | G2: Social Work | H2: Islamic Studies | I2: =H2 -> Islamic Studies
A3: ='Student Basic Info'!A3 -> 102 | B3: Bangla | C3: English | D3: ICT | E3: Civics | F3: Islamic History | G3: Social Work | H3: Islamic Studies | I3: =H3 -> Islamic Studies
A4: ='Student Basic Info'!A4 -> 103 | B4: Bangla | C4: English | D4: ICT | E4: Civics | F4: Islamic History | G4: Social Work | H4: Islamic Studies | I4: =H4 -> Islamic Studies
A5: ='Student Basic Info'!A5 -> 104 | B5: Bangla | C5: English | D5: ICT | E5: Civics | F5: Islamic History | G5: Social Work | H5: Islamic Studies | I5: =H5 -> Islamic Studies
A6: ='Student Basic Info'!A6 -> 105 | B6: Bangla | C6: English | D6: ICT | E6: Civics | F6: Islamic History | G6: Social Work | H6: Islamic Studies | I6: =H6 -> Islamic Studies
A7: ='Student Basic Info'!A7 -> 106 | B7: Bangla | C7: English | D7: ICT | E7: Civics | F7: Islamic History | G7: Social Work | H7: Islamic Studies | I7: =H7 -> Islamic Studies
A8: ='Student Basic Info'!A8 -> 107 | B8: Bangla | C8: English | D8: ICT | E8: Civics | F8: Islamic History | G8: Social Work | H8: Islamic Studies | I8: =H8 -> Islamic Studies
A9: ='Student Basic Info'!A9 -> 108 | B9: Bangla | C9: English | D9: ICT | E9: Civics | F9: Islamic History | G9: Social Work | H9: Islamic Studies | I9: =H9 -> Islamic Studies
A10: ='Student Basic Info'!A10 -> 109 | B10: Bangla | C10: English | D10: ICT | E10: Civics | F10: Islamic History | G10: Social Work | H10: Islamic Studies | I10: =H10 -> Islamic Studies
A11: ='Student Basic Info'!A11 -> 110 | B11: Bangla | C11: English | D11: ICT | E11: Civics | F11: Islamic History | G11: Social Work | H11: Islamic Studies | I11: =H11 -> Islamic Studies
A12: ='Student Basic Info'!A12 -> 111 | B12: Bangla | C12: English | D12: ICT | E12: Civics | F12: Islamic History | G12: Social Work | H12: Islamic Studies | I12: =H12 -> Islamic Studies
A13: ='Student Basic Info'!A13 -> 112 | B13: Bangla | C13: English | D13: ICT | E13: Civics | F13: Islamic History | G13: Social Work | H13: Islamic Studies | I13: =H13 -> Islamic Studies
... A306: ='Student Basic Info'!A306 -> 1392 | B306: Bangla | C306: English | D306: ICT | E306: Civics | F306: Islamic History | G306: Social Work | H306: Islamic Studies | I306: =H306 -> Islamic Studies

Sheet Bangla
A1: Roll | B1: Marks MCQ | C1: Marks CQ | D1: Total Marks | E1: Result | F1: Grade | G1: GPA
A2: ='Student Basic Info'!A2 -> 101 | C2: 33 | D2: =IF(B2+C2=0, "", B2+C2) -> 33 | E2: =IF(D2="","", IF(C2>=33,"Pass","Fail")) -> Pass | F2: =(IF(D2="","",IF(E2="Fail","F",IF(D2>=80,"A+",IF(D2>=70,"A",IF(D2>=60,"A-",IF(D2>=50,"B",IF(D2>=40,"C",IF(D2>=33,"D","F"))))))))) -> D | G2: =(IF(D2="","",IF(F2="F",0,IF(D2>=80,5,IF(D2>=70,4,IF(D2>=60,3.5,IF(D2>=50,3,IF(D2>=40,2,IF(D2>=33,1,0))))))))) -> 1
A3: ='Student Basic Info'!A3 -> 102 | C3: 50 | D3: =IF(B3+C3=0, "", B3+C3) -> 50 | E3: =IF(D3="","", IF(C3>=33,"Pass","Fail")) -> Pass | F3: =(IF(D3="","",IF(E3="Fail","F",IF(D3>=80,"A+",IF(D3>=70,"A",IF(D3>=60,"A-",IF(D3>=50,"B",IF(D3>=40,"C",IF(D3>=33,"D","F"))))))))) -> B | G3: =(IF(D3="","",IF(F3="F",0,IF(D3>=80,5,IF(D3>=70,4,IF(D3>=60,3.5,IF(D3>=50,3,IF(D3>=40,2,IF(D3>=33,1,0))))))))) -> 3
A4: ='Student Basic Info'!A4 -> 103 | C4: 34 | D4: =IF(B4+C4=0, "", B4+C4) -> 34 | E4: =IF(D4="","", IF(C4>=33,"Pass","Fail")) -> Pass | F4: =(IF(D4="","",IF(E4="Fail","F",IF(D4>=80,"A+",IF(D4>=70,"A",IF(D4>=60,"A-",IF(D4>=50,"B",IF(D4>=40,"C",IF(D4>=33,"D","F"))))))))) -> D | G4: =(IF(D4="","",IF(F4="F",0,IF(D4>=80,5,IF(D4>=70,4,IF(D4>=60,3.5,IF(D4>=50,3,IF(D4>=40,2,IF(D4>=33,1,0))))))))) -> 1
A5: ='Student Basic Info'!A5 -> 104 | C5: 52 | D5: =IF(B5+C5=0, "", B5+C5) -> 52 | E5: =IF(D5="","", IF(C5>=33,"Pass","Fail")) -> Pass | F5: =(IF(D5="","",IF(E5="Fail","F",IF(D5>=80,"A+",IF(D5>=70,"A",IF(D5>=60,"A-",IF(D5>=50,"B",IF(D5>=40,"C",IF(D5>=33,"D","F"))))))))) -> B | G5: =(IF(D5="","",IF(F5="F",0,IF(D5>=80,5,IF(D5>=70,4,IF(D5>=60,3.5,IF(D5>=50,3,IF(D5>=40,2,IF(D5>=33,1,0))))))))) -> 3
A6: ='Student Basic Info'!A6 -> 105 | C6: 53 | D6: =IF(B6+C6=0, "", B6+C6) -> 53 | E6: =IF(D6="","", IF(C6>=33,"Pass","Fail")) -> Pass | F6: =(IF(D6="","",IF(E6="Fail","F",IF(D6>=80,"A+",IF(D6>=70,"A",IF(D6>=60,"A-",IF(D6>=50,"B",IF(D6>=40,"C",IF(D6>=33,"D","F"))))))))) -> B | G6: =(IF(D6="","",IF(F6="F",0,IF(D6>=80,5,IF(D6>=70,4,IF(D6>=60,3.5,IF(D6>=50,3,IF(D6>=40,2,IF(D6>=33,1,0))))))))) -> 3
A7: ='Student Basic Info'!A7 -> 106 | C7: 46 | D7: =IF(B7+C7=0, "", B7+C7) -> 46 | E7: =IF(D7="","", IF(C7>=33,"Pass","Fail")) -> Pass | F7: =(IF(D7="","",IF(E7="Fail","F",IF(D7>=80,"A+",IF(D7>=70,"A",IF(D7>=60,"A-",IF(D7>=50,"B",IF(D7>=40,"C",IF(D7>=33,"D","F"))))))))) -> C | G7: =(IF(D7="","",IF(F7="F",0,IF(D7>=80,5,IF(D7>=70,4,IF(D7>=60,3.5,IF(D7>=50,3,IF(D7>=40,2,IF(D7>=33,1,0))))))))) -> 2
A8: ='Student Basic Info'!A8 -> 107 | C8: 40 | D8: =IF(B8+C8=0, "", B8+C8) -> 40 | E8: =IF(D8="","", IF(C8>=33,"Pass","Fail")) -> Pass | F8: =(IF(D8="","",IF(E8="Fail","F",IF(D8>=80,"A+",IF(D8>=70,"A",IF(D8>=60,"A-",IF(D8>=50,"B",IF(D8>=40,"C",IF(D8>=33,"D","F"))))))))) -> C | G8: =(IF(D8="","",IF(F8="F",0,IF(D8>=80,5,IF(D8>=70,4,IF(D8>=60,3.5,IF(D8>=50,3,IF(D8>=40,2,IF(D8>=33,1,0))))))))) -> 2
A9: ='Student Basic Info'!A9 -> 108 | C9: 37 | D9: =IF(B9+C9=0, "", B9+C9) -> 37 | E9: =IF(D9="","", IF(C9>=33,"Pass","Fail")) -> Pass | F9: =(IF(D9="","",IF(E9="Fail","F",IF(D9>=80,"A+",IF(D9>=70,"A",IF(D9>=60,"A-",IF(D9>=50,"B",IF(D9>=40,"C",IF(D9>=33,"D","F"))))))))) -> D | G9: =(IF(D9="","",IF(F9="F",0,IF(D9>=80,5,IF(D9>=70,4,IF(D9>=60,3.5,IF(D9>=50,3,IF(D9>=40,2,IF(D9>=33,1,0))))))))) -> 1
A10: ='Student Basic Info'!A10 -> 109 | D10: =IF(B10+C10=0, "", B10+C10) | E10: =IF(D10="","", IF(C10>=33,"Pass","Fail")) | F10: =(IF(D10="","",IF(E10="Fail","F",IF(D10>=80,"A+",IF(D10>=70,"A",IF(D10>=60,"A-",IF(D10>=50,"B",IF(D10>=40,"C",IF(D10>=33,"D","F"))))))))) | G10: =(IF(D10="","",IF(F10="F",0,IF(D10>=80,5,IF(D10>=70,4,IF(D10>=60,3.5,IF(D10>=50,3,IF(D10>=40,2,IF(D10>=33,1,0)))))))))
A11: ='Student Basic Info'!A11 -> 110 | C11: 33 | D11: =IF(B11+C11=0, "", B11+C11) -> 33 | E11: =IF(D11="","", IF(C11>=33,"Pass","Fail")) -> Pass | F11: =(IF(D11="","",IF(E11="Fail","F",IF(D11>=80,"A+",IF(D11>=70,"A",IF(D11>=60,"A-",IF(D11>=50,"B",IF(D11>=40,"C",IF(D11>=33,"D","F"))))))))) -> D | G11: =(IF(D11="","",IF(F11="F",0,IF(D11>=80,5,IF(D11>=70,4,IF(D11>=60,3.5,IF(D11>=50,3,IF(D11>=40,2,IF(D11>=33,1,0))))))))) -> 1
A12: ='Student Basic Info'!A12 -> 111 | D12: =IF(B12+C12=0, "", B12+C12) | E12: =IF(D12="","", IF(C12>=33,"Pass","Fail")) | F12: =(IF(D12="","",IF(E12="Fail","F",IF(D12>=80,"A+",IF(D12>=70,"A",IF(D12>=60,"A-",IF(D12>=50,"B",IF(D12>=40,"C",IF(D12>=33,"D","F"))))))))) | G12: =(IF(D12="","",IF(F12="F",0,IF(D12>=80,5,IF(D12>=70,4,IF(D12>=60,3.5,IF(D12>=50,3,IF(D12>=40,2,IF(D12>=33,1,0)))))))))
A13: ='Student Basic Info'!A13 -> 112 | D13: =IF(B13+C13=0, "", B13+C13) | E13: =IF(D13="","", IF(C13>=33,"Pass","Fail")) | F13: =(IF(D13="","",IF(E13="Fail","F",IF(D13>=80,"A+",IF(D13>=70,"A",IF(D13>=60,"A-",IF(D13>=50,"B",IF(D13>=40,"C",IF(D13>=33,"D","F"))))))))) | G13: =(IF(D13="","",IF(F13="F",0,IF(D13>=80,5,IF(D13>=70,4,IF(D13>=60,3.5,IF(D13>=50,3,IF(D13>=40,2,IF(D13>=33,1,0)))))))))
A14: ='Student Basic Info'!A14 -> 113 | C14: 46 | D14: =IF(B14+C14=0, "", B14+C14) -> 46 | E14: =IF(D14="","", IF(C14>=33,"Pass","Fail")) -> Pass | F14: =(IF(D14="","",IF(E14="Fail","F",IF(D14>=80,"A+",IF(D14>=70,"A",IF(D14>=60,"A-",IF(D14>=50,"B",IF(D14>=40,"C",IF(D14>=33,"D","F"))))))))) -> C | G14: =(IF(D14="","",IF(F14="F",0,IF(D14>=80,5,IF(D14>=70,4,IF(D14>=60,3.5,IF(D14>=50,3,IF(D14>=40,2,IF(D14>=33,1,0))))))))) -> 2
A15: ='Student Basic Info'!A15 -> 114 | D15: =IF(B15+C15=0, "", B15+C15) | E15: =IF(D15="","", IF(C15>=33,"Pass","Fail")) | F15: =(IF(D15="","",IF(E15="Fail","F",IF(D15>=80,"A+",IF(D15>=70,"A",IF(D15>=60,"A-",IF(D15>=50,"B",IF(D15>=40,"C",IF(D15>=33,"D","F"))))))))) | G15: =(IF(D15="","",IF(F15="F",0,IF(D15>=80,5,IF(D15>=70,4,IF(D15>=60,3.5,IF(D15>=50,3,IF(D15>=40,2,IF(D15>=33,1,0)))))))))
A16: ='Student Basic Info'!A16 -> 115 | D16: =IF(B16+C16=0, "", B16+C16) | E16: =IF(D16="","", IF(C16>=33,"Pass","Fail")) | F16: =(IF(D16="","",IF(E16="Fail","F",IF(D16>=80,"A+",IF(D16>=70,"A",IF(D16>=60,"A-",IF(D16>=50,"B",IF(D16>=40,"C",IF(D16>=33,"D","F"))))))))) | G16: =(IF(D16="","",IF(F16="F",0,IF(D16>=80,5,IF(D16>=70,4,IF(D16>=60,3.5,IF(D16>=50,3,IF(D16>=40,2,IF(D16>=33,1,0)))))))))
A17: ='Student Basic Info'!A17 -> 116 | C17: 44 | D17: =IF(B17+C17=0, "", B17+C17) -> 44 | E17: =IF(D17="","", IF(C17>=33,"Pass","Fail")) -> Pass | F17: =(IF(D17="","",IF(E17="Fail","F",IF(D17>=80,"A+",IF(D17>=70,"A",IF(D17>=60,"A-",IF(D17>=50,"B",IF(D17>=40,"C",IF(D17>=33,"D","F"))))))))) -> C | G17: =(IF(D17="","",IF(F17="F",0,IF(D17>=80,5,IF(D17>=70,4,IF(D17>=60,3.5,IF(D17>=50,3,IF(D17>=40,2,IF(D17>=33,1,0))))))))) -> 2
A18: ='Student Basic Info'!A18 -> 117 | C18: 43 | D18: =IF(B18+C18=0, "", B18+C18) -> 43 | E18: =IF(D18="","", IF(C18>=33,"Pass","Fail")) -> Pass | F18: =(IF(D18="","",IF(E18="Fail","F",IF(D18>=80,"A+",IF(D18>=70,"A",IF(D18>=60,"A-",IF(D18>=50,"B",IF(D18>=40,"C",IF(D18>=33,"D","F"))))))))) -> C | G18: =(IF(D18="","",IF(F18="F",0,IF(D18>=80,5,IF(D18>=70,4,IF(D18>=60,3.5,IF(D18>=50,3,IF(D18>=40,2,IF(D18>=33,1,0))))))))) -> 2
A19: ='Student Basic Info'!A19 -> 118 | C19: 53 | D19: =IF(B19+C19=0, "", B19+C19) -> 53 | E19: =IF(D19="","", IF(C19>=33,"Pass","Fail")) -> Pass | F19: =(IF(D19="","",IF(E19="Fail","F",IF(D19>=80,"A+",IF(D19>=70,"A",IF(D19>=60,"A-",IF(D19>=50,"B",IF(D19>=40,"C",IF(D19>=33,"D","F"))))))))) -> B | G19: =(IF(D19="","",IF(F19="F",0,IF(D19>=80,5,IF(D19>=70,4,IF(D19>=60,3.5,IF(D19>=50,3,IF(D19>=40,2,IF(D19>=33,1,0))))))))) -> 3
A20: ='Student Basic Info'!A20 -> 119 | D20: =IF(B20+C20=0, "", B20+C20) | E20: =IF(D20="","", IF(C20>=33,"Pass","Fail")) | F20: =(IF(D20="","",IF(E20="Fail","F",IF(D20>=80,"A+",IF(D20>=70,"A",IF(D20>=60,"A-",IF(D20>=50,"B",IF(D20>=40,"C",IF(D20>=33,"D","F"))))))))) | G20: =(IF(D20="","",IF(F20="F",0,IF(D20>=80,5,IF(D20>=70,4,IF(D20>=60,3.5,IF(D20>=50,3,IF(D20>=40,2,IF(D20>=33,1,0)))))))))
A21: ='Student Basic Info'!A21 -> 120 | C21: 33 | D21: =IF(B21+C21=0, "", B21+C21) -> 33 | E21: =IF(D21="","", IF(C21>=33,"Pass","Fail")) -> Pass | F21: =(IF(D21="","",IF(E21="Fail","F",IF(D21>=80,"A+",IF(D21>=70,"A",IF(D21>=60,"A-",IF(D21>=50,"B",IF(D21>=40,"C",IF(D21>=33,"D","F"))))))))) -> D | G21: =(IF(D21="","",IF(F21="F",0,IF(D21>=80,5,IF(D21>=70,4,IF(D21>=60,3.5,IF(D21>=50,3,IF(D21>=40,2,IF(D21>=33,1,0))))))))) -> 1
A22: ='Student Basic Info'!A22 -> 121 | C22: 33 | D22: =IF(B22+C22=0, "", B22+C22) -> 33 | E22: =IF(D22="","", IF(C22>=33,"Pass","Fail")) -> Pass | F22: =(IF(D22="","",IF(E22="Fail","F",IF(D22>=80,"A+",IF(D22>=70,"A",IF(D22>=60,"A-",IF(D22>=50,"B",IF(D22>=40,"C",IF(D22>=33,"D","F"))))))))) -> D | G22: =(IF(D22="","",IF(F22="F",0,IF(D22>=80,5,IF(D22>=70,4,IF(D22>=60,3.5,IF(D22>=50,3,IF(D22>=40,2,IF(D22>=33,1,0))))))))) -> 1
A23: ='Student Basic Info'!A23 -> 122 | C23: 40 | D23: =IF(B23+C23=0, "", B23+C23) -> 40 | E23: =IF(D23="","", IF(C23>=33,"Pass","Fail")) -> Pass | F23: =(IF(D23="","",IF(E23="Fail","F",IF(D23>=80,"A+",IF(D23>=70,"A",IF(D23>=60,"A-",IF(D23>=50,"B",IF(D23>=40,"C",IF(D23>=33,"D","F"))))))))) -> C | G23: =(IF(D23="","",IF(F23="F",0,IF(D23>=80,5,IF(D23>=70,4,IF(D23>=60,3.5,IF(D23>=50,3,IF(D23>=40,2,IF(D23>=33,1,0))))))))) -> 2
A24: ='Student Basic Info'!A24 -> 123 | C24: 46 | D24: =IF(B24+C24=0, "", B24+C24) -> 46 | E24: =IF(D24="","", IF(C24>=33,"Pass","Fail")) -> Pass | F24: =(IF(D24="","",IF(E24="Fail","F",IF(D24>=80,"A+",IF(D24>=70,"A",IF(D24>=60,"A-",IF(D24>=50,"B",IF(D24>=40,"C",IF(D24>=33,"D","F"))))))))) -> C | G24: =(IF(D24="","",IF(F24="F",0,IF(D24>=80,5,IF(D24>=70,4,IF(D24>=60,3.5,IF(D24>=50,3,IF(D24>=40,2,IF(D24>=33,1,0))))))))) -> 2
A25: ='Student Basic Info'!A25 -> 124 | D25: =IF(B25+C25=0, "", B25+C25) | E25: =IF(D25="","", IF(C25>=33,"Pass","Fail")) | F25: =(IF(D25="","",IF(E25="Fail","F",IF(D25>=80,"A+",IF(D25>=70,"A",IF(D25>=60,"A-",IF(D25>=50,"B",IF(D25>=40,"C",IF(D25>=33,"D","F"))))))))) | G25: =(IF(D25="","",IF(F25="F",0,IF(D25>=80,5,IF(D25>=70,4,IF(D25>=60,3.5,IF(D25>=50,3,IF(D25>=40,2,IF(D25>=33,1,0)))))))))
A26: ='Student Basic Info'!A26 -> 125 | D26: =IF(B26+C26=0, "", B26+C26) | E26: =IF(D26="","", IF(C26>=33,"Pass","Fail")) | F26: =(IF(D26="","",IF(E26="Fail","F",IF(D26>=80,"A+",IF(D26>=70,"A",IF(D26>=60,"A-",IF(D26>=50,"B",IF(D26>=40,"C",IF(D26>=33,"D","F"))))))))) | G26: =(IF(D26="","",IF(F26="F",0,IF(D26>=80,5,IF(D26>=70,4,IF(D26>=60,3.5,IF(D26>=50,3,IF(D26>=40,2,IF(D26>=33,1,0)))))))))
A27: ='Student Basic Info'!A27 -> 126 | D27: =IF(B27+C27=0, "", B27+C27) | E27: =IF(D27="","", IF(C27>=33,"Pass","Fail")) | F27: =(IF(D27="","",IF(E27="Fail","F",IF(D27>=80,"A+",IF(D27>=70,"A",IF(D27>=60,"A-",IF(D27>=50,"B",IF(D27>=40,"C",IF(D27>=33,"D","F"))))))))) | G27: =(IF(D27="","",IF(F27="F",0,IF(D27>=80,5,IF(D27>=70,4,IF(D27>=60,3.5,IF(D27>=50,3,IF(D27>=40,2,IF(D27>=33,1,0)))))))))
A28: ='Student Basic Info'!A28 -> 127 | D28: =IF(B28+C28=0, "", B28+C28) | E28: =IF(D28="","", IF(C28>=33,"Pass","Fail")) | F28: =(IF(D28="","",IF(E28="Fail","F",IF(D28>=80,"A+",IF(D28>=70,"A",IF(D28>=60,"A-",IF(D28>=50,"B",IF(D28>=40,"C",IF(D28>=33,"D","F"))))))))) | G28: =(IF(D28="","",IF(F28="F",0,IF(D28>=80,5,IF(D28>=70,4,IF(D28>=60,3.5,IF(D28>=50,3,IF(D28>=40,2,IF(D28>=33,1,0)))))))))
A29: ='Student Basic Info'!A29 -> 128 | C29: 25 | D29: =IF(B29+C29=0, "", B29+C29) -> 25 | E29: =IF(D29="","", IF(C29>=33,"Pass","Fail")) -> Fail | F29: =(IF(D29="","",IF(E29="Fail","F",IF(D29>=80,"A+",IF(D29>=70,"A",IF(D29>=60,"A-",IF(D29>=50,"B",IF(D29>=40,"C",IF(D29>=33,"D","F"))))))))) -> F | G29: =(IF(D29="","",IF(F29="F",0,IF(D29>=80,5,IF(D29>=70,4,IF(D29>=60,3.5,IF(D29>=50,3,IF(D29>=40,2,IF(D29>=33,1,0))))))))) -> 0
A30: ='Student Basic Info'!A30 -> 129 | C30: 33 | D30: =IF(B30+C30=0, "", B30+C30) -> 33 | E30: =IF(D30="","", IF(C30>=33,"Pass","Fail")) -> Pass | F30: =(IF(D30="","",IF(E30="Fail","F",IF(D30>=80,"A+",IF(D30>=70,"A",IF(D30>=60,"A-",IF(D30>=50,"B",IF(D30>=40,"C",IF(D30>=33,"D","F"))))))))) -> D | G30: =(IF(D30="","",IF(F30="F",0,IF(D30>=80,5,IF(D30>=70,4,IF(D30>=60,3.5,IF(D30>=50,3,IF(D30>=40,2,IF(D30>=33,1,0))))))))) -> 1
A31: ='Student Basic Info'!A31 -> 130 | C31: 40 | D31: =IF(B31+C31=0, "", B31+C31) -> 40 | E31: =IF(D31="","", IF(C31>=33,"Pass","Fail")) -> Pass | F31: =(IF(D31="","",IF(E31="Fail","F",IF(D31>=80,"A+",IF(D31>=70,"A",IF(D31>=60,"A-",IF(D31>=50,"B",IF(D31>=40,"C",IF(D31>=33,"D","F"))))))))) -> C | G31: =(IF(D31="","",IF(F31="F",0,IF(D31>=80,5,IF(D31>=70,4,IF(D31>=60,3.5,IF(D31>=50,3,IF(D31>=40,2,IF(D31>=33,1,0))))))))) -> 2
A32: ='Student Basic Info'!A32 -> 131 | C32: 42 | D32: =IF(B32+C32=0, "", B32+C32) -> 42 | E32: =IF(D32="","", IF(C32>=33,"Pass","Fail")) -> Pass | F32: =(IF(D32="","",IF(E32="Fail","F",IF(D32>=80,"A+",IF(D32>=70,"A",IF(D32>=60,"A-",IF(D32>=50,"B",IF(D32>=40,"C",IF(D32>=33,"D","F"))))))))) -> C | G32: =(IF(D32="","",IF(F32="F",0,IF(D32>=80,5,IF(D32>=70,4,IF(D32>=60,3.5,IF(D32>=50,3,IF(D32>=40,2,IF(D32>=33,1,0))))))))) -> 2
A33: ='Student Basic Info'!A33 -> 132 | C33: 37 | D33: =IF(B33+C33=0, "", B33+C33) -> 37 | E33: =IF(D33="","", IF(C33>=33,"Pass","Fail")) -> Pass | F33: =(IF(D33="","",IF(E33="Fail","F",IF(D33>=80,"A+",IF(D33>=70,"A",IF(D33>=60,"A-",IF(D33>=50,"B",IF(D33>=40,"C",IF(D33>=33,"D","F"))))))))) -> D | G33: =(IF(D33="","",IF(F33="F",0,IF(D33>=80,5,IF(D33>=70,4,IF(D33>=60,3.5,IF(D33>=50,3,IF(D33>=40,2,IF(D33>=33,1,0))))))))) -> 1
A34: ='Student Basic Info'!A34 -> 133 | C34: 33 | D34: =IF(B34+C34=0, "", B34+C34) -> 33 | E34: =IF(D34="","", IF(C34>=33,"Pass","Fail")) -> Pass | F34: =(IF(D34="","",IF(E34="Fail","F",IF(D34>=80,"A+",IF(D34>=70,"A",IF(D34>=60,"A-",IF(D34>=50,"B",IF(D34>=40,"C",IF(D34>=33,"D","F"))))))))) -> D | G34: =(IF(D34="","",IF(F34="F",0,IF(D34>=80,5,IF(D34>=70,4,IF(D34>=60,3.5,IF(D34>=50,3,IF(D34>=40,2,IF(D34>=33,1,0))))))))) -> 1
A35: ='Student Basic Info'!A35 -> 134 | D35: =IF(B35+C35=0, "", B35+C35) | E35: =IF(D35="","", IF(C35>=33,"Pass","Fail")) | F35: =(IF(D35="","",IF(E35="Fail","F",IF(D35>=80,"A+",IF(D35>=70,"A",IF(D35>=60,"A-",IF(D35>=50,"B",IF(D35>=40,"C",IF(D35>=33,"D","F"))))))))) | G35: =(IF(D35="","",IF(F35="F",0,IF(D35>=80,5,IF(D35>=70,4,IF(D35>=60,3.5,IF(D35>=50,3,IF(D35>=40,2,IF(D35>=33,1,0)))))))))
A36: ='Student Basic Info'!A36 -> 135 | C36: 19 | D36: =IF(B36+C36=0, "", B36+C36) -> 19 | E36: =IF(D36="","", IF(C36>=33,"Pass","Fail")) -> Fail | F36: =(IF(D36="","",IF(E36="Fail","F",IF(D36>=80,"A+",IF(D36>=70,"A",IF(D36>=60,"A-",IF(D36>=50,"B",IF(D36>=40,"C",IF(D36>=33,"D","F"))))))))) -> F | G36: =(IF(D36="","",IF(F36="F",0,IF(D36>=80,5,IF(D36>=70,4,IF(D36>=60,3.5,IF(D36>=50,3,IF(D36>=40,2,IF(D36>=33,1,0))))))))) -> 0
A37: ='Student Basic Info'!A37 -> 136 | C37: 37 | D37: =IF(B37+C37=0, "", B37+C37) -> 37 | E37: =IF(D37="","", IF(C37>=33,"Pass","Fail")) -> Pass | F37: =(IF(D37="","",IF(E37="Fail","F",IF(D37>=80,"A+",IF(D37>=70,"A",IF(D37>=60,"A-",IF(D37>=50,"B",IF(D37>=40,"C",IF(D37>=33,"D","F"))))))))) -> D | G37: =(IF(D37="","",IF(F37="F",0,IF(D37>=80,5,IF(D37>=70,4,IF(D37>=60,3.5,IF(D37>=50,3,IF(D37>=40,2,IF(D37>=33,1,0))))))))) -> 1
A38: ='Student Basic Info'!A38 -> 137 | D38: =IF(B38+C38=0, "", B38+C38) | E38: =IF(D38="","", IF(C38>=33,"Pass","Fail")) | F38: =(IF(D38="","",IF(E38="Fail","F",IF(D38>=80,"A+",IF(D38>=70,"A",IF(D38>=60,"A-",IF(D38>=50,"B",IF(D38>=40,"C",IF(D38>=33,"D","F"))))))))) | G38: =(IF(D38="","",IF(F38="F",0,IF(D38>=80,5,IF(D38>=70,4,IF(D38>=60,3.5,IF(D38>=50,3,IF(D38>=40,2,IF(D38>=33,1,0)))))))))
A39: ='Student Basic Info'!A39 -> 138 | D39: =IF(B39+C39=0, "", B39+C39) | E39: =IF(D39="","", IF(C39>=33,"Pass","Fail")) | F39: =(IF(D39="","",IF(E39="Fail","F",IF(D39>=80,"A+",IF(D39>=70,"A",IF(D39>=60,"A-",IF(D39>=50,"B",IF(D39>=40,"C",IF(D39>=33,"D","F"))))))))) | G39: =(IF(D39="","",IF(F39="F",0,IF(D39>=80,5,IF(D39>=70,4,IF(D39>=60,3.5,IF(D39>=50,3,IF(D39>=40,2,IF(D39>=33,1,0)))))))))
A40: ='Student Basic Info'!A40 -> 139 | C40: 16 | D40: =IF(B40+C40=0, "", B40+C40) -> 16 | E40: =IF(D40="","", IF(C40>=33,"Pass","Fail")) -> Fail | F40: =(IF(D40="","",IF(E40="Fail","F",IF(D40>=80,"A+",IF(D40>=70,"A",IF(D40>=60,"A-",IF(D40>=50,"B",IF(D40>=40,"C",IF(D40>=33,"D","F"))))))))) -> F | G40: =(IF(D40="","",IF(F40="F",0,IF(D40>=80,5,IF(D40>=70,4,IF(D40>=60,3.5,IF(D40>=50,3,IF(D40>=40,2,IF(D40>=33,1,0))))))))) -> 0
...

Sheet English
A1: Roll | B1: Marks CQ | C1: Total Marks | D1: Result | E1: Grade | F1: GPA
A2: ='Student Basic Info'!A2 -> 101 | B2: 24 | C2: =IF(B2=0,"",B2) -> 24 | D2: =IF(C2="","", IF(C2>=33,"Pass","Fail")) -> Fail | E2: =(IF(C2="","",IF(D2="Fail","F",IF(C2>=80,"A+",IF(C2>=70,"A",IF(C2>=60,"A-",IF(C2>=50,"B",IF(C2>=40,"C",IF(C2>=33,"D","F"))))))))) -> F | F2: =(IF(C2="","",IF(E2="F",0,IF(C2>=80,5,IF(C2>=70,4,IF(C2>=60,3.5,IF(C2>=50,3,IF(C2>=40,2,IF(C2>=33,1,0))))))))) -> 0
A3: ='Student Basic Info'!A3 -> 102 | B3: 33 | C3: =IF(B3=0,"",B3) -> 33 | D3: =IF(C3="","", IF(C3>=33,"Pass","Fail")) -> Pass | E3: =(IF(C3="","",IF(D3="Fail","F",IF(C3>=80,"A+",IF(C3>=70,"A",IF(C3>=60,"A-",IF(C3>=50,"B",IF(C3>=40,"C",IF(C3>=33,"D","F"))))))))) -> D | F3: =(IF(C3="","",IF(E3="F",0,IF(C3>=80,5,IF(C3>=70,4,IF(C3>=60,3.5,IF(C3>=50,3,IF(C3>=40,2,IF(C3>=33,1,0))))))))) -> 1
A4: ='Student Basic Info'!A4 -> 103 | B4: 18 | C4: =IF(B4=0,"",B4) -> 18 | D4: =IF(C4="","", IF(C4>=33,"Pass","Fail")) -> Fail | E4: =(IF(C4="","",IF(D4="Fail","F",IF(C4>=80,"A+",IF(C4>=70,"A",IF(C4>=60,"A-",IF(C4>=50,"B",IF(C4>=40,"C",IF(C4>=33,"D","F"))))))))) -> F | F4: =(IF(C4="","",IF(E4="F",0,IF(C4>=80,5,IF(C4>=70,4,IF(C4>=60,3.5,IF(C4>=50,3,IF(C4>=40,2,IF(C4>=33,1,0))))))))) -> 0
A5: ='Student Basic Info'!A5 -> 104 | B5: 33 | C5: =IF(B5=0,"",B5) -> 33 | D5: =IF(C5="","", IF(C5>=33,"Pass","Fail")) -> Pass | E5: =(IF(C5="","",IF(D5="Fail","F",IF(C5>=80,"A+",IF(C5>=70,"A",IF(C5>=60,"A-",IF(C5>=50,"B",IF(C5>=40,"C",IF(C5>=33,"D","F"))))))))) -> D | F5: =(IF(C5="","",IF(E5="F",0,IF(C5>=80,5,IF(C5>=70,4,IF(C5>=60,3.5,IF(C5>=50,3,IF(C5>=40,2,IF(C5>=33,1,0))))))))) -> 1
A6: ='Student Basic Info'!A6 -> 105 | B6: 33 | C6: =IF(B6=0,"",B6) -> 33 | D6: =IF(C6="","", IF(C6>=33,"Pass","Fail")) -> Pass | E6: =(IF(C6="","",IF(D6="Fail","F",IF(C6>=80,"A+",IF(C6>=70,"A",IF(C6>=60,"A-",IF(C6>=50,"B",IF(C6>=40,"C",IF(C6>=33,"D","F"))))))))) -> D | F6: =(IF(C6="","",IF(E6="F",0,IF(C6>=80,5,IF(C6>=70,4,IF(C6>=60,3.5,IF(C6>=50,3,IF(C6>=40,2,IF(C6>=33,1,0))))))))) -> 1
A7: ='Student Basic Info'!A7 -> 106 | B7: 38 | C7: =IF(B7=0,"",B7) -> 38 | D7: =IF(C7="","", IF(C7>=33,"Pass","Fail")) -> Pass | E7: =(IF(C7="","",IF(D7="Fail","F",IF(C7>=80,"A+",IF(C7>=70,"A",IF(C7>=60,"A-",IF(C7>=50,"B",IF(C7>=40,"C",IF(C7>=33,"D","F"))))))))) -> D | F7: =(IF(C7="","",IF(E7="F",0,IF(C7>=80,5,IF(C7>=70,4,IF(C7>=60,3.5,IF(C7>=50,3,IF(C7>=40,2,IF(C7>=33,1,0))))))))) -> 1
A8: ='Student Basic Info'!A8 -> 107 | B8: 19 | C8: =IF(B8=0,"",B8) -> 19 | D8: =IF(C8="","", IF(C8>=33,"Pass","Fail")) -> Fail | E8: =(IF(C8="","",IF(D8="Fail","F",IF(C8>=80,"A+",IF(C8>=70,"A",IF(C8>=60,"A-",IF(C8>=50,"B",IF(C8>=40,"C",IF(C8>=33,"D","F"))))))))) -> F | F8: =(IF(C8="","",IF(E8="F",0,IF(C8>=80,5,IF(C8>=70,4,IF(C8>=60,3.5,IF(C8>=50,3,IF(C8>=40,2,IF(C8>=33,1,0))))))))) -> 0
A9: ='Student Basic Info'!A9 -> 108 | B9: 33 | C9: =IF(B9=0,"",B9) -> 33 | D9: =IF(C9="","", IF(C9>=33,"Pass","Fail")) -> Pass | E9: =(IF(C9="","",IF(D9="Fail","F",IF(C9>=80,"A+",IF(C9>=70,"A",IF(C9>=60,"A-",IF(C9>=50,"B",IF(C9>=40,"C",IF(C9>=33,"D","F"))))))))) -> D | F9: =(IF(C9="","",IF(E9="F",0,IF(C9>=80,5,IF(C9>=70,4,IF(C9>=60,3.5,IF(C9>=50,3,IF(C9>=40,2,IF(C9>=33,1,0))))))))) -> 1
A10: ='Student Basic Info'!A10 -> 109 | C10: =IF(B10=0,"",B10) | D10: =IF(C10="","", IF(C10>=33,"Pass","Fail")) | E10: =(IF(C10="","",IF(D10="Fail","F",IF(C10>=80,"A+",IF(C10>=70,"A",IF(C10>=60,"A-",IF(C10>=50,"B",IF(C10>=40,"C",IF(C10>=33,"D","F"))))))))) | F10: =(IF(C10="","",IF(E10="F",0,IF(C10>=80,5,IF(C10>=70,4,IF(C10>=60,3.5,IF(C10>=50,3,IF(C10>=40,2,IF(C10>=33,1,0)))))))))
A11: ='Student Basic Info'!A11 -> 110 | B11: 33 | C11: =IF(B11=0,"",B11) -> 33 | D11: =IF(C11="","", IF(C11>=33,"Pass","Fail")) -> Pass | E11: =(IF(C11="","",IF(D11="Fail","F",IF(C11>=80,"A+",IF(C11>=70,"A",IF(C11>=60,"A-",IF(C11>=50,"B",IF(C11>=40,"C",IF(C11>=33,"D","F"))))))))) -> D | F11: =(IF(C11="","",IF(E11="F",0,IF(C11>=80,5,IF(C11>=70,4,IF(C11>=60,3.5,IF(C11>=50,3,IF(C11>=40,2,IF(C11>=33,1,0))))))))) -> 1
A12: ='Student Basic Info'!A12 -> 111 | C12: =IF(B12=0,"",B12) | D12: =IF(C12="","", IF(C12>=33,"Pass","Fail")) | E12: =(IF(C12="","",IF(D12="Fail","F",IF(C12>=80,"A+",IF(C12>=70,"A",IF(C12>=60,"A-",IF(C12>=50,"B",IF(C12>=40,"C",IF(C12>=33,"D","F"))))))))) | F12: =(IF(C12="","",IF(E12="F",0,IF(C12>=80,5,IF(C12>=70,4,IF(C12>=60,3.5,IF(C12>=50,3,IF(C12>=40,2,IF(C12>=33,1,0)))))))))
A13: ='Student Basic Info'!A13 -> 112 | C13: =IF(B13=0,"",B13) | D13: =IF(C13="","", IF(C13>=33,"Pass","Fail")) | E13: =(IF(C13="","",IF(D13="Fail","F",IF(C13>=80,"A+",IF(C13>=70,"A",IF(C13>=60,"A-",IF(C13>=50,"B",IF(C13>=40,"C",IF(C13>=33,"D","F"))))))))) | F13: =(IF(C13="","",IF(E13="F",0,IF(C13>=80,5,IF(C13>=70,4,IF(C13>=60,3.5,IF(C13>=50,3,IF(C13>=40,2,IF(C13>=33,1,0)))))))))
A14: ='Student Basic Info'!A14 -> 113 | B14: 50 | C14: =IF(B14=0,"",B14) -> 50 | D14: =IF(C14="","", IF(C14>=33,"Pass","Fail")) -> Pass | E14: =(IF(C14="","",IF(D14="Fail","F",IF(C14>=80,"A+",IF(C14>=70,"A",IF(C14>=60,"A-",IF(C14>=50,"B",IF(C14>=40,"C",IF(C14>=33,"D","F"))))))))) -> B | F14: =(IF(C14="","",IF(E14="F",0,IF(C14>=80,5,IF(C14>=70,4,IF(C14>=60,3.5,IF(C14>=50,3,IF(C14>=40,2,IF(C14>=33,1,0))))))))) -> 3
A15: ='Student Basic Info'!A15 -> 114 | C15: =IF(B15=0,"",B15) | D15: =IF(C15="","", IF(C15>=33,"Pass","Fail")) | E15: =(IF(C15="","",IF(D15="Fail","F",IF(C15>=80,"A+",IF(C15>=70,"A",IF(C15>=60,"A-",IF(C15>=50,"B",IF(C15>=40,"C",IF(C15>=33,"D","F"))))))))) | F15: =(IF(C15="","",IF(E15="F",0,IF(C15>=80,5,IF(C15>=70,4,IF(C15>=60,3.5,IF(C15>=50,3,IF(C15>=40,2,IF(C15>=33,1,0)))))))))
A16: ='Student Basic Info'!A16 -> 115 | C16: =IF(B16=0,"",B16) | D16: =IF(C16="","", IF(C16>=33,"Pass","Fail")) | E16: =(IF(C16="","",IF(D16="Fail","F",IF(C16>=80,"A+",IF(C16>=70,"A",IF(C16>=60,"A-",IF(C16>=50,"B",IF(C16>=40,"C",IF(C16>=33,"D","F"))))))))) | F16: =(IF(C16="","",IF(E16="F",0,IF(C16>=80,5,IF(C16>=70,4,IF(C16>=60,3.5,IF(C16>=50,3,IF(C16>=40,2,IF(C16>=33,1,0)))))))))
A17: ='Student Basic Info'!A17 -> 116 | B17: 40 | C17: =IF(B17=0,"",B17) -> 40 | D17: =IF(C17="","", IF(C17>=33,"Pass","Fail")) -> Pass | E17: =(IF(C17="","",IF(D17="Fail","F",IF(C17>=80,"A+",IF(C17>=70,"A",IF(C17>=60,"A-",IF(C17>=50,"B",IF(C17>=40,"C",IF(C17>=33,"D","F"))))))))) -> C | F17: =(IF(C17="","",IF(E17="F",0,IF(C17>=80,5,IF(C17>=70,4,IF(C17>=60,3.5,IF(C17>=50,3,IF(C17>=40,2,IF(C17>=33,1,0))))))))) -> 2
A18: ='Student Basic Info'!A18 -> 117 | B18: 60 | C18: =IF(B18=0,"",B18) -> 60 | D18: =IF(C18="","", IF(C18>=33,"Pass","Fail")) -> Pass | E18: =(IF(C18="","",IF(D18="Fail","F",IF(C18>=80,"A+",IF(C18>=70,"A",IF(C18>=60,"A-",IF(C18>=50,"B",IF(C18>=40,"C",IF(C18>=33,"D","F"))))))))) -> A- | F18: =(IF(C18="","",IF(E18="F",0,IF(C18>=80,5,IF(C18>=70,4,IF(C18>=60,3.5,IF(C18>=50,3,IF(C18>=40,2,IF(C18>=33,1,0))))))))) -> 3.5
A19: ='Student Basic Info'!A19 -> 118 | B19: 52 | C19: =IF(B19=0,"",B19) -> 52 | D19: =IF(C19="","", IF(C19>=33,"Pass","Fail")) -> Pass | E19: =(IF(C19="","",IF(D19="Fail","F",IF(C19>=80,"A+",IF(C19>=70,"A",IF(C19>=60,"A-",IF(C19>=50,"B",IF(C19>=40,"C",IF(C19>=33,"D","F"))))))))) -> B | F19: =(IF(C19="","",IF(E19="F",0,IF(C19>=80,5,IF(C19>=70,4,IF(C19>=60,3.5,IF(C19>=50,3,IF(C19>=40,2,IF(C19>=33,1,0))))))))) -> 3
A20: ='Student Basic Info'!A20 -> 119 | C20: =IF(B20=0,"",B20) | D20: =IF(C20="","", IF(C20>=33,"Pass","Fail")) | E20: =(IF(C20="","",IF(D20="Fail","F",IF(C20>=80,"A+",IF(C20>=70,"A",IF(C20>=60,"A-",IF(C20>=50,"B",IF(C20>=40,"C",IF(C20>=33,"D","F"))))))))) | F20: =(IF(C20="","",IF(E20="F",0,IF(C20>=80,5,IF(C20>=70,4,IF(C20>=60,3.5,IF(C20>=50,3,IF(C20>=40,2,IF(C20>=33,1,0)))))))))
A21: ='Student Basic Info'!A21 -> 120 | B21: 18 | C21: =IF(B21=0,"",B21) -> 18 | D21: =IF(C21="","", IF(C21>=33,"Pass","Fail")) -> Fail | E21: =(IF(C21="","",IF(D21="Fail","F",IF(C21>=80,"A+",IF(C21>=70,"A",IF(C21>=60,"A-",IF(C21>=50,"B",IF(C21>=40,"C",IF(C21>=33,"D","F"))))))))) -> F | F21: =(IF(C21="","",IF(E21="F",0,IF(C21>=80,5,IF(C21>=70,4,IF(C21>=60,3.5,IF(C21>=50,3,IF(C21>=40,2,IF(C21>=33,1,0))))))))) -> 0
A22: ='Student Basic Info'!A22 -> 121 | B22: 20 | C22: =IF(B22=0,"",B22) -> 20 | D22: =IF(C22="","", IF(C22>=33,"Pass","Fail")) -> Fail | E22: =(IF(C22="","",IF(D22="Fail","F",IF(C22>=80,"A+",IF(C22>=70,"A",IF(C22>=60,"A-",IF(C22>=50,"B",IF(C22>=40,"C",IF(C22>=33,"D","F"))))))))) -> F | F22: =(IF(C22="","",IF(E22="F",0,IF(C22>=80,5,IF(C22>=70,4,IF(C22>=60,3.5,IF(C22>=50,3,IF(C22>=40,2,IF(C22>=33,1,0))))))))) -> 0
A23: ='Student Basic Info'!A23 -> 122 | B23: 43 | C23: =IF(B23=0,"",B23) -> 43 | D23: =IF(C23="","", IF(C23>=33,"Pass","Fail")) -> Pass | E23: =(IF(C23="","",IF(D23="Fail","F",IF(C23>=80,"A+",IF(C23>=70,"A",IF(C23>=60,"A-",IF(C23>=50,"B",IF(C23>=40,"C",IF(C23>=33,"D","F"))))))))) -> C | F23: =(IF(C23="","",IF(E23="F",0,IF(C23>=80,5,IF(C23>=70,4,IF(C23>=60,3.5,IF(C23>=50,3,IF(C23>=40,2,IF(C23>=33,1,0))))))))) -> 2
A24: ='Student Basic Info'!A24 -> 123 | B24: 50 | C24: =IF(B24=0,"",B24) -> 50 | D24: =IF(C24="","", IF(C24>=33,"Pass","Fail")) -> Pass | E24: =(IF(C24="","",IF(D24="Fail","F",IF(C24>=80,"A+",IF(C24>=70,"A",IF(C24>=60,"A-",IF(C24>=50,"B",IF(C24>=40,"C",IF(C24>=33,"D","F"))))))))) -> B | F24: =(IF(C24="","",IF(E24="F",0,IF(C24>=80,5,IF(C24>=70,4,IF(C24>=60,3.5,IF(C24>=50,3,IF(C24>=40,2,IF(C24>=33,1,0))))))))) -> 3
A25: ='Student Basic Info'!A25 -> 124 | C25: =IF(B25=0,"",B25) | D25: =IF(C25="","", IF(C25>=33,"Pass","Fail")) | E25: =(IF(C25="","",IF(D25="Fail","F",IF(C25>=80,"A+",IF(C25>=70,"A",IF(C25>=60,"A-",IF(C25>=50,"B",IF(C25>=40,"C",IF(C25>=33,"D","F"))))))))) | F25: =(IF(C25="","",IF(E25="F",0,IF(C25>=80,5,IF(C25>=70,4,IF(C25>=60,3.5,IF(C25>=50,3,IF(C25>=40,2,IF(C25>=33,1,0)))))))))
A26: ='Student Basic Info'!A26 -> 125 | C26: =IF(B26=0,"",B26) | D26: =IF(C26="","", IF(C26>=33,"Pass","Fail")) | E26: =(IF(C26="","",IF(D26="Fail","F",IF(C26>=80,"A+",IF(C26>=70,"A",IF(C26>=60,"A-",IF(C26>=50,"B",IF(C26>=40,"C",IF(C26>=33,"D","F"))))))))) | F26: =(IF(C26="","",IF(E26="F",0,IF(C26>=80,5,IF(C26>=70,4,IF(C26>=60,3.5,IF(C26>=50,3,IF(C26>=40,2,IF(C26>=33,1,0)))))))))
A27: ='Student Basic Info'!A27 -> 126 | C27: =IF(B27=0,"",B27) | D27: =IF(C27="","", IF(C27>=33,"Pass","Fail")) | E27: =(IF(C27="","",IF(D27="Fail","F",IF(C27>=80,"A+",IF(C27>=70,"A",IF(C27>=60,"A-",IF(C27>=50,"B",IF(C27>=40,"C",IF(C27>=33,"D","F"))))))))) | F27: =(IF(C27="","",IF(E27="F",0,IF(C27>=80,5,IF(C27>=70,4,IF(C27>=60,3.5,IF(C27>=50,3,IF(C27>=40,2,IF(C27>=33,1,0)))))))))
A28: ='Student Basic Info'!A28 -> 127 | C28: =IF(B28=0,"",B28) | D28: =IF(C28="","", IF(C28>=33,"Pass","Fail")) | E28: =(IF(C28="","",IF(D28="Fail","F",IF(C28>=80,"A+",IF(C28>=70,"A",IF(C28>=60,"A-",IF(C28>=50,"B",IF(C28>=40,"C",IF(C28>=33,"D","F"))))))))) | F28: =(IF(C28="","",IF(E28="F",0,IF(C28>=80,5,IF(C28>=70,4,IF(C28>=60,3.5,IF(C28>=50,3,IF(C28>=40,2,IF(C28>=33,1,0)))))))))
A29: ='Student Basic Info'!A29 -> 128 | B29: 33 | C29: =IF(B29=0,"",B29) -> 33 | D29: =IF(C29="","", IF(C29>=33,"Pass","Fail")) -> Pass | E29: =(IF(C29="","",IF(D29="Fail","F",IF(C29>=80,"A+",IF(C29>=70,"A",IF(C29>=60,"A-",IF(C29>=50,"B",IF(C29>=40,"C",IF(C29>=33,"D","F"))))))))) -> D | F29: =(IF(C29="","",IF(E29="F",0,IF(C29>=80,5,IF(C29>=70,4,IF(C29>=60,3.5,IF(C29>=50,3,IF(C29>=40,2,IF(C29>=33,1,0))))))))) -> 1
A30: ='Student Basic Info'!A30 -> 129 | B30: 17 | C30: =IF(B30=0,"",B30) -> 17 | D30: =IF(C30="","", IF(C30>=33,"Pass","Fail")) -> Fail | E30: =(IF(C30="","",IF(D30="Fail","F",IF(C30>=80,"A+",IF(C30>=70,"A",IF(C30>=60,"A-",IF(C30>=50,"B",IF(C30>=40,"C",IF(C30>=33,"D","F"))))))))) -> F | F30: =(IF(C30="","",IF(E30="F",0,IF(C30>=80,5,IF(C30>=70,4,IF(C30>=60,3.5,IF(C30>=50,3,IF(C30>=40,2,IF(C30>=33,1,0))))))))) -> 0
A31: ='Student Basic Info'!A31 -> 130 | B31: 43 | C31: =IF(B31=0,"",B31) -> 43 | D31: =IF(C31="","", IF(C31>=33,"Pass","Fail")) -> Pass | E31: =(IF(C31="","",IF(D31="Fail","F",IF(C31>=80,"A+",IF(C31>=70,"A",IF(C31>=60,"A-",IF(C31>=50,"B",IF(C31>=40,"C",IF(C31>=33,"D","F"))))))))) -> C | F31: =(IF(C31="","",IF(E31="F",0,IF(C31>=80,5,IF(C31>=70,4,IF(C31>=60,3.5,IF(C31>=50,3,IF(C31>=40,2,IF(C31>=33,1,0))))))))) -> 2
A32: ='Student Basic Info'!A32 -> 131 | B32: 35 | C32: =IF(B32=0,"",B32) -> 35 | D32: =IF(C32="","", IF(C32>=33,"Pass","Fail")) -> Pass | E32: =(IF(C32="","",IF(D32="Fail","F",IF(C32>=80,"A+",IF(C32>=70,"A",IF(C32>=60,"A-",IF(C32>=50,"B",IF(C32>=40,"C",IF(C32>=33,"D","F"))))))))) -> D | F32: =(IF(C32="","",IF(E32="F",0,IF(C32>=80,5,IF(C32>=70,4,IF(C32>=60,3.5,IF(C32>=50,3,IF(C32>=40,2,IF(C32>=33,1,0))))))))) -> 1
A33: ='Student Basic Info'!A33 -> 132 | B33: 36 | C33: =IF(B33=0,"",B33) -> 36 | D33: =IF(C33="","", IF(C33>=33,"Pass","Fail")) -> Pass | E33: =(IF(C33="","",IF(D33="Fail","F",IF(C33>=80,"A+",IF(C33>=70,"A",IF(C33>=60,"A-",IF(C33>=50,"B",IF(C33>=40,"C",IF(C33>=33,"D","F"))))))))) -> D | F33: =(IF(C33="","",IF(E33="F",0,IF(C33>=80,5,IF(C33>=70,4,IF(C33>=60,3.5,IF(C33>=50,3,IF(C33>=40,2,IF(C33>=33,1,0))))))))) -> 1
A34: ='Student Basic Info'!A34 -> 133 | B34: 13 | C34: =IF(B34=0,"",B34) -> 13 | D34: =IF(C34="","", IF(C34>=33,"Pass","Fail")) -> Fail | E34: =(IF(C34="","",IF(D34="Fail","F",IF(C34>=80,"A+",IF(C34>=70,"A",IF(C34>=60,"A-",IF(C34>=50,"B",IF(C34>=40,"C",IF(C34>=33,"D","F"))))))))) -> F | F34: =(IF(C34="","",IF(E34="F",0,IF(C34>=80,5,IF(C34>=70,4,IF(C34>=60,3.5,IF(C34>=50,3,IF(C34>=40,2,IF(C34>=33,1,0))))))))) -> 0
A35: ='Student Basic Info'!A35 -> 134 | C35: =IF(B35=0,"",B35) | D35: =IF(C35="","", IF(C35>=33,"Pass","Fail")) | E35: =(IF(C35="","",IF(D35="Fail","F",IF(C35>=80,"A+",IF(C35>=70,"A",IF(C35>=60,"A-",IF(C35>=50,"B",IF(C35>=40,"C",IF(C35>=33,"D","F"))))))))) | F35: =(IF(C35="","",IF(E35="F",0,IF(C35>=80,5,IF(C35>=70,4,IF(C35>=60,3.5,IF(C35>=50,3,IF(C35>=40,2,IF(C35>=33,1,0)))))))))
A36: ='Student Basic Info'!A36 -> 135 | B36: 34 | C36: =IF(B36=0,"",B36) -> 34 | D36: =IF(C36="","", IF(C36>=33,"Pass","Fail")) -> Pass | E36: =(IF(C36="","",IF(D36="Fail","F",IF(C36>=80,"A+",IF(C36>=70,"A",IF(C36>=60,"A-",IF(C36>=50,"B",IF(C36>=40,"C",IF(C36>=33,"D","F"))))))))) -> D | F36: =(IF(C36="","",IF(E36="F",0,IF(C36>=80,5,IF(C36>=70,4,IF(C36>=60,3.5,IF(C36>=50,3,IF(C36>=40,2,IF(C36>=33,1,0))))))))) -> 1
A37: ='Student Basic Info'!A37 -> 136 | B37: 11 | C37: =IF(B37=0,"",B37) -> 11 | D37: =IF(C37="","", IF(C37>=33,"Pass","Fail")) -> Fail | E37: =(IF(C37="","",IF(D37="Fail","F",IF(C37>=80,"A+",IF(C37>=70,"A",IF(C37>=60,"A-",IF(C37>=50,"B",IF(C37>=40,"C",IF(C37>=33,"D","F"))))))))) -> F | F37: =(IF(C37="","",IF(E37="F",0,IF(C37>=80,5,IF(C37>=70,4,IF(C37>=60,3.5,IF(C37>=50,3,IF(C37>=40,2,IF(C37>=33,1,0))))))))) -> 0
A38: ='Student Basic Info'!A38 -> 137 | C38: =IF(B38=0,"",B38) | D38: =IF(C38="","", IF(C38>=33,"Pass","Fail")) | E38: =(IF(C38="","",IF(D38="Fail","F",IF(C38>=80,"A+",IF(C38>=70,"A",IF(C38>=60,"A-",IF(C38>=50,"B",IF(C38>=40,"C",IF(C38>=33,"D","F"))))))))) | F38: =(IF(C38="","",IF(E38="F",0,IF(C38>=80,5,IF(C38>=70,4,IF(C38>=60,3.5,IF(C38>=50,3,IF(C38>=40,2,IF(C38>=33,1,0)))))))))
A39: ='Student Basic Info'!A39 -> 138 | C39: =IF(B39=0,"",B39) | D39: =IF(C39="","", IF(C39>=33,"Pass","Fail")) | E39: =(IF(C39="","",IF(D39="Fail","F",IF(C39>=80,"A+",IF(C39>=70,"A",IF(C39>=60,"A-",IF(C39>=50,"B",IF(C39>=40,"C",IF(C39>=33,"D","F"))))))))) | F39: =(IF(C39="","",IF(E39="F",0,IF(C39>=80,5,IF(C39>=70,4,IF(C39>=60,3.5,IF(C39>=50,3,IF(C39>=40,2,IF(C39>=33,1,0)))))))))
A40: ='Student Basic Info'!A40 -> 139 | B40: 34 | C40: =IF(B40=0,"",B40) -> 34 | D40: =IF(C40="","", IF(C40>=33,"Pass","Fail")) -> Pass | E40: =(IF(C40="","",IF(D40="Fail","F",IF(C40>=80,"A+",IF(C40>=70,"A",IF(C40>=60,"A-",IF(C40>=50,"B",IF(C40>=40,"C",IF(C40>=33,"D","F"))))))))) -> D | F40: =(IF(C40="","",IF(E40="F",0,IF(C40>=80,5,IF(C40>=70,4,IF(C40>=60,3.5,IF(C40>=50,3,IF(C40>=40,2,IF(C40>=33,1,0))))))))) -> 1
...

Sheet ICT
A1: Roll | B1: Marks MCQ | C1: Marks CQ | D1: Practical | E1: Total Marks | F1: Result | G1: Grade | H1: GPA
A2: ='Student Basic Info'!A2 -> 101 | B2: 4 | C2: 1 | D2: 23 | E2: =IF(B2+C2+D2=0, "", B2+C2+D2) -> 28 | F2: =IF(E2="","", IF(AND(B2 >=8,C2>=17,D2>=8),"Pass","Fail")) -> Fail | G2: =(IF(E2="","",IF(F2="Fail","F",IF(E2>=80,"A+",IF(E2>=70,"A",IF(E2>=60,"A-",IF(E2>=50,"B",IF(E2>=40,"C",IF(E2>=33,"D","F"))))))))) -> F | H2: =(IF(E2="","",IF(G2="F",0,IF(E2>=80,5,IF(E2>=70,4,IF(E2>=60,3.5,IF(E2>=50,3,IF(E2>=40,2,IF(E2>=33,1,0))))))))) -> 0
A3: ='Student Basic Info'!A3 -> 102 | B3: 7 | C3: 5 | D3: 22 | E3: =IF(B3+C3+D3=0, "", B3+C3+D3) -> 34 | F3: =IF(E3="","", IF(AND(B3 >=8,C3>=17,D3>=8),"Pass","Fail")) -> Fail | G3: =(IF(E3="","",IF(F3="Fail","F",IF(E3>=80,"A+",IF(E3>=70,"A",IF(E3>=60,"A-",IF(E3>=50,"B",IF(E3>=40,"C",IF(E3>=33,"D","F"))))))))) -> F | H3: =(IF(E3="","",IF(G3="F",0,IF(E3>=80,5,IF(E3>=70,4,IF(E3>=60,3.5,IF(E3>=50,3,IF(E3>=40,2,IF(E3>=33,1,0))))))))) -> 0
A4: ='Student Basic Info'!A4 -> 103 | B4: 11 | C4: 4 | D4: 24 | E4: =IF(B4+C4+D4=0, "", B4+C4+D4) -> 39 | F4: =IF(E4="","", IF(AND(B4 >=8,C4>=17,D4>=8),"Pass","Fail")) -> Fail | G4: =(IF(E4="","",IF(F4="Fail","F",IF(E4>=80,"A+",IF(E4>=70,"A",IF(E4>=60,"A-",IF(E4>=50,"B",IF(E4>=40,"C",IF(E4>=33,"D","F"))))))))) -> F | H4: =(IF(E4="","",IF(G4="F",0,IF(E4>=80,5,IF(E4>=70,4,IF(E4>=60,3.5,IF(E4>=50,3,IF(E4>=40,2,IF(E4>=33,1,0))))))))) -> 0
A5: ='Student Basic Info'!A5 -> 104 | B5: 8 | C5: 12 | D5: 18 | E5: =IF(B5+C5+D5=0, "", B5+C5+D5) -> 38 | F5: =IF(E5="","", IF(AND(B5 >=8,C5>=17,D5>=8),"Pass","Fail")) -> Fail | G5: =(IF(E5="","",IF(F5="Fail","F",IF(E5>=80,"A+",IF(E5>=70,"A",IF(E5>=60,"A-",IF(E5>=50,"B",IF(E5>=40,"C",IF(E5>=33,"D","F"))))))))) -> F | H5: =(IF(E5="","",IF(G5="F",0,IF(E5>=80,5,IF(E5>=70,4,IF(E5>=60,3.5,IF(E5>=50,3,IF(E5>=40,2,IF(E5>=33,1,0))))))))) -> 0
A6: ='Student Basic Info'!A6 -> 105 | B6: 6 | C6: 6 | D6: 18 | E6: =IF(B6+C6+D6=0, "", B6+C6+D6) -> 30 | F6: =IF(E6="","", IF(AND(B6 >=8,C6>=17,D6>=8),"Pass","Fail")) -> Fail | G6: =(IF(E6="","",IF(F6="Fail","F",IF(E6>=80,"A+",IF(E6>=70,"A",IF(E6>=60,"A-",IF(E6>=50,"B",IF(E6>=40,"C",IF(E6>=33,"D","F"))))))))) -> F | H6: =(IF(E6="","",IF(G6="F",0,IF(E6>=80,5,IF(E6>=70,4,IF(E6>=60,3.5,IF(E6>=50,3,IF(E6>=40,2,IF(E6>=33,1,0))))))))) -> 0
A7: ='Student Basic Info'!A7 -> 106 | B7: 10 | C7: 11 | D7: 18 | E7: =IF(B7+C7+D7=0, "", B7+C7+D7) -> 39 | F7: =IF(E7="","", IF(AND(B7 >=8,C7>=17,D7>=8),"Pass","Fail")) -> Fail | G7: =(IF(E7="","",IF(F7="Fail","F",IF(E7>=80,"A+",IF(E7>=70,"A",IF(E7>=60,"A-",IF(E7>=50,"B",IF(E7>=40,"C",IF(E7>=33,"D","F"))))))))) -> F | H7: =(IF(E7="","",IF(G7="F",0,IF(E7>=80,5,IF(E7>=70,4,IF(E7>=60,3.5,IF(E7>=50,3,IF(E7>=40,2,IF(E7>=33,1,0))))))))) -> 0
A8: ='Student Basic Info'!A8 -> 107 | B8: 9 | C8: 4 | D8: 20 | E8: =IF(B8+C8+D8=0, "", B8+C8+D8) -> 33 | F8: =IF(E8="","", IF(AND(B8 >=8,C8>=17,D8>=8),"Pass","Fail")) -> Fail | G8: =(IF(E8="","",IF(F8="Fail","F",IF(E8>=80,"A+",IF(E8>=70,"A",IF(E8>=60,"A-",IF(E8>=50,"B",IF(E8>=40,"C",IF(E8>=33,"D","F"))))))))) -> F | H8: =(IF(E8="","",IF(G8="F",0,IF(E8>=80,5,IF(E8>=70,4,IF(E8>=60,3.5,IF(E8>=50,3,IF(E8>=40,2,IF(E8>=33,1,0))))))))) -> 0
A9: ='Student Basic Info'!A9 -> 108 | B9: 9 | C9: 12 | D9: 24 | E9: =IF(B9+C9+D9=0, "", B9+C9+D9) -> 45 | F9: =IF(E9="","", IF(AND(B9 >=8,C9>=17,D9>=8),"Pass","Fail")) -> Fail | G9: =(IF(E9="","",IF(F9="Fail","F",IF(E9>=80,"A+",IF(E9>=70,"A",IF(E9>=60,"A-",IF(E9>=50,"B",IF(E9>=40,"C",IF(E9>=33,"D","F"))))))))) -> F | H9: =(IF(E9="","",IF(G9="F",0,IF(E9>=80,5,IF(E9>=70,4,IF(E9>=60,3.5,IF(E9>=50,3,IF(E9>=40,2,IF(E9>=33,1,0))))))))) -> 0
A10: ='Student Basic Info'!A10 -> 109 | E10: =IF(B10+C10+D10=0, "", B10+C10+D10) | F10: =IF(E10="","", IF(AND(B10 >=8,C10>=17,D10>=8),"Pass","Fail")) | G10: =(IF(E10="","",IF(F10="Fail","F",IF(E10>=80,"A+",IF(E10>=70,"A",IF(E10>=60,"A-",IF(E10>=50,"B",IF(E10>=40,"C",IF(E10>=33,"D","F"))))))))) | H10: =(IF(E10="","",IF(G10="F",0,IF(E10>=80,5,IF(E10>=70,4,IF(E10>=60,3.5,IF(E10>=50,3,IF(E10>=40,2,IF(E10>=33,1,0)))))))))
A11: ='Student Basic Info'!A11 -> 110 | B11: 7 | C11: 7 | D11: 8 | E11: =IF(B11+C11+D11=0, "", B11+C11+D11) -> 22 | F11: =IF(E11="","", IF(AND(B11 >=8,C11>=17,D11>=8),"Pass","Fail")) -> Fail | G11: =(IF(E11="","",IF(F11="Fail","F",IF(E11>=80,"A+",IF(E11>=70,"A",IF(E11>=60,"A-",IF(E11>=50,"B",IF(E11>=40,"C",IF(E11>=33,"D","F"))))))))) -> F | H11: =(IF(E11="","",IF(G11="F",0,IF(E11>=80,5,IF(E11>=70,4,IF(E11>=60,3.5,IF(E11>=50,3,IF(E11>=40,2,IF(E11>=33,1,0))))))))) -> 0
A12: ='Student Basic Info'!A12 -> 111 | E12: =IF(B12+C12+D12=0, "", B12+C12+D12) | F12: =IF(E12="","", IF(AND(B12 >=8,C12>=17,D12>=8),"Pass","Fail")) | G12: =(IF(E12="","",IF(F12="Fail","F",IF(E12>=80,"A+",IF(E12>=70,"A",IF(E12>=60,"A-",IF(E12>=50,"B",IF(E12>=40,"C",IF(E12>=33,"D","F"))))))))) | H12: =(IF(E12="","",IF(G12="F",0,IF(E12>=80,5,IF(E12>=70,4,IF(E12>=60,3.5,IF(E12>=50,3,IF(E12>=40,2,IF(E12>=33,1,0)))))))))
A13: ='Student Basic Info'!A13 -> 112 | E13: =IF(B13+C13+D13=0, "", B13+C13+D13) | F13: =IF(E13="","", IF(AND(B13 >=8,C13>=17,D13>=8),"Pass","Fail")) | G13: =(IF(E13="","",IF(F13="Fail","F",IF(E13>=80,"A+",IF(E13>=70,"A",IF(E13>=60,"A-",IF(E13>=50,"B",IF(E13>=40,"C",IF(E13>=33,"D","F"))))))))) | H13: =(IF(E13="","",IF(G13="F",0,IF(E13>=80,5,IF(E13>=70,4,IF(E13>=60,3.5,IF(E13>=50,3,IF(E13>=40,2,IF(E13>=33,1,0)))))))))
A14: ='Student Basic Info'!A14 -> 113 | B14: 16 | C14: 20 | D14: 25 | E14: =IF(B14+C14+D14=0, "", B14+C14+D14) -> 61 | F14: =IF(E14="","", IF(AND(B14 >=8,C14>=17,D14>=8),"Pass","Fail")) -> Pass | G14: =(IF(E14="","",IF(F14="Fail","F",IF(E14>=80,"A+",IF(E14>=70,"A",IF(E14>=60,"A-",IF(E14>=50,"B",IF(E14>=40,"C",IF(E14>=33,"D","F"))))))))) -> A- | H14: =(IF(E14="","",IF(G14="F",0,IF(E14>=80,5,IF(E14>=70,4,IF(E14>=60,3.5,IF(E14>=50,3,IF(E14>=40,2,IF(E14>=33,1,0))))))))) -> 3.5
A15: ='Student Basic Info'!A15 -> 114 | E15: =IF(B15+C15+D15=0, "", B15+C15+D15) | F15: =IF(E15="","", IF(AND(B15 >=8,C15>=17,D15>=8),"Pass","Fail")) | G15: =(IF(E15="","",IF(F15="Fail","F",IF(E15>=80,"A+",IF(E15>=70,"A",IF(E15>=60,"A-",IF(E15>=50,"B",IF(E15>=40,"C",IF(E15>=33,"D","F"))))))))) | H15: =(IF(E15="","",IF(G15="F",0,IF(E15>=80,5,IF(E15>=70,4,IF(E15>=60,3.5,IF(E15>=50,3,IF(E15>=40,2,IF(E15>=33,1,0)))))))))
A16: ='Student Basic Info'!A16 -> 115 | E16: =IF(B16+C16+D16=0, "", B16+C16+D16) | F16: =IF(E16="","", IF(AND(B16 >=8,C16>=17,D16>=8),"Pass","Fail")) | G16: =(IF(E16="","",IF(F16="Fail","F",IF(E16>=80,"A+",IF(E16>=70,"A",IF(E16>=60,"A-",IF(E16>=50,"B",IF(E16>=40,"C",IF(E16>=33,"D","F"))))))))) | H16: =(IF(E16="","",IF(G16="F",0,IF(E16>=80,5,IF(E16>=70,4,IF(E16>=60,3.5,IF(E16>=50,3,IF(E16>=40,2,IF(E16>=33,1,0)))))))))
A17: ='Student Basic Info'!A17 -> 116 | B17: 8 | C17: 3 | D17: 24 | E17: =IF(B17+C17+D17=0, "", B17+C17+D17) -> 35 | F17: =IF(E17="","", IF(AND(B17 >=8,C17>=17,D17>=8),"Pass","Fail")) -> Fail | G17: =(IF(E17="","",IF(F17="Fail","F",IF(E17>=80,"A+",IF(E17>=70,"A",IF(E17>=60,"A-",IF(E17>=50,"B",IF(E17>=40,"C",IF(E17>=33,"D","F"))))))))) -> F | H17: =(IF(E17="","",IF(G17="F",0,IF(E17>=80,5,IF(E17>=70,4,IF(E17>=60,3.5,IF(E17>=50,3,IF(E17>=40,2,IF(E17>=33,1,0))))))))) -> 0
A18: ='Student Basic Info'!A18 -> 117 | B18: 15 | C18: 27 | D18: 22 | E18: =IF(B18+C18+D18=0, "", B18+C18+D18) -> 64 | F18: =IF(E18="","", IF(AND(B18 >=8,C18>=17,D18>=8),"Pass","Fail")) -> Pass | G18: =(IF(E18="","",IF(F18="Fail","F",IF(E18>=80,"A+",IF(E18>=70,"A",IF(E18>=60,"A-",IF(E18>=50,"B",IF(E18>=40,"C",IF(E18>=33,"D","F"))))))))) -> A- | H18: =(IF(E18="","",IF(G18="F",0,IF(E18>=80,5,IF(E18>=70,4,IF(E18>=60,3.5,IF(E18>=50,3,IF(E18>=40,2,IF(E18>=33,1,0))))))))) -> 3.5
A19: ='Student Basic Info'!A19 -> 118 | B19: 11 | C19: 8 | D19: 18 | E19: =IF(B19+C19+D19=0, "", B19+C19+D19) -> 37 | F19: =IF(E19="","", IF(AND(B19 >=8,C19>=17,D19>=8),"Pass","Fail")) -> Fail | G19: =(IF(E19="","",IF(F19="Fail","F",IF(E19>=80,"A+",IF(E19>=70,"A",IF(E19>=60,"A-",IF(E19>=50,"B",IF(E19>=40,"C",IF(E19>=33,"D","F"))))))))) -> F | H19: =(IF(E19="","",IF(G19="F",0,IF(E19>=80,5,IF(E19>=70,4,IF(E19>=60,3.5,IF(E19>=50,3,IF(E19>=40,2,IF(E19>=33,1,0))))))))) -> 0
A20: ='Student Basic Info'!A20 -> 119 | E20: =IF(B20+C20+D20=0, "", B20+C20+D20) | F20: =IF(E20="","", IF(AND(B20 >=8,C20>=17,D20>=8),"Pass","Fail")) | G20: =(IF(E20="","",IF(F20="Fail","F",IF(E20>=80,"A+",IF(E20>=70,"A",IF(E20>=60,"A-",IF(E20>=50,"B",IF(E20>=40,"C",IF(E20>=33,"D","F"))))))))) | H20: =(IF(E20="","",IF(G20="F",0,IF(E20>=80,5,IF(E20>=70,4,IF(E20>=60,3.5,IF(E20>=50,3,IF(E20>=40,2,IF(E20>=33,1,0)))))))))
A21: ='Student Basic Info'!A21 -> 120 | B21: 6 | C21: 2 | D21: 24 | E21: =IF(B21+C21+D21=0, "", B21+C21+D21) -> 32 | F21: =IF(E21="","", IF(AND(B21 >=8,C21>=17,D21>=8),"Pass","Fail")) -> Fail | G21: =(IF(E21="","",IF(F21="Fail","F",IF(E21>=80,"A+",IF(E21>=70,"A",IF(E21>=60,"A-",IF(E21>=50,"B",IF(E21>=40,"C",IF(E21>=33,"D","F"))))))))) -> F | H21: =(IF(E21="","",IF(G21="F",0,IF(E21>=80,5,IF(E21>=70,4,IF(E21>=60,3.5,IF(E21>=50,3,IF(E21>=40,2,IF(E21>=33,1,0))))))))) -> 0
A22: ='Student Basic Info'!A22 -> 121 | B22: 7 | C22: 6 | D22: 23 | E22: =IF(B22+C22+D22=0, "", B22+C22+D22) -> 36 | F22: =IF(E22="","", IF(AND(B22 >=8,C22>=17,D22>=8),"Pass","Fail")) -> Fail | G22: =(IF(E22="","",IF(F22="Fail","F",IF(E22>=80,"A+",IF(E22>=70,"A",IF(E22>=60,"A-",IF(E22>=50,"B",IF(E22>=40,"C",IF(E22>=33,"D","F"))))))))) -> F | H22: =(IF(E22="","",IF(G22="F",0,IF(E22>=80,5,IF(E22>=70,4,IF(E22>=60,3.5,IF(E22>=50,3,IF(E22>=40,2,IF(E22>=33,1,0))))))))) -> 0
A23: ='Student Basic Info'!A23 -> 122 | B23: 10 | C23: 3 | D23: 18 | E23: =IF(B23+C23+D23=0, "", B23+C23+D23) -> 31 | F23: =IF(E23="","", IF(AND(B23 >=8,C23>=17,D23>=8),"Pass","Fail")) -> Fail | G23: =(IF(E23="","",IF(F23="Fail","F",IF(E23>=80,"A+",IF(E23>=70,"A",IF(E23>=60,"A-",IF(E23>=50,"B",IF(E23>=40,"C",IF(E23>=33,"D","F"))))))))) -> F | H23: =(IF(E23="","",IF(G23="F",0,IF(E23>=80,5,IF(E23>=70,4,IF(E23>=60,3.5,IF(E23>=50,3,IF(E23>=40,2,IF(E23>=33,1,0))))))))) -> 0
A24: ='Student Basic Info'!A24 -> 123 | B24: 11 | C24: 4 | D24: 24 | E24: =IF(B24+C24+D24=0, "", B24+C24+D24) -> 39 | F24: =IF(E24="","", IF(AND(B24 >=8,C24>=17,D24>=8),"Pass","Fail")) -> Fail | G24: =(IF(E24="","",IF(F24="Fail","F",IF(E24>=80,"A+",IF(E24>=70,"A",IF(E24>=60,"A-",IF(E24>=50,"B",IF(E24>=40,"C",IF(E24>=33,"D","F"))))))))) -> F | H24: =(IF(E24="","",IF(G24="F",0,IF(E24>=80,5,IF(E24>=70,4,IF(E24>=60,3.5,IF(E24>=50,3,IF(E24>=40,2,IF(E24>=33,1,0))))))))) -> 0
A25: ='Student Basic Info'!A25 -> 124 | E25: =IF(B25+C25+D25=0, "", B25+C25+D25) | F25: =IF(E25="","", IF(AND(B25 >=8,C25>=17,D25>=8),"Pass","Fail")) | G25: =(IF(E25="","",IF(F25="Fail","F",IF(E25>=80,"A+",IF(E25>=70,"A",IF(E25>=60,"A-",IF(E25>=50,"B",IF(E25>=40,"C",IF(E25>=33,"D","F"))))))))) | H25: =(IF(E25="","",IF(G25="F",0,IF(E25>=80,5,IF(E25>=70,4,IF(E25>=60,3.5,IF(E25>=50,3,IF(E25>=40,2,IF(E25>=33,1,0)))))))))
A26: ='Student Basic Info'!A26 -> 125 | E26: =IF(B26+C26+D26=0, "", B26+C26+D26) | F26: =IF(E26="","", IF(AND(B26 >=8,C26>=17,D26>=8),"Pass","Fail")) | G26: =(IF(E26="","",IF(F26="Fail","F",IF(E26>=80,"A+",IF(E26>=70,"A",IF(E26>=60,"A-",IF(E26>=50,"B",IF(E26>=40,"C",IF(E26>=33,"D","F"))))))))) | H26: =(IF(E26="","",IF(G26="F",0,IF(E26>=80,5,IF(E26>=70,4,IF(E26>=60,3.5,IF(E26>=50,3,IF(E26>=40,2,IF(E26>=33,1,0)))))))))
A27: ='Student Basic Info'!A27 -> 126 | E27: =IF(B27+C27+D27=0, "", B27+C27+D27) | F27: =IF(E27="","", IF(AND(B27 >=8,C27>=17,D27>=8),"Pass","Fail")) | G27: =(IF(E27="","",IF(F27="Fail","F",IF(E27>=80,"A+",IF(E27>=70,"A",IF(E27>=60,"A-",IF(E27>=50,"B",IF(E27>=40,"C",IF(E27>=33,"D","F"))))))))) | H27: =(IF(E27="","",IF(G27="F",0,IF(E27>=80,5,IF(E27>=70,4,IF(E27>=60,3.5,IF(E27>=50,3,IF(E27>=40,2,IF(E27>=33,1,0)))))))))
A28: ='Student Basic Info'!A28 -> 127 | E28: =IF(B28+C28+D28=0, "", B28+C28+D28) | F28: =IF(E28="","", IF(AND(B28 >=8,C28>=17,D28>=8),"Pass","Fail")) | G28: =(IF(E28="","",IF(F28="Fail","F",IF(E28>=80,"A+",IF(E28>=70,"A",IF(E28>=60,"A-",IF(E28>=50,"B",IF(E28>=40,"C",IF(E28>=33,"D","F"))))))))) | H28: =(IF(E28="","",IF(G28="F",0,IF(E28>=80,5,IF(E28>=70,4,IF(E28>=60,3.5,IF(E28>=50,3,IF(E28>=40,2,IF(E28>=33,1,0)))))))))
A29: ='Student Basic Info'!A29 -> 128 | B29: 6 | C29: 9 | D29: 24 | E29: =IF(B29+C29+D29=0, "", B29+C29+D29) -> 39 | F29: =IF(E29="","", IF(AND(B29 >=8,C29>=17,D29>=8),"Pass","Fail")) -> Fail | G29: =(IF(E29="","",IF(F29="Fail","F",IF(E29>=80,"A+",IF(E29>=70,"A",IF(E29>=60,"A-",IF(E29>=50,"B",IF(E29>=40,"C",IF(E29>=33,"D","F"))))))))) -> F | H29: =(IF(E29="","",IF(G29="F",0,IF(E29>=80,5,IF(E29>=70,4,IF(E29>=60,3.5,IF(E29>=50,3,IF(E29>=40,2,IF(E29>=33,1,0))))))))) -> 0
A30: ='Student Basic Info'!A30 -> 129 | B30: 6 | C30: 6 | D30: 8 | E30: =IF(B30+C30+D30=0, "", B30+C30+D30) -> 20 | F30: =IF(E30="","", IF(AND(B30 >=8,C30>=17,D30>=8),"Pass","Fail")) -> Fail | G30: =(IF(E30="","",IF(F30="Fail","F",IF(E30>=80,"A+",IF(E30>=70,"A",IF(E30>=60,"A-",IF(E30>=50,"B",IF(E30>=40,"C",IF(E30>=33,"D","F"))))))))) -> F | H30: =(IF(E30="","",IF(G30="F",0,IF(E30>=80,5,IF(E30>=70,4,IF(E30>=60,3.5,IF(E30>=50,3,IF(E30>=40,2,IF(E30>=33,1,0))))))))) -> 0
