Workbook

Sheet Introduction
D8: RESULT PROCESSING SYSTEM Developed by ALI HOSSAIN
C10: Lecturer in Information & Communication Technology, Bamni Degree College, Companiganj, Noakhali
D11: BSc. in Computer Science & Enginnering, University of Chittagong

Sheet Inputs
A2: Title of Exam | C2: First Year - Term Exam 2024
A4: Number of Science Students
A6: Number of Commerce Students
A8: Number of Arts Students
A10: Total Number of Students | C10: =C4+C6+C8 -> 0
A12: MCQ Mark | C12: 25
A14: CQ Mark | C14: 50
A16: Practical Mark | C16: 25
A18: Total Marks | C18: =C12+C14+C16 -> 100

Sheet Sheet1
A1: Group | B1: Roll | C1: Subject1 | D1: Subject2 | E1: Subject3 | F1: Subject4
A2: Science | B2: 701
A3: Science | B3: 702
A4: Science | B4: 703
A5: Science | B5: 704
A6: Science | B6: 705
A7: Science | B7: 706
A8: Science | B8: 707
A9: Science | B9: 708
A10: Science | B10: 709
A11: Science | B11: 710
A12: Commerce
A13: Commerce
A14: Commerce
A15: Commerce
A16: Commerce
A17: Arts
A18: Arts
A19: Arts
A20: Arts
A21: Arts

Sheet Student Basic Info
A1: ID | B1: Group | C1: Name | D1: Father | E1: Mother | F1: Gender | G1: Religion | H1: Address | I1: Contact | J1: Session | K1: Name in Bengali | L1: Father in Bengali | M1: Mother in Bengali | N1: Remarks
A2: 701 | B2: Science | C2: Tanjila Mostafa Tasnim | D2: Golam Mostafa | E2: Farjana Mostafa | F2: Female | G2: Islam | H2: Rampur, Companiganj, Noakhali | I2: 01884-168997 | J2: 2023-2024
A3: 702 | B3: Science | C3: Foyez Ahmed | D3: Hafim Ahmed | E3: Amena Aktar | F3: Male | G3: Islam | H3: Rampur, Companiganj, Noakhali | I3: 01821-044223 | J3: 2023-2024
A4: 703 | B4: Science | C4: Zannatul Nayem | D4: Nur Islam | E4: Bibi kulsum | F4: Female | G4: Islam | H4: Rampur, Companiganj, Noakhali | I4: 01826-008578 | J4: 2023-2024
A5: 704 | B5: Science | C5: Farmana Nusrat Chowdhury | D5: Neyamot Ullah Chowdhury | E5: Khaleda Akter | F5: Female | G5: Islam | H5: Rampur, Companiganj, Noakhali | I5: 1824826416 | J5: 2023-2024
A6: 705 | B6: Science | C6: Zannatul Ferdaus | D6: Ruhul Amin | E6: Fahima Akter | F6: Female | G6: Islam | H6: Rampur, Companiganj, Noakhali | I6: 01815502619 / 01892028139 | J6: 2023-2024
A7: 706 | B7: Science | C7: Abdul Alim Shawon | D7: Abdul Hadith | E7: Rowshona Ara Begum | F7: Male | G7: Islam | H7: Rampur, Companiganj, Noakhali | I7: 01827-220450 | J7: 2023-2024
A8: 707 | B8: Science | C8: Sharmin Aktar | D8: Zakar Hosain Faruk | E8: Nur Nahar Nayon | F8: Female | G8: Islam | H8: Rampur, Companiganj, Noakhali | I8: 01811-284099 | J8: 2023-2024
A9: 708 | B9: Science | C9: Nafisa Aktar Prova | D9: Nur Uddin | E9: Bibi Fatema Aktar | F9: Female | G9: Islam | H9: Rampur, Companiganj, Noakhali | I9: 01715-913980 | J9: 2023-2024
A10: 709 | B10: Science | C10: Nafisa Anjum Prena | D10: Nur Uddin | E10: Bibi Fatema Akter | F10: Female | G10: Islam | H10: Rampur, Companiganj, Noakhali | I10: 01854-017519 | J10: 2023-2024
A11: 710 | B11: Science | C11: Umme Tabassum Maisha | D11: Md. Shelim Ullah | E11: Shahanaj Aktar | F11: Female | G11: Islam | H11: Rampur, Companiganj, Noakhali | J11: 2023-2024
A12: 711 | B12: Science | C12: Rakhi Ahasan | D12: Asan Ullah | E12: Amena Begum | F12: Female | G12: Islam | H12: Rampur, Companiganj, Noakhali | I12: 01815-960966 | J12: 2023-2024
A13: 712 | B13: Science | C13: Nadiyatul Nayem | D13: Kamal Uddin | E13: Kohinur Aktar | F13: Female | G13: Islam | H13: Rampur, Companiganj, Noakhali | I13: 01318-816818 | J13: 2023-2024
A14: 713 | B14: Science | C14: Zannatul Ferdaus Fariha | D14: Muhammad Sofi Ullah | E14: Zoynob Aktar | F14: Female | G14: Islam | H14: Rampur, Companiganj, Noakhali | I14: 01817-412851 | J14: 2023-2024
A15: 714 | B15: Science | C15: Khadijatul Kubra | D15: Golam Sorwar | E15: Bibi Kulsum | F15: Female | G15: Islam | H15: Rampur, Companiganj, Noakhali | I15: 01815-536524 | J15: 2023-2024
A16: 715 | B16: Science | C16: Tanjila Islam | D16: Nur Islam | E16: Zannatul Ferdaus | F16: Female | G16: Islam | H16: Rampur, Companiganj, Noakhali | I16: 01601-365237 | J16: 2023-2024
A17: 716 | B17: Science | C17: Nazmun Nahar Rikha | D17: Md. Alamgir Hosain | E17: Shamsun Nahar | F17: Female | G17: Islam | H17: Rampur, Companiganj, Noakhali | I17: 01824-105005 | J17: 2023-2024
A18: 717 | B18: Science | C18: Umme Rojina | D18: Nozrul Islam | E18: Rahela Aktar | F18: Female | G18: Islam | H18: Rampur, Companiganj, Noakhali | I18: 1715829255 | J18: 2023-2024
A19: 718 | B19: Science | C19: Zannatul Ferdaus | D19: Shahab Uddin | E19: Marjahan | F19: Female | G19: Islam | H19: Rampur, Companiganj, Noakhali | I19: 01875-096313 | J19: 2023-2024
A20: 719 | B20: Science | C20: Shazeda Amin Shuchi | D20: Amir Hosain | E20: Fatema Aktar | F20: Female | G20: Islam | H20: Rampur, Companiganj, Noakhali | I20: 01820-942992 | J20: 2023-2024
A21: 720 | B21: Science | C21: Farzana Aktar | D21: Atik Ullah | E21: Nazman Nahar | F21: Female | G21: Islam | H21: Rampur, Companiganj, Noakhali | I21: 01881-334735 | J21: 2023-2024
A22: 721 | B22: Science | C22: Nowrin Faiza Niduwa | D22: Zashim Uddin | E22: Sultana Razia | F22: Female | G22: Islam | H22: Rampur, Companiganj, Noakhali | I22: 01818-383576 | J22: 2023-2024
A23: 722 | B23: Science | C23: Mahmudau Rahman Munna | D23: Msotafizur Rahman | E23: Ferdaus Ara | F23: Male | G23: Islam | H23: Rampur, Companiganj, Noakhali | I23: 0185-9460020 | J23: 2023-2024
A24: 723 | B24: Science | C24: Shamsuzzaman | D24: Ruhal Amin | E24: Shamsun Nahar | F24: Male | G24: Islam | H24: Rampur, Companiganj, Noakhali | I24: 01609-756268 | J24: 2023-2024
A25: 724 | B25: Science | C25: Dipto Chandra Das | D25: Nirmon Chandra Das | E25: Anjona Bala Das | F25: Male | G25: Hindu | H25: Rampur, Companiganj, Noakhali | I25: 01840-637020 | J25: 2023-2024
A26: 725 | B26: Science | C26: Shorfuddin Nayem | D26: Dalowar Hosain | E26: Razia Sultana | F26: Male | G26: Islam | H26: Rampur, Companiganj, Noakhali | I26: 01885-048969 | J26: 2023-2024
A27: 726 | B27: Science | C27: Mosaddek Ali | D27: Korban Ali | E27: Bibi Kulsum | F27: Male | G27: Islam | H27: Rampur, Companiganj, Noakhali | I27: 01787-254740 | J27: 2023-2024
A28: 727 | B28: Science | C28: Fahmida Sultana | D28: Md. Zajam Hosain | E28: Bibi Fatema Khatun | F28: Female | G28: Islam | H28: Rampur, Companiganj, Noakhali | I28: 01823-710538 | J28: 2023-2024
A29: 728 | B29: Science | C29: Aditya Chandra Das (Akash) | D29: Dilip Chandra Das | E29: Archana Bala Das | F29: Male | G29: Hindu | H29: Rampur, Companiganj, Noakhali | I29: 01818-887179 | J29: 2023-2024
A30: 729 | B30: Science | C30: Golam Kibriya | D30: Zakir Hosain | E30: Late Rabeya Bosri | F30: Male | G30: Islam | H30: Rampur, Companiganj, Noakhali | I30: 01867-810051 | J30: 2023-2024
... A39: 738 | B39: Science | C39: Arpita Rani Bhoumik | D39: Kiriti Kumar Nath | E39: Rani Bhowmil | F39: Female | G39: Hindu | H39: Rampur, Companiganj, Noakhali | I39: 01763-826298 | J39: 2023-2024
A40: 739 | B40: Science | C40: Israt Zahan Shrabonti | D40: Abul Hosain | E40: Shaleha Begum | F40: Female | G40: Islam | H40: Rampur, Companiganj, Noakhali | J40: 2023-2024
A41: 740 | B41: Science | C41: Fatema Zannat | D41: Motahar Hossain | E41: Saleha Begum | F41: Female | G41: Islam | H41: Rampur, Companiganj, Noakhali | I41: 01861-661157 | J41: 2023-2024
A42: 741 | B42: Science | C42: Rezmin Aktar | D42: Kamal Uddin | E42: Bibi Zulekha | F42: Female | G42: Islam | H42: Rampur, Companiganj, Noakhali | J42: 2023-2024
A43: 742 | B43: Science | C43: Md. Shohrab Hosain | D43: Feroz Alom | E43: Rokeya Begum | F43: Male | G43: Islam | H43: Rampur, Companiganj, Noakhali | I43: 01825-278479 | J43: 2023-2024
A44: 743 | B44: Science | C44: Umme Habiba | D44: Md. Nur Nobi | E44: Fatema Begum | F44: Female | G44: Islam | H44: Rampur, Companiganj, Noakhali | I44: 01815-425492 | J44: 2023-2024
A45: 744 | B45: Science | C45: Tarek Rahman Tamin | D45: Mozubur Rahman | E45: Kawsar Khanom Alo | F45: Male | G45: Islam | H45: Rampur, Companiganj, Noakhali | I45: 01860-644620 | J45: 2023-2024
A46: 745 | B46: Science | C46: Nabiha Nusrat | D46: Md. Moin Uddin | E46: Nasima Aktar | F46: Female | G46: Islam | H46: Rampur, Companiganj, Noakhali | I46: 01828-777699 | J46: 2023-2024
A47: 746 | B47: Science | C47: Sharika Mahzabin | D47: Md. Nurul Amin | E47: Sufiya Khatun | F47: Female | G47: Islam | H47: Rampur, Companiganj, Noakhali | I47: 01821-993838 | J47: 2023-2024
A48: 747 | B48: Science | C48: Jahedul Islam | D48: Md. Shohidul Islam | E48: Fatema Khatun | F48: Male | G48: Islam | H48: Rampur, Companiganj, Noakhali | I48: 01894-009841 | J48: 2023-2024
...

Sheet Prev. Academic
A1: ID | B1: Institution Name | C1: Group | D1: Session | E1: GPA | F1: Board Name | G1: Roll | H1: Reg No
A2: ='Student Basic Info'!A2 -> 701 | B2: Bamni High School | C2: Science | D2: 2021-22 | E2: 5 | F2: Cumilla | G2: 197409 | H2: 197409
A3: ='Student Basic Info'!A3 -> 702 | B3: Bamni High School | C3: Science | D3: 2021-22 | E3: 5 | F3: Cumilla | G3: 197409 | H3: 197409
A4: ='Student Basic Info'!A4 -> 703 | B4: Bamni High School | C4: Science | D4: 2021-22 | E4: 5 | F4: Cumilla | G4: 197409 | H4: 197409
A5: ='Student Basic Info'!A5 -> 704 | B5: Bamni High School | C5: Science | D5: 2021-22 | E5: 5 | F5: Cumilla | G5: 197409 | H5: 197409
A6: ='Student Basic Info'!A6 -> 705 | B6: Bamni High School | C6: Science | D6: 2021-22 | E6: 5 | F6: Cumilla | G6: 197409 | H6: 197409
A7: ='Student Basic Info'!A7 -> 706 | B7: Bamni High School | C7: Science | D7: 2021-22 | E7: 5 | F7: Cumilla | G7: 197409 | H7: 197409
A8: ='Student Basic Info'!A8 -> 707 | B8: Bamni High School | C8: Science | D8: 2021-22 | E8: 5 | F8: Cumilla | G8: 197409 | H8: 197409
A9: ='Student Basic Info'!A9 -> 708 | B9: Bamni High School | C9: Science | D9: 2021-22 | E9: 5 | F9: Cumilla | G9: 197409 | H9: 197409
A10: ='Student Basic Info'!A10 -> 709 | B10: Bamni High School | C10: Science | D10: 2021-22 | E10: 5 | F10: Cumilla | G10: 197409 | H10: 197409
A11: ='Student Basic Info'!A11 -> 710 | B11: Bamni High School | C11: Science | D11: 2021-22 | E11: 5 | F11: Cumilla | G11: 197409 | H11: 197409
A12: ='Student Basic Info'!A12 -> 711 | B12: Bamni High School | C12: Science | D12: 2021-22 | E12: 5 | F12: Cumilla | G12: 197409 | H12: 197409
A13: ='Student Basic Info'!A13 -> 712 | B13: Bamni High School | C13: Science | D13: 2021-22 | E13: 5 | F13: Cumilla | G13: 197409 | H13: 197409
... A88: ='Student Basic Info'!A88 -> 6812 | B88: Bamni High School | C88: Science | D88: 2021-23 | E88: 6 | F88: Cumilla | G88: 197409 | H88: 197409

Sheet SubjectList
A1: ID | B1: Compulsory1 | C1: Compulsory2 | D1: Compulsory1 | E1: Subject1 | F1: Subject2 | G1: Subject3 | H1: Subject4 | I1: Optioinal
A2: ='Student Basic Info'!A2 -> 701 | B2: Bangla | C2: English | D2: ICT | E2: Physics | F2: Chemistry | G2: Biology | H2: Math | I2: =H2 -> Math
A3: ='Student Basic Info'!A3 -> 702 | B3: Bangla | C3: English | D3: ICT | E3: Physics | F3: Chemistry | G3: Biology | H3: Math | I3: =H3 -> Math
A4: ='Student Basic Info'!A4 -> 703 | B4: Bangla | C4: English | D4: ICT | E4: Physics | F4: Chemistry | G4: Biology | H4: Math | I4: =H4 -> Math
A5: ='Student Basic Info'!A5 -> 704 | B5: Bangla | C5: English | D5: ICT | E5: Physics | F5: Chemistry | G5: Biology | H5: Math | I5: =H5 -> Math
A6: ='Student Basic Info'!A6 -> 705 | B6: Bangla | C6: English | D6: ICT | E6: Physics | F6: Chemistry | G6: Biology | H6: Math | I6: =H6 -> Math
A7: ='Student Basic Info'!A7 -> 706 | B7: Bangla | C7: English | D7: ICT | E7: Physics | F7: Chemistry | G7: Biology | H7: Math | I7: =H7 -> Math
A8: ='Student Basic Info'!A8 -> 707 | B8: Bangla | C8: English | D8: ICT | E8: Physics | F8: Chemistry | G8: Biology | H8: Math | I8: =H8 -> Math
A9: ='Student Basic Info'!A9 -> 708 | B9: Bangla | C9: English | D9: ICT | E9: Physics | F9: Chemistry | G9: Biology | H9: Math | I9: =H9 -> Math
A10: ='Student Basic Info'!A10 -> 709 | B10: Bangla | C10: English | D10: ICT | E10: Physics | F10: Chemistry | G10: Biology | H10: Math | I10: =H10 -> Math
A11: ='Student Basic Info'!A11 -> 710 | B11: Bangla | C11: English | D11: ICT | E11: Physics | F11: Chemistry | G11: Biology | H11: Math | I11: =H11 -> Math
A12: ='Student Basic Info'!A12 -> 711 | B12: Bangla | C12: English | D12: ICT | E12: Physics | F12: Chemistry | G12: Biology | H12: Math | I12: =H12 -> Math
A13: ='Student Basic Info'!A13 -> 712 | B13: Bangla | C13: English | D13: ICT | E13: Physics | F13: Chemistry | G13: Biology | H13: Math | I13: =H13 -> Math
... A88: ='Student Basic Info'!A88 -> 6812 | B88: Bangla | C88: English | D88: ICT | E88: Physics | F88: Chemistry | G88: Biology | H88: Math | I88: =H88 -> Math

Sheet Bangla
A1: Roll | B1: Marks MCQ | C1: Marks CQ | D1: Total Marks | E1: Result | F1: Grade | G1: GPA
A2: ='Student Basic Info'!A2 -> 701 | C2: 60 | D2: =IF(B2+C2=0, "", B2+C2) -> 60 | E2: =IF(D2="","", IF(C2>=33,"Pass","Fail")) -> Pass | F2: =(IF(D2="","",IF(E2="Fail","F",IF(D2>=80,"A+",IF(D2>=70,"A",IF(D2>=60,"A-",IF(D2>=50,"B",IF(D2>=40,"C",IF(D2>=33,"D","F"))))))))) -> A- | G2: =(IF(D2="","",IF(F2="F",0,IF(D2>=80,5,IF(D2>=70,4,IF(D2>=60,3.5,IF(D2>=50,3,IF(D2>=40,2,IF(D2>=33,1,0))))))))) -> 3.5
A3: ='Student Basic Info'!A3 -> 702 | D3: =IF(B3+C3=0, "", B3+C3) | E3: =IF(D3="","", IF(C3>=33,"Pass","Fail")) | F3: =(IF(D3="","",IF(E3="Fail","F",IF(D3>=80,"A+",IF(D3>=70,"A",IF(D3>=60,"A-",IF(D3>=50,"B",IF(D3>=40,"C",IF(D3>=33,"D","F"))))))))) | G3: =(IF(D3="","",IF(F3="F",0,IF(D3>=80,5,IF(D3>=70,4,IF(D3>=60,3.5,IF(D3>=50,3,IF(D3>=40,2,IF(D3>=33,1,0)))))))))
A4: ='Student Basic Info'!A4 -> 703 | D4: =IF(B4+C4=0, "", B4+C4) | E4: =IF(D4="","", IF(C4>=33,"Pass","Fail")) | F4: =(IF(D4="","",IF(E4="Fail","F",IF(D4>=80,"A+",IF(D4>=70,"A",IF(D4>=60,"A-",IF(D4>=50,"B",IF(D4>=40,"C",IF(D4>=33,"D","F"))))))))) | G4: =(IF(D4="","",IF(F4="F",0,IF(D4>=80,5,IF(D4>=70,4,IF(D4>=60,3.5,IF(D4>=50,3,IF(D4>=40,2,IF(D4>=33,1,0)))))))))
A5: ='Student Basic Info'!A5 -> 704 | C5: 62 | D5: =IF(B5+C5=0, "", B5+C5) -> 62 | E5: =IF(D5="","", IF(C5>=33,"Pass","Fail")) -> Pass | F5: =(IF(D5="","",IF(E5="Fail","F",IF(D5>=80,"A+",IF(D5>=70,"A",IF(D5>=60,"A-",IF(D5>=50,"B",IF(D5>=40,"C",IF(D5>=33,"D","F"))))))))) -> A- | G5: =(IF(D5="","",IF(F5="F",0,IF(D5>=80,5,IF(D5>=70,4,IF(D5>=60,3.5,IF(D5>=50,3,IF(D5>=40,2,IF(D5>=33,1,0))))))))) -> 3.5
A6: ='Student Basic Info'!A6 -> 705 | D6: =IF(B6+C6=0, "", B6+C6) | E6: =IF(D6="","", IF(C6>=33,"Pass","Fail")) | F6: =(IF(D6="","",IF(E6="Fail","F",IF(D6>=80,"A+",IF(D6>=70,"A",IF(D6>=60,"A-",IF(D6>=50,"B",IF(D6>=40,"C",IF(D6>=33,"D","F"))))))))) | G6: =(IF(D6="","",IF(F6="F",0,IF(D6>=80,5,IF(D6>=70,4,IF(D6>=60,3.5,IF(D6>=50,3,IF(D6>=40,2,IF(D6>=33,1,0)))))))))
A7: ='Student Basic Info'!A7 -> 706 | D7: =IF(B7+C7=0, "", B7+C7) | E7: =IF(D7="","", IF(C7>=33,"Pass","Fail")) | F7: =(IF(D7="","",IF(E7="Fail","F",IF(D7>=80,"A+",IF(D7>=70,"A",IF(D7>=60,"A-",IF(D7>=50,"B",IF(D7>=40,"C",IF(D7>=33,"D","F"))))))))) | G7: =(IF(D7="","",IF(F7="F",0,IF(D7>=80,5,IF(D7>=70,4,IF(D7>=60,3.5,IF(D7>=50,3,IF(D7>=40,2,IF(D7>=33,1,0)))))))))
A8: ='Student Basic Info'!A8 -> 707 | D8: =IF(B8+C8=0, "", B8+C8) | E8: =IF(D8="","", IF(C8>=33,"Pass","Fail")) | F8: =(IF(D8="","",IF(E8="Fail","F",IF(D8>=80,"A+",IF(D8>=70,"A",IF(D8>=60,"A-",IF(D8>=50,"B",IF(D8>=40,"C",IF(D8>=33,"D","F"))))))))) | G8: =(IF(D8="","",IF(F8="F",0,IF(D8>=80,5,IF(D8>=70,4,IF(D8>=60,3.5,IF(D8>=50,3,IF(D8>=40,2,IF(D8>=33,1,0)))))))))
A9: ='Student Basic Info'!A9 -> 708 | C9: 62 | D9: =IF(B9+C9=0, "", B9+C9) -> 62 | E9: =IF(D9="","", IF(C9>=33,"Pass","Fail")) -> Pass | F9: =(IF(D9="","",IF(E9="Fail","F",IF(D9>=80,"A+",IF(D9>=70,"A",IF(D9>=60,"A-",IF(D9>=50,"B",IF(D9>=40,"C",IF(D9>=33,"D","F"))))))))) -> A- | G9: =(IF(D9="","",IF(F9="F",0,IF(D9>=80,5,IF(D9>=70,4,IF(D9>=60,3.5,IF(D9>=50,3,IF(D9>=40,2,IF(D9>=33,1,0))))))))) -> 3.5
A10: ='Student Basic Info'!A10 -> 709 | C10: 63 | D10: =IF(B10+C10=0, "", B10+C10) -> 63 | E10: =IF(D10="","", IF(C10>=33,"Pass","Fail")) -> Pass | F10: =(IF(D10="","",IF(E10="Fail","F",IF(D10>=80,"A+",IF(D10>=70,"A",IF(D10>=60,"A-",IF(D10>=50,"B",IF(D10>=40,"C",IF(D10>=33,"D","F"))))))))) -> A- | G10: =(IF(D10="","",IF(F10="F",0,IF(D10>=80,5,IF(D10>=70,4,IF(D10>=60,3.5,IF(D10>=50,3,IF(D10>=40,2,IF(D10>=33,1,0))))))))) -> 3.5
A11: ='Student Basic Info'!A11 -> 710 | C11: 56 | D11: =IF(B11+C11=0, "", B11+C11) -> 56 | E11: =IF(D11="","", IF(C11>=33,"Pass","Fail")) -> Pass | F11: =(IF(D11="","",IF(E11="Fail","F",IF(D11>=80,"A+",IF(D11>=70,"A",IF(D11>=60,"A-",IF(D11>=50,"B",IF(D11>=40,"C",IF(D11>=33,"D","F"))))))))) -> B | G11: =(IF(D11="","",IF(F11="F",0,IF(D11>=80,5,IF(D11>=70,4,IF(D11>=60,3.5,IF(D11>=50,3,IF(D11>=40,2,IF(D11>=33,1,0))))))))) -> 3
A12: ='Student Basic Info'!A12 -> 711 | D12: =IF(B12+C12=0, "", B12+C12) | E12: =IF(D12="","", IF(C12>=33,"Pass","Fail")) | F12: =(IF(D12="","",IF(E12="Fail","F",IF(D12>=80,"A+",IF(D12>=70,"A",IF(D12>=60,"A-",IF(D12>=50,"B",IF(D12>=40,"C",IF(D12>=33,"D","F"))))))))) | G12: =(IF(D12="","",IF(F12="F",0,IF(D12>=80,5,IF(D12>=70,4,IF(D12>=60,3.5,IF(D12>=50,3,IF(D12>=40,2,IF(D12>=33,1,0)))))))))
A13: ='Student Basic Info'!A13 -> 712 | C13: 50 | D13: =IF(B13+C13=0, "", B13+C13) -> 50 | E13: =IF(D13="","", IF(C13>=33,"Pass","Fail")) -> Pass | F13: =(IF(D13="","",IF(E13="Fail","F",IF(D13>=80,"A+",IF(D13>=70,"A",IF(D13>=60,"A-",IF(D13>=50,"B",IF(D13>=40,"C",IF(D13>=33,"D","F"))))))))) -> B | G13: =(IF(D13="","",IF(F13="F",0,IF(D13>=80,5,IF(D13>=70,4,IF(D13>=60,3.5,IF(D13>=50,3,IF(D13>=40,2,IF(D13>=33,1,0))))))))) -> 3
A14: ='Student Basic Info'!A14 -> 713 | C14: 57 | D14: =IF(B14+C14=0, "", B14+C14) -> 57 | E14: =IF(D14="","", IF(C14>=33,"Pass","Fail")) -> Pass | F14: =(IF(D14="","",IF(E14="Fail","F",IF(D14>=80,"A+",IF(D14>=70,"A",IF(D14>=60,"A-",IF(D14>=50,"B",IF(D14>=40,"C",IF(D14>=33,"D","F"))))))))) -> B | G14: =(IF(D14="","",IF(F14="F",0,IF(D14>=80,5,IF(D14>=70,4,IF(D14>=60,3.5,IF(D14>=50,3,IF(D14>=40,2,IF(D14>=33,1,0))))))))) -> 3
A15: ='Student Basic Info'!A15 -> 714 | C15: 64 | D15: =IF(B15+C15=0, "", B15+C15) -> 64 | E15: =IF(D15="","", IF(C15>=33,"Pass","Fail")) -> Pass | F15: =(IF(D15="","",IF(E15="Fail","F",IF(D15>=80,"A+",IF(D15>=70,"A",IF(D15>=60,"A-",IF(D15>=50,"B",IF(D15>=40,"C",IF(D15>=33,"D","F"))))))))) -> A- | G15: =(IF(D15="","",IF(F15="F",0,IF(D15>=80,5,IF(D15>=70,4,IF(D15>=60,3.5,IF(D15>=50,3,IF(D15>=40,2,IF(D15>=33,1,0))))))))) -> 3.5
A16: ='Student Basic Info'!A16 -> 715 | C16: 41 | D16: =IF(B16+C16=0, "", B16+C16) -> 41 | E16: =IF(D16="","", IF(C16>=33,"Pass","Fail")) -> Pass | F16: =(IF(D16="","",IF(E16="Fail","F",IF(D16>=80,"A+",IF(D16>=70,"A",IF(D16>=60,"A-",IF(D16>=50,"B",IF(D16>=40,"C",IF(D16>=33,"D","F"))))))))) -> C | G16: =(IF(D16="","",IF(F16="F",0,IF(D16>=80,5,IF(D16>=70,4,IF(D16>=60,3.5,IF(D16>=50,3,IF(D16>=40,2,IF(D16>=33,1,0))))))))) -> 2
A17: ='Student Basic Info'!A17 -> 716 | C17: 40 | D17: =IF(B17+C17=0, "", B17+C17) -> 40 | E17: =IF(D17="","", IF(C17>=33,"Pass","Fail")) -> Pass | F17: =(IF(D17="","",IF(E17="Fail","F",IF(D17>=80,"A+",IF(D17>=70,"A",IF(D17>=60,"A-",IF(D17>=50,"B",IF(D17>=40,"C",IF(D17>=33,"D","F"))))))))) -> C | G17: =(IF(D17="","",IF(F17="F",0,IF(D17>=80,5,IF(D17>=70,4,IF(D17>=60,3.5,IF(D17>=50,3,IF(D17>=40,2,IF(D17>=33,1,0))))))))) -> 2
A18: ='Student Basic Info'!A18 -> 717 | C18: 50 | D18: =IF(B18+C18=0, "", B18+C18) -> 50 | E18: =IF(D18="","", IF(C18>=33,"Pass","Fail")) -> Pass | F18: =(IF(D18="","",IF(E18="Fail","F",IF(D18>=80,"A+",IF(D18>=70,"A",IF(D18>=60,"A-",IF(D18>=50,"B",IF(D18>=40,"C",IF(D18>=33,"D","F"))))))))) -> B | G18: =(IF(D18="","",IF(F18="F",0,IF(D18>=80,5,IF(D18>=70,4,IF(D18>=60,3.5,IF(D18>=50,3,IF(D18>=40,2,IF(D18>=33,1,0))))))))) -> 3
A19: ='Student Basic Info'!A19 -> 718 | D19: =IF(B19+C19=0, "", B19+C19) | E19: =IF(D19="","", IF(C19>=33,"Pass","Fail")) | F19: =(IF(D19="","",IF(E19="Fail","F",IF(D19>=80,"A+",IF(D19>=70,"A",IF(D19>=60,"A-",IF(D19>=50,"B",IF(D19>=40,"C",IF(D19>=33,"D","F"))))))))) | G19: =(IF(D19="","",IF(F19="F",0,IF(D19>=80,5,IF(D19>=70,4,IF(D19>=60,3.5,IF(D19>=50,3,IF(D19>=40,2,IF(D19>=33,1,0)))))))))
A20: ='Student Basic Info'!A20 -> 719 | C20: 55 | D20: =IF(B20+C20=0, "", B20+C20) -> 55 | E20: =IF(D20="","", IF(C20>=33,"Pass","Fail")) -> Pass | F20: =(IF(D20="","",IF(E20="Fail","F",IF(D20>=80,"A+",IF(D20>=70,"A",IF(D20>=60,"A-",IF(D20>=50,"B",IF(D20>=40,"C",IF(D20>=33,"D","F"))))))))) -> B | G20: =(IF(D20="","",IF(F20="F",0,IF(D20>=80,5,IF(D20>=70,4,IF(D20>=60,3.5,IF(D20>=50,3,IF(D20>=40,2,IF(D20>=33,1,0))))))))) -> 3
A21: ='Student Basic Info'!A21 -> 720 | C21: 50 | D21: =IF(B21+C21=0, "", B21+C21) -> 50 | E21: =IF(D21="","", IF(C21>=33,"Pass","Fail")) -> Pass | F21: =(IF(D21="","",IF(E21="Fail","F",IF(D21>=80,"A+",IF(D21>=70,"A",IF(D21>=60,"A-",IF(D21>=50,"B",IF(D21>=40,"C",IF(D21>=33,"D","F"))))))))) -> B | G21: =(IF(D21="","",IF(F21="F",0,IF(D21>=80,5,IF(D21>=70,4,IF(D21>=60,3.5,IF(D21>=50,3,IF(D21>=40,2,IF(D21>=33,1,0))))))))) -> 3
A22: ='Student Basic Info'!A22 -> 721 | D22: =IF(B22+C22=0, "", B22+C22) | E22: =IF(D22="","", IF(C22>=33,"Pass","Fail")) | F22: =(IF(D22="","",IF(E22="Fail","F",IF(D22>=80,"A+",IF(D22>=70,"A",IF(D22>=60,"A-",IF(D22>=50,"B",IF(D22>=40,"C",IF(D22>=33,"D","F"))))))))) | G22: =(IF(D22="","",IF(F22="F",0,IF(D22>=80,5,IF(D22>=70,4,IF(D22>=60,3.5,IF(D22>=50,3,IF(D22>=40,2,IF(D22>=33,1,0)))))))))
A23: ='Student Basic Info'!A23 -> 722 | C23: 57 | D23: =IF(B23+C23=0, "", B23+C23) -> 57 | E23: =IF(D23="","", IF(C23>=33,"Pass","Fail")) -> Pass | F23: =(IF(D23="","",IF(E23="Fail","F",IF(D23>=80,"A+",IF(D23>=70,"A",IF(D23>=60,"A-",IF(D23>=50,"B",IF(D23>=40,"C",IF(D23>=33,"D","F"))))))))) -> B | G23: =(IF(D23="","",IF(F23="F",0,IF(D23>=80,5,IF(D23>=70,4,IF(D23>=60,3.5,IF(D23>=50,3,IF(D23>=40,2,IF(D23>=33,1,0))))))))) -> 3
A24: ='Student Basic Info'!A24 -> 723 | C24: 72 | D24: =IF(B24+C24=0, "", B24+C24) -> 72 | E24: =IF(D24="","", IF(C24>=33,"Pass","Fail")) -> Pass | F24: =(IF(D24="","",IF(E24="Fail","F",IF(D24>=80,"A+",IF(D24>=70,"A",IF(D24>=60,"A-",IF(D24>=50,"B",IF(D24>=40,"C",IF(D24>=33,"D","F"))))))))) -> A | G24: =(IF(D24="","",IF(F24="F",0,IF(D24>=80,5,IF(D24>=70,4,IF(D24>=60,3.5,IF(D24>=50,3,IF(D24>=40,2,IF(D24>=33,1,0))))))))) -> 4
A25: ='Student Basic Info'!A25 -> 724 | C25: 46 | D25: =IF(B25+C25=0, "", B25+C25) -> 46 | E25: =IF(D25="","", IF(C25>=33,"Pass","Fail")) -> Pass | F25: =(IF(D25="","",IF(E25="Fail","F",IF(D25>=80,"A+",IF(D25>=70,"A",IF(D25>=60,"A-",IF(D25>=50,"B",IF(D25>=40,"C",IF(D25>=33,"D","F"))))))))) -> C | G25: =(IF(D25="","",IF(F25="F",0,IF(D25>=80,5,IF(D25>=70,4,IF(D25>=60,3.5,IF(D25>=50,3,IF(D25>=40,2,IF(D25>=33,1,0))))))))) -> 2
A26: ='Student Basic Info'!A26 -> 725 | C26: 41 | D26: =IF(B26+C26=0, "", B26+C26) -> 41 | E26: =IF(D26="","", IF(C26>=33,"Pass","Fail")) -> Pass | F26: =(IF(D26="","",IF(E26="Fail","F",IF(D26>=80,"A+",IF(D26>=70,"A",IF(D26>=60,"A-",IF(D26>=50,"B",IF(D26>=40,"C",IF(D26>=33,"D","F"))))))))) -> C | G26: =(IF(D26="","",IF(F26="F",0,IF(D26>=80,5,IF(D26>=70,4,IF(D26>=60,3.5,IF(D26>=50,3,IF(D26>=40,2,IF(D26>=33,1,0))))))))) -> 2
A27: ='Student Basic Info'!A27 -> 726 | D27: =IF(B27+C27=0, "", B27+C27) | E27: =IF(D27="","", IF(C27>=33,"Pass","Fail")) | F27: =(IF(D27="","",IF(E27="Fail","F",IF(D27>=80,"A+",IF(D27>=70,"A",IF(D27>=60,"A-",IF(D27>=50,"B",IF(D27>=40,"C",IF(D27>=33,"D","F"))))))))) | G27: =(IF(D27="","",IF(F27="F",0,IF(D27>=80,5,IF(D27>=70,4,IF(D27>=60,3.5,IF(D27>=50,3,IF(D27>=40,2,IF(D27>=33,1,0)))))))))
A28: ='Student Basic Info'!A28 -> 727 | C28: 62 | D28: =IF(B28+C28=0, "", B28+C28) -> 62 | E28: =IF(D28="","", IF(C28>=33,"Pass","Fail")) -> Pass | F28: =(IF(D28="","",IF(E28="Fail","F",IF(D28>=80,"A+",IF(D28>=70,"A",IF(D28>=60,"A-",IF(D28>=50,"B",IF(D28>=40,"C",IF(D28>=33,"D","F"))))))))) -> A- | G28: =(IF(D28="","",IF(F28="F",0,IF(D28>=80,5,IF(D28>=70,4,IF(D28>=60,3.5,IF(D28>=50,3,IF(D28>=40,2,IF(D28>=33,1,0))))))))) -> 3.5
A29: ='Student Basic Info'!A29 -> 728 | C29: 40 | D29: =IF(B29+C29=0, "", B29+C29) -> 40 | E29: =IF(D29="","", IF(C29>=33,"Pass","Fail")) -> Pass | F29: =(IF(D29="","",IF(E29="Fail","F",IF(D29>=80,"A+",IF(D29>=70,"A",IF(D29>=60,"A-",IF(D29>=50,"B",IF(D29>=40,"C",IF(D29>=33,"D","F"))))))))) -> C | G29: =(IF(D29="","",IF(F29="F",0,IF(D29>=80,5,IF(D29>=70,4,IF(D29>=60,3.5,IF(D29>=50,3,IF(D29>=40,2,IF(D29>=33,1,0))))))))) -> 2
A30: ='Student Basic Info'!A30 -> 729 | C30: 35 | D30: =IF(B30+C30=0, "", B30+C30) -> 35 | E30: =IF(D30="","", IF(C30>=33,"Pass","Fail")) -> Pass | F30: =(IF(D30="","",IF(E30="Fail","F",IF(D30>=80,"A+",IF(D30>=70,"A",IF(D30>=60,"A-",IF(D30>=50,"B",IF(D30>=40,"C",IF(D30>=33,"D","F"))))))))) -> D | G30: =(IF(D30="","",IF(F30="F",0,IF(D30>=80,5,IF(D30>=70,4,IF(D30>=60,3.5,IF(D30>=50,3,IF(D30>=40,2,IF(D30>=33,1,0))))))))) -> 1
A31: ='Student Basic Info'!A31 -> 730 | C31: 36 | D31: =IF(B31+C31=0, "", B31+C31) -> 36 | E31: =IF(D31="","", IF(C31>=33,"Pass","Fail")) -> Pass | F31: =(IF(D31="","",IF(E31="Fail","F",IF(D31>=80,"A+",IF(D31>=70,"A",IF(D31>=60,"A-",IF(D31>=50,"B",IF(D31>=40,"C",IF(D31>=33,"D","F"))))))))) -> D | G31: =(IF(D31="","",IF(F31="F",0,IF(D31>=80,5,IF(D31>=70,4,IF(D31>=60,3.5,IF(D31>=50,3,IF(D31>=40,2,IF(D31>=33,1,0))))))))) -> 1
A32: ='Student Basic Info'!A32 -> 731 | C32: 51 | D32: =IF(B32+C32=0, "", B32+C32) -> 51 | E32: =IF(D32="","", IF(C32>=33,"Pass","Fail")) -> Pass | F32: =(IF(D32="","",IF(E32="Fail","F",IF(D32>=80,"A+",IF(D32>=70,"A",IF(D32>=60,"A-",IF(D32>=50,"B",IF(D32>=40,"C",IF(D32>=33,"D","F"))))))))) -> B | G32: =(IF(D32="","",IF(F32="F",0,IF(D32>=80,5,IF(D32>=70,4,IF(D32>=60,3.5,IF(D32>=50,3,IF(D32>=40,2,IF(D32>=33,1,0))))))))) -> 3
A33: ='Student Basic Info'!A33 -> 732 | C33: 33 | D33: =IF(B33+C33=0, "", B33+C33) -> 33 | E33: =IF(D33="","", IF(C33>=33,"Pass","Fail")) -> Pass | F33: =(IF(D33="","",IF(E33="Fail","F",IF(D33>=80,"A+",IF(D33>=70,"A",IF(D33>=60,"A-",IF(D33>=50,"B",IF(D33>=40,"C",IF(D33>=33,"D","F"))))))))) -> D | G33: =(IF(D33="","",IF(F33="F",0,IF(D33>=80,5,IF(D33>=70,4,IF(D33>=60,3.5,IF(D33>=50,3,IF(D33>=40,2,IF(D33>=33,1,0))))))))) -> 1
A34: ='Student Basic Info'!A34 -> 733 | C34: 45 | D34: =IF(B34+C34=0, "", B34+C34) -> 45 | E34: =IF(D34="","", IF(C34>=33,"Pass","Fail")) -> Pass | F34: =(IF(D34="","",IF(E34="Fail","F",IF(D34>=80,"A+",IF(D34>=70,"A",IF(D34>=60,"A-",IF(D34>=50,"B",IF(D34>=40,"C",IF(D34>=33,"D","F"))))))))) -> C | G34: =(IF(D34="","",IF(F34="F",0,IF(D34>=80,5,IF(D34>=70,4,IF(D34>=60,3.5,IF(D34>=50,3,IF(D34>=40,2,IF(D34>=33,1,0))))))))) -> 2
A35: ='Student Basic Info'!A35 -> 734 | C35: 52 | D35: =IF(B35+C35=0, "", B35+C35) -> 52 | E35: =IF(D35="","", IF(C35>=33,"Pass","Fail")) -> Pass | F35: =(IF(D35="","",IF(E35="Fail","F",IF(D35>=80,"A+",IF(D35>=70,"A",IF(D35>=60,"A-",IF(D35>=50,"B",IF(D35>=40,"C",IF(D35>=33,"D","F"))))))))) -> B | G35: =(IF(D35="","",IF(F35="F",0,IF(D35>=80,5,IF(D35>=70,4,IF(D35>=60,3.5,IF(D35>=50,3,IF(D35>=40,2,IF(D35>=33,1,0))))))))) -> 3
A36: ='Student Basic Info'!A36 -> 735 | C36: 50 | D36: =IF(B36+C36=0, "", B36+C36) -> 50 | E36: =IF(D36="","", IF(C36>=33,"Pass","Fail")) -> Pass | F36: =(IF(D36="","",IF(E36="Fail","F",IF(D36>=80,"A+",IF(D36>=70,"A",IF(D36>=60,"A-",IF(D36>=50,"B",IF(D36>=40,"C",IF(D36>=33,"D","F"))))))))) -> B | G36: =(IF(D36="","",IF(F36="F",0,IF(D36>=80,5,IF(D36>=70,4,IF(D36>=60,3.5,IF(D36>=50,3,IF(D36>=40,2,IF(D36>=33,1,0))))))))) -> 3
A37: ='Student Basic Info'!A37 -> 736 | C37: 40 | D37: =IF(B37+C37=0, "", B37+C37) -> 40 | E37: =IF(D37="","", IF(C37>=33,"Pass","Fail")) -> Pass | F37: =(IF(D37="","",IF(E37="Fail","F",IF(D37>=80,"A+",IF(D37>=70,"A",IF(D37>=60,"A-",IF(D37>=50,"B",IF(D37>=40,"C",IF(D37>=33,"D","F"))))))))) -> C | G37: =(IF(D37="","",IF(F37="F",0,IF(D37>=80,5,IF(D37>=70,4,IF(D37>=60,3.5,IF(D37>=50,3,IF(D37>=40,2,IF(D37>=33,1,0))))))))) -> 2
A38: ='Student Basic Info'!A38 -> 737 | C38: 57 | D38: =IF(B38+C38=0, "", B38+C38) -> 57 | E38: =IF(D38="","", IF(C38>=33,"Pass","Fail")) -> Pass | F38: =(IF(D38="","",IF(E38="Fail","F",IF(D38>=80,"A+",IF(D38>=70,"A",IF(D38>=60,"A-",IF(D38>=50,"B",IF(D38>=40,"C",IF(D38>=33,"D","F"))))))))) -> B | G38: =(IF(D38="","",IF(F38="F",0,IF(D38>=80,5,IF(D38>=70,4,IF(D38>=60,3.5,IF(D38>=50,3,IF(D38>=40,2,IF(D38>=33,1,0))))))))) -> 3
A39: ='Student Basic Info'!A39 -> 738 | C39: 54 | D39: =IF(B39+C39=0, "", B39+C39) -> 54 | E39: =IF(D39="","", IF(C39>=33,"Pass","Fail")) -> Pass | F39: =(IF(D39="","",IF(E39="Fail","F",IF(D39>=80,"A+",IF(D39>=70,"A",IF(D39>=60,"A-",IF(D39>=50,"B",IF(D39>=40,"C",IF(D39>=33,"D","F"))))))))) -> B | G39: =(IF(D39="","",IF(F39="F",0,IF(D39>=80,5,IF(D39>=70,4,IF(D39>=60,3.5,IF(D39>=50,3,IF(D39>=40,2,IF(D39>=33,1,0))))))))) -> 3
... A42: ='Student Basic Info'!A42 -> 741 | C42: 60 | D42: =IF(B42+C42=0, "", B42+C42) -> 60 | E42: =IF(D42="","", IF(C42>=33,"Pass","Fail")) -> Pass | F42: =(IF(D42="","",IF(E42="Fail","F",IF(D42>=80,"A+",IF(D42>=70,"A",IF(D42>=60,"A-",IF(D42>=50,"B",IF(D42>=40,"C",IF(D42>=33,"D","F"))))))))) -> A- | G42: =(IF(D42="","",IF(F42="F",0,IF(D42>=80,5,IF(D42>=70,4,IF(D42>=60,3.5,IF(D42>=50,3,IF(D42>=40,2,IF(D42>=33,1,0))))))))) -> 3.5
...

Sheet English
A1: Roll | B1: Marks CQ | C1: Total Marks | D1: Result | E1: Grade | F1: GPA
A2: ='Student Basic Info'!A2 -> 701 | B2: 45 | C2: =IF(B2=0, "",B2) -> 45 | D2: =IF(C2="","", IF(C2>=33,"Pass","Fail")) -> Pass | E2: =(IF(C2="","",IF(D2="Fail","F",IF(C2>=80,"A+",IF(C2>=70,"A",IF(C2>=60,"A-",IF(C2>=50,"B",IF(C2>=40,"C",IF(C2>=33,"D","F"))))))))) -> C | F2: =(IF(C2="","",IF(E2="F",0,IF(C2>=80,5,IF(C2>=70,4,IF(C2>=60,3.5,IF(C2>=50,3,IF(C2>=40,2,IF(C2>=33,1,0))))))))) -> 2
A3: ='Student Basic Info'!A3 -> 702 | C3: =IF(B3=0, "",B3) | D3: =IF(C3="","", IF(C3>=33,"Pass","Fail")) | E3: =(IF(C3="","",IF(D3="Fail","F",IF(C3>=80,"A+",IF(C3>=70,"A",IF(C3>=60,"A-",IF(C3>=50,"B",IF(C3>=40,"C",IF(C3>=33,"D","F"))))))))) | F3: =(IF(C3="","",IF(E3="F",0,IF(C3>=80,5,IF(C3>=70,4,IF(C3>=60,3.5,IF(C3>=50,3,IF(C3>=40,2,IF(C3>=33,1,0)))))))))
A4: ='Student Basic Info'!A4 -> 703 | C4: =IF(B4=0, "",B4) | D4: =IF(C4="","", IF(C4>=33,"Pass","Fail")) | E4: =(IF(C4="","",IF(D4="Fail","F",IF(C4>=80,"A+",IF(C4>=70,"A",IF(C4>=60,"A-",IF(C4>=50,"B",IF(C4>=40,"C",IF(C4>=33,"D","F"))))))))) | F4: =(IF(C4="","",IF(E4="F",0,IF(C4>=80,5,IF(C4>=70,4,IF(C4>=60,3.5,IF(C4>=50,3,IF(C4>=40,2,IF(C4>=33,1,0)))))))))
A5: ='Student Basic Info'!A5 -> 704 | B5: 38 | C5: =IF(B5=0, "",B5) -> 38 | D5: =IF(C5="","", IF(C5>=33,"Pass","Fail")) -> Pass | E5: =(IF(C5="","",IF(D5="Fail","F",IF(C5>=80,"A+",IF(C5>=70,"A",IF(C5>=60,"A-",IF(C5>=50,"B",IF(C5>=40,"C",IF(C5>=33,"D","F"))))))))) -> D | F5: =(IF(C5="","",IF(E5="F",0,IF(C5>=80,5,IF(C5>=70,4,IF(C5>=60,3.5,IF(C5>=50,3,IF(C5>=40,2,IF(C5>=33,1,0))))))))) -> 1
A6: ='Student Basic Info'!A6 -> 705 | C6: =IF(B6=0, "",B6) | D6: =IF(C6="","", IF(C6>=33,"Pass","Fail")) | E6: =(IF(C6="","",IF(D6="Fail","F",IF(C6>=80,"A+",IF(C6>=70,"A",IF(C6>=60,"A-",IF(C6>=50,"B",IF(C6>=40,"C",IF(C6>=33,"D","F"))))))))) | F6: =(IF(C6="","",IF(E6="F",0,IF(C6>=80,5,IF(C6>=70,4,IF(C6>=60,3.5,IF(C6>=50,3,IF(C6>=40,2,IF(C6>=33,1,0)))))))))
A7: ='Student Basic Info'!A7 -> 706 | C7: =IF(B7=0, "",B7) | D7: =IF(C7="","", IF(C7>=33,"Pass","Fail")) | E7: =(IF(C7="","",IF(D7="Fail","F",IF(C7>=80,"A+",IF(C7>=70,"A",IF(C7>=60,"A-",IF(C7>=50,"B",IF(C7>=40,"C",IF(C7>=33,"D","F"))))))))) | F7: =(IF(C7="","",IF(E7="F",0,IF(C7>=80,5,IF(C7>=70,4,IF(C7>=60,3.5,IF(C7>=50,3,IF(C7>=40,2,IF(C7>=33,1,0)))))))))
A8: ='Student Basic Info'!A8 -> 707 | C8: =IF(B8=0, "",B8) | D8: =IF(C8="","", IF(C8>=33,"Pass","Fail")) | E8: =(IF(C8="","",IF(D8="Fail","F",IF(C8>=80,"A+",IF(C8>=70,"A",IF(C8>=60,"A-",IF(C8>=50,"B",IF(C8>=40,"C",IF(C8>=33,"D","F"))))))))) | F8: =(IF(C8="","",IF(E8="F",0,IF(C8>=80,5,IF(C8>=70,4,IF(C8>=60,3.5,IF(C8>=50,3,IF(C8>=40,2,IF(C8>=33,1,0)))))))))
A9: ='Student Basic Info'!A9 -> 708 | B9: 33 | C9: =IF(B9=0, "",B9) -> 33 | D9: =IF(C9="","", IF(C9>=33,"Pass","Fail")) -> Pass | E9: =(IF(C9="","",IF(D9="Fail","F",IF(C9>=80,"A+",IF(C9>=70,"A",IF(C9>=60,"A-",IF(C9>=50,"B",IF(C9>=40,"C",IF(C9>=33,"D","F"))))))))) -> D | F9: =(IF(C9="","",IF(E9="F",0,IF(C9>=80,5,IF(C9>=70,4,IF(C9>=60,3.5,IF(C9>=50,3,IF(C9>=40,2,IF(C9>=33,1,0))))))))) -> 1
A10: ='Student Basic Info'!A10 -> 709 | B10: 33 | C10: =IF(B10=0, "",B10) -> 33 | D10: =IF(C10="","", IF(C10>=33,"Pass","Fail")) -> Pass | E10: =(IF(C10="","",IF(D10="Fail","F",IF(C10>=80,"A+",IF(C10>=70,"A",IF(C10>=60,"A-",IF(C10>=50,"B",IF(C10>=40,"C",IF(C10>=33,"D","F"))))))))) -> D | F10: =(IF(C10="","",IF(E10="F",0,IF(C10>=80,5,IF(C10>=70,4,IF(C10>=60,3.5,IF(C10>=50,3,IF(C10>=40,2,IF(C10>=33,1,0))))))))) -> 1
A11: ='Student Basic Info'!A11 -> 710 | B11: 27 | C11: =IF(B11=0, "",B11) -> 27 | D11: =IF(C11="","", IF(C11>=33,"Pass","Fail")) -> Fail | E11: =(IF(C11="","",IF(D11="Fail","F",IF(C11>=80,"A+",IF(C11>=70,"A",IF(C11>=60,"A-",IF(C11>=50,"B",IF(C11>=40,"C",IF(C11>=33,"D","F"))))))))) -> F | F11: =(IF(C11="","",IF(E11="F",0,IF(C11>=80,5,IF(C11>=70,4,IF(C11>=60,3.5,IF(C11>=50,3,IF(C11>=40,2,IF(C11>=33,1,0))))))))) -> 0
A12: ='Student Basic Info'!A12 -> 711 | C12: =IF(B12=0, "",B12) | D12: =IF(C12="","", IF(C12>=33,"Pass","Fail")) | E12: =(IF(C12="","",IF(D12="Fail","F",IF(C12>=80,"A+",IF(C12>=70,"A",IF(C12>=60,"A-",IF(C12>=50,"B",IF(C12>=40,"C",IF(C12>=33,"D","F"))))))))) | F12: =(IF(C12="","",IF(E12="F",0,IF(C12>=80,5,IF(C12>=70,4,IF(C12>=60,3.5,IF(C12>=50,3,IF(C12>=40,2,IF(C12>=33,1,0)))))))))
A13: ='Student Basic Info'!A13 -> 712 | B13: 33 | C13: =IF(B13=0, "",B13) -> 33 | D13: =IF(C13="","", IF(C13>=33,"Pass","Fail")) -> Pass | E13: =(IF(C13="","",IF(D13="Fail","F",IF(C13>=80,"A+",IF(C13>=70,"A",IF(C13>=60,"A-",IF(C13>=50,"B",IF(C13>=40,"C",IF(C13>=33,"D","F"))))))))) -> D | F13: =(IF(C13="","",IF(E13="F",0,IF(C13>=80,5,IF(C13>=70,4,IF(C13>=60,3.5,IF(C13>=50,3,IF(C13>=40,2,IF(C13>=33,1,0))))))))) -> 1
A14: ='Student Basic Info'!A14 -> 713 | B14: 44 | C14: =IF(B14=0, "",B14) -> 44 | D14: =IF(C14="","", IF(C14>=33,"Pass","Fail")) -> Pass | E14: =(IF(C14="","",IF(D14="Fail","F",IF(C14>=80,"A+",IF(C14>=70,"A",IF(C14>=60,"A-",IF(C14>=50,"B",IF(C14>=40,"C",IF(C14>=33,"D","F"))))))))) -> C | F14: =(IF(C14="","",IF(E14="F",0,IF(C14>=80,5,IF(C14>=70,4,IF(C14>=60,3.5,IF(C14>=50,3,IF(C14>=40,2,IF(C14>=33,1,0))))))))) -> 2
A15: ='Student Basic Info'!A15 -> 714 | B15: 47 | C15: =IF(B15=0, "",B15) -> 47 | D15: =IF(C15="","", IF(C15>=33,"Pass","Fail")) -> Pass | E15: =(IF(C15="","",IF(D15="Fail","F",IF(C15>=80,"A+",IF(C15>=70,"A",IF(C15>=60,"A-",IF(C15>=50,"B",IF(C15>=40,"C",IF(C15>=33,"D","F"))))))))) -> C | F15: =(IF(C15="","",IF(E15="F",0,IF(C15>=80,5,IF(C15>=70,4,IF(C15>=60,3.5,IF(C15>=50,3,IF(C15>=40,2,IF(C15>=33,1,0))))))))) -> 2
A16: ='Student Basic Info'!A16 -> 715 | B16: 17 | C16: =IF(B16=0, "",B16) -> 17 | D16: =IF(C16="","", IF(C16>=33,"Pass","Fail")) -> Fail | E16: =(IF(C16="","",IF(D16="Fail","F",IF(C16>=80,"A+",IF(C16>=70,"A",IF(C16>=60,"A-",IF(C16>=50,"B",IF(C16>=40,"C",IF(C16>=33,"D","F"))))))))) -> F | F16: =(IF(C16="","",IF(E16="F",0,IF(C16>=80,5,IF(C16>=70,4,IF(C16>=60,3.5,IF(C16>=50,3,IF(C16>=40,2,IF(C16>=33,1,0))))))))) -> 0 | I16: \
A17: ='Student Basic Info'!A17 -> 716 | B17: 23 | C17: =IF(B17=0, "",B17) -> 23 | D17: =IF(C17="","", IF(C17>=33,"Pass","Fail")) -> Fail | E17: =(IF(C17="","",IF(D17="Fail","F",IF(C17>=80,"A+",IF(C17>=70,"A",IF(C17>=60,"A-",IF(C17>=50,"B",IF(C17>=40,"C",IF(C17>=33,"D","F"))))))))) -> F | F17: =(IF(C17="","",IF(E17="F",0,IF(C17>=80,5,IF(C17>=70,4,IF(C17>=60,3.5,IF(C17>=50,3,IF(C17>=40,2,IF(C17>=33,1,0))))))))) -> 0
A18: ='Student Basic Info'!A18 -> 717 | B18: 24 | C18: =IF(B18=0, "",B18) -> 24 | D18: =IF(C18="","", IF(C18>=33,"Pass","Fail")) -> Fail | E18: =(IF(C18="","",IF(D18="Fail","F",IF(C18>=80,"A+",IF(C18>=70,"A",IF(C18>=60,"A-",IF(C18>=50,"B",IF(C18>=40,"C",IF(C18>=33,"D","F"))))))))) -> F | F18: =(IF(C18="","",IF(E18="F",0,IF(C18>=80,5,IF(C18>=70,4,IF(C18>=60,3.5,IF(C18>=50,3,IF(C18>=40,2,IF(C18>=33,1,0))))))))) -> 0
A19: ='Student Basic Info'!A19 -> 718 | C19: =IF(B19=0, "",B19) | D19: =IF(C19="","", IF(C19>=33,"Pass","Fail")) | E19: =(IF(C19="","",IF(D19="Fail","F",IF(C19>=80,"A+",IF(C19>=70,"A",IF(C19>=60,"A-",IF(C19>=50,"B",IF(C19>=40,"C",IF(C19>=33,"D","F"))))))))) | F19: =(IF(C19="","",IF(E19="F",0,IF(C19>=80,5,IF(C19>=70,4,IF(C19>=60,3.5,IF(C19>=50,3,IF(C19>=40,2,IF(C19>=33,1,0)))))))))
A20: ='Student Basic Info'!A20 -> 719 | B20: 25 | C20: =IF(B20=0, "",B20) -> 25 | D20: =IF(C20="","", IF(C20>=33,"Pass","Fail")) -> Fail | E20: =(IF(C20="","",IF(D20="Fail","F",IF(C20>=80,"A+",IF(C20>=70,"A",IF(C20>=60,"A-",IF(C20>=50,"B",IF(C20>=40,"C",IF(C20>=33,"D","F"))))))))) -> F | F20: =(IF(C20="","",IF(E20="F",0,IF(C20>=80,5,IF(C20>=70,4,IF(C20>=60,3.5,IF(C20>=50,3,IF(C20>=40,2,IF(C20>=33,1,0))))))))) -> 0
A21: ='Student Basic Info'!A21 -> 720 | B21: 29 | C21: =IF(B21=0, "",B21) -> 29 | D21: =IF(C21="","", IF(C21>=33,"Pass","Fail")) -> Fail | E21: =(IF(C21="","",IF(D21="Fail","F",IF(C21>=80,"A+",IF(C21>=70,"A",IF(C21>=60,"A-",IF(C21>=50,"B",IF(C21>=40,"C",IF(C21>=33,"D","F"))))))))) -> F | F21: =(IF(C21="","",IF(E21="F",0,IF(C21>=80,5,IF(C21>=70,4,IF(C21>=60,3.5,IF(C21>=50,3,IF(C21>=40,2,IF(C21>=33,1,0))))))))) -> 0
A22: ='Student Basic Info'!A22 -> 721 | C22: =IF(B22=0, "",B22) | D22: =IF(C22="","", IF(C22>=33,"Pass","Fail")) | E22: =(IF(C22="","",IF(D22="Fail","F",IF(C22>=80,"A+",IF(C22>=70,"A",IF(C22>=60,"A-",IF(C22>=50,"B",IF(C22>=40,"C",IF(C22>=33,"D","F"))))))))) | F22: =(IF(C22="","",IF(E22="F",0,IF(C22>=80,5,IF(C22>=70,4,IF(C22>=60,3.5,IF(C22>=50,3,IF(C22>=40,2,IF(C22>=33,1,0)))))))))
A23: ='Student Basic Info'!A23 -> 722 | B23: 41 | C23: =IF(B23=0, "",B23) -> 41 | D23: =IF(C23="","", IF(C23>=33,"Pass","Fail")) -> Pass | E23: =(IF(C23="","",IF(D23="Fail","F",IF(C23>=80,"A+",IF(C23>=70,"A",IF(C23>=60,"A-",IF(C23>=50,"B",IF(C23>=40,"C",IF(C23>=33,"D","F"))))))))) -> C | F23: =(IF(C23="","",IF(E23="F",0,IF(C23>=80,5,IF(C23>=70,4,IF(C23>=60,3.5,IF(C23>=50,3,IF(C23>=40,2,IF(C23>=33,1,0))))))))) -> 2
A24: ='Student Basic Info'!A24 -> 723 | B24: 64 | C24: =IF(B24=0, "",B24) -> 64 | D24: =IF(C24="","", IF(C24>=33,"Pass","Fail")) -> Pass | E24: =(IF(C24="","",IF(D24="Fail","F",IF(C24>=80,"A+",IF(C24>=70,"A",IF(C24>=60,"A-",IF(C24>=50,"B",IF(C24>=40,"C",IF(C24>=33,"D","F"))))))))) -> A- | F24: =(IF(C24="","",IF(E24="F",0,IF(C24>=80,5,IF(C24>=70,4,IF(C24>=60,3.5,IF(C24>=50,3,IF(C24>=40,2,IF(C24>=33,1,0))))))))) -> 3.5
A25: ='Student Basic Info'!A25 -> 724 | B25: 34 | C25: =IF(B25=0, "",B25) -> 34 | D25: =IF(C25="","", IF(C25>=33,"Pass","Fail")) -> Pass | E25: =(IF(C25="","",IF(D25="Fail","F",IF(C25>=80,"A+",IF(C25>=70,"A",IF(C25>=60,"A-",IF(C25>=50,"B",IF(C25>=40,"C",IF(C25>=33,"D","F"))))))))) -> D | F25: =(IF(C25="","",IF(E25="F",0,IF(C25>=80,5,IF(C25>=70,4,IF(C25>=60,3.5,IF(C25>=50,3,IF(C25>=40,2,IF(C25>=33,1,0))))))))) -> 1
A26: ='Student Basic Info'!A26 -> 725 | B26: 34 | C26: =IF(B26=0, "",B26) -> 34 | D26: =IF(C26="","", IF(C26>=33,"Pass","Fail")) -> Pass | E26: =(IF(C26="","",IF(D26="Fail","F",IF(C26>=80,"A+",IF(C26>=70,"A",IF(C26>=60,"A-",IF(C26>=50,"B",IF(C26>=40,"C",IF(C26>=33,"D","F"))))))))) -> D | F26: =(IF(C26="","",IF(E26="F",0,IF(C26>=80,5,IF(C26>=70,4,IF(C26>=60,3.5,IF(C26>=50,3,IF(C26>=40,2,IF(C26>=33,1,0))))))))) -> 1
A27: ='Student Basic Info'!A27 -> 726 | C27: =IF(B27=0, "",B27) | D27: =IF(C27="","", IF(C27>=33,"Pass","Fail")) | E27: =(IF(C27="","",IF(D27="Fail","F",IF(C27>=80,"A+",IF(C27>=70,"A",IF(C27>=60,"A-",IF(C27>=50,"B",IF(C27>=40,"C",IF(C27>=33,"D","F"))))))))) | F27: =(IF(C27="","",IF(E27="F",0,IF(C27>=80,5,IF(C27>=70,4,IF(C27>=60,3.5,IF(C27>=50,3,IF(C27>=40,2,IF(C27>=33,1,0)))))))))
A28: ='Student Basic Info'!A28 -> 727 | B28: 37 | C28: =IF(B28=0, "",B28) -> 37 | D28: =IF(C28="","", IF(C28>=33,"Pass","Fail")) -> Pass | E28: =(IF(C28="","",IF(D28="Fail","F",IF(C28>=80,"A+",IF(C28>=70,"A",IF(C28>=60,"A-",IF(C28>=50,"B",IF(C28>=40,"C",IF(C28>=33,"D","F"))))))))) -> D | F28: =(IF(C28="","",IF(E28="F",0,IF(C28>=80,5,IF(C28>=70,4,IF(C28>=60,3.5,IF(C28>=50,3,IF(C28>=40,2,IF(C28>=33,1,0))))))))) -> 1
A29: ='Student Basic Info'!A29 -> 728 | B29: 29 | C29: =IF(B29=0, "",B29) -> 29 | D29: =IF(C29="","", IF(C29>=33,"Pass","Fail")) -> Fail | E29: =(IF(C29="","",IF(D29="Fail","F",IF(C29>=80,"A+",IF(C29>=70,"A",IF(C29>=60,"A-",IF(C29>=50,"B",IF(C29>=40,"C",IF(C29>=33,"D","F"))))))))) -> F | F29: =(IF(C29="","",IF(E29="F",0,IF(C29>=80,5,IF(C29>=70,4,IF(C29>=60,3.5,IF(C29>=50,3,IF(C29>=40,2,IF(C29>=33,1,0))))))))) -> 0
A30: ='Student Basic Info'!A30 -> 729 | B30: 18 | C30: =IF(B30=0, "",B30) -> 18 | D30: =IF(C30="","", IF(C30>=33,"Pass","Fail")) -> Fail | E30: =(IF(C30="","",IF(D30="Fail","F",IF(C30>=80,"A+",IF(C30>=70,"A",IF(C30>=60,"A-",IF(C30>=50,"B",IF(C30>=40,"C",IF(C30>=33,"D","F"))))))))) -> F | F30: =(IF(C30="","",IF(E30="F",0,IF(C30>=80,5,IF(C30>=70,4,IF(C30>=60,3.5,IF(C30>=50,3,IF(C30>=40,2,IF(C30>=33,1,0))))))))) -> 0
A31: ='Student Basic Info'!A31 -> 730 | B31: 23 | C31: =IF(B31=0, "",B31) -> 23 | D31: =IF(C31="","", IF(C31>=33,"Pass","Fail")) -> Fail | E31: =(IF(C31="","",IF(D31="Fail","F",IF(C31>=80,"A+",IF(C31>=70,"A",IF(C31>=60,"A-",IF(C31>=50,"B",IF(C31>=40,"C",IF(C31>=33,"D","F"))))))))) -> F | F31: =(IF(C31="","",IF(E31="F",0,IF(C31>=80,5,IF(C31>=70,4,IF(C31>=60,3.5,IF(C31>=50,3,IF(C31>=40,2,IF(C31>=33,1,0))))))))) -> 0
A32: ='Student Basic Info'!A32 -> 731 | B32: 24 | C32: =IF(B32=0, "",B32) -> 24 | D32: =IF(C32="","", IF(C32>=33,"Pass","Fail")) -> Fail | E32: =(IF(C32="","",IF(D32="Fail","F",IF(C32>=80,"A+",IF(C32>=70,"A",IF(C32>=60,"A-",IF(C32>=50,"B",IF(C32>=40,"C",IF(C32>=33,"D","F"))))))))) -> F | F32: =(IF(C32="","",IF(E32="F",0,IF(C32>=80,5,IF(C32>=70,4,IF(C32>=60,3.5,IF(C32>=50,3,IF(C32>=40,2,IF(C32>=33,1,0))))))))) -> 0
A33: ='Student Basic Info'!A33 -> 732 | B33: 17 | C33: =IF(B33=0, "",B33) -> 17 | D33: =IF(C33="","", IF(C33>=33,"Pass","Fail")) -> Fail | E33: =(IF(C33="","",IF(D33="Fail","F",IF(C33>=80,"A+",IF(C33>=70,"A",IF(C33>=60,"A-",IF(C33>=50,"B",IF(C33>=40,"C",IF(C33>=33,"D","F"))))))))) -> F | F33: =(IF(C33="","",IF(E33="F",0,IF(C33>=80,5,IF(C33>=70,4,IF(C33>=60,3.5,IF(C33>=50,3,IF(C33>=40,2,IF(C33>=33,1,0))))))))) -> 0
A34: ='Student Basic Info'!A34 -> 733 | B34: 34 | C34: =IF(B34=0, "",B34) -> 34 | D34: =IF(C34="","", IF(C34>=33,"Pass","Fail")) -> Pass | E34: =(IF(C34="","",IF(D34="Fail","F",IF(C34>=80,"A+",IF(C34>=70,"A",IF(C34>=60,"A-",IF(C34>=50,"B",IF(C34>=40,"C",IF(C34>=33,"D","F"))))))))) -> D | F34: =(IF(C34="","",IF(E34="F",0,IF(C34>=80,5,IF(C34>=70,4,IF(C34>=60,3.5,IF(C34>=50,3,IF(C34>=40,2,IF(C34>=33,1,0))))))))) -> 1
A35: ='Student Basic Info'!A35 -> 734 | B35: 33 | C35: =IF(B35=0, "",B35) -> 33 | D35: =IF(C35="","", IF(C35>=33,"Pass","Fail")) -> Pass | E35: =(IF(C35="","",IF(D35="Fail","F",IF(C35>=80,"A+",IF(C35>=70,"A",IF(C35>=60,"A-",IF(C35>=50,"B",IF(C35>=40,"C",IF(C35>=33,"D","F"))))))))) -> D | F35: =(IF(C35="","",IF(E35="F",0,IF(C35>=80,5,IF(C35>=70,4,IF(C35>=60,3.5,IF(C35>=50,3,IF(C35>=40,2,IF(C35>=33,1,0))))))))) -> 1
A36: ='Student Basic Info'!A36 -> 735 | B36: 44 | C36: =IF(B36=0, "",B36) -> 44 | D36: =IF(C36="","", IF(C36>=33,"Pass","Fail")) -> Pass | E36: =(IF(C36="","",IF(D36="Fail","F",IF(C36>=80,"A+",IF(C36>=70,"A",IF(C36>=60,"A-",IF(C36>=50,"B",IF(C36>=40,"C",IF(C36>=33,"D","F"))))))))) -> C | F36: =(IF(C36="","",IF(E36="F",0,IF(C36>=80,5,IF(C36>=70,4,IF(C36>=60,3.5,IF(C36>=50,3,IF(C36>=40,2,IF(C36>=33,1,0))))))))) -> 2
A37: ='Student Basic Info'!A37 -> 736 | B37: 16 | C37: =IF(B37=0, "",B37) -> 16 | D37: =IF(C37="","", IF(C37>=33,"Pass","Fail")) -> Fail | E37: =(IF(C37="","",IF(D37="Fail","F",IF(C37>=80,"A+",IF(C37>=70,"A",IF(C37>=60,"A-",IF(C37>=50,"B",IF(C37>=40,"C",IF(C37>=33,"D","F"))))))))) -> F | F37: =(IF(C37="","",IF(E37="F",0,IF(C37>=80,5,IF(C37>=70,4,IF(C37>=60,3.5,IF(C37>=50,3,IF(C37>=40,2,IF(C37>=33,1,0))))))))) -> 0
A38: ='Student Basic Info'!A38 -> 737 | B38: 47 | C38: =IF(B38=0, "",B38) -> 47 | D38: =IF(C38="","", IF(C38>=33,"Pass","Fail")) -> Pass | E38: =(IF(C38="","",IF(D38="Fail","F",IF(C38>=80,"A+",IF(C38>=70,"A",IF(C38>=60,"A-",IF(C38>=50,"B",IF(C38>=40,"C",IF(C38>=33,"D","F"))))))))) -> C | F38: =(IF(C38="","",IF(E38="F",0,IF(C38>=80,5,IF(C38>=70,4,IF(C38>=60,3.5,IF(C38>=50,3,IF(C38>=40,2,IF(C38>=33,1,0))))))))) -> 2
A39: ='Student Basic Info'!A39 -> 738 | B39: 44 | C39: =IF(B39=0, "",B39) -> 44 | D39: =IF(C39="","", IF(C39>=33,"Pass","Fail")) -> Pass | E39: =(IF(C39="","",IF(D39="Fail","F",IF(C39>=80,"A+",IF(C39>=70,"A",IF(C39>=60,"A-",IF(C39>=50,"B",IF(C39>=40,"C",IF(C39>=33,"D","F"))))))))) -> C | F39: =(IF(C39="","",IF(E39="F",0,IF(C39>=80,5,IF(C39>=70,4,IF(C39>=60,3.5,IF(C39>=50,3,IF(C39>=40,2,IF(C39>=33,1,0))))))))) -> 2
... A42: ='Student Basic Info'!A42 -> 741 | B42: 54 | C42: =IF(B42=0, "",B42) -> 54 | D42: =IF(C42="","", IF(C42>=33,"Pass","Fail")) -> Pass | E42: =(IF(C42="","",IF(D42="Fail","F",IF(C42>=80,"A+",IF(C42>=70,"A",IF(C42>=60,"A-",IF(C42>=50,"B",IF(C42>=40,"C",IF(C42>=33,"D","F"))))))))) -> B | F42: =(IF(C42="","",IF(E42="F",0,IF(C42>=80,5,IF(C42>=70,4,IF(C42>=60,3.5,IF(C42>=50,3,IF(C42>=40,2,IF(C42>=33,1,0))))))))) -> 3
...

Sheet ICT
A1: Roll | B1: Marks MCQ | C1: Marks CQ | D1: Practical | E1: Total Marks | F1: Result | G1: Grade | H1: GPA
A2: ='Student Basic Info'!A2 -> 701 | B2: 17 | C2: 40 | D2: 25 | E2: =IF(B2+C2=0, "", B2+C2+D2) -> 82 | F2: =IF(E2="","", IF(AND(B2 >=8,C2>=17,D2>=8),"Pass","Fail")) -> Pass | G2: =(IF(E2="","",IF(F2="Fail","F",IF(E2>=80,"A+",IF(E2>=70,"A",IF(E2>=60,"A-",IF(E2>=50,"B",IF(E2>=40,"C",IF(E2>=33,"D","F"))))))))) -> A+ | H2: =(IF(E2="","",IF(G2="F",0,IF(E2>=80,5,IF(E2>=70,4,IF(E2>=60,3.5,IF(E2>=50,3,IF(E2>=40,2,IF(E2>=33,1,0))))))))) -> 5
A3: ='Student Basic Info'!A3 -> 702 | E3: =IF(B3+C3=0, "", B3+C3+D3) | F3: =IF(E3="","", IF(AND(B3 >=8,C3>=17,D3>=8),"Pass","Fail")) | G3: =(IF(E3="","",IF(F3="Fail","F",IF(E3>=80,"A+",IF(E3>=70,"A",IF(E3>=60,"A-",IF(E3>=50,"B",IF(E3>=40,"C",IF(E3>=33,"D","F"))))))))) | H3: =(IF(E3="","",IF(G3="F",0,IF(E3>=80,5,IF(E3>=70,4,IF(E3>=60,3.5,IF(E3>=50,3,IF(E3>=40,2,IF(E3>=33,1,0)))))))))
A4: ='Student Basic Info'!A4 -> 703 | E4: =IF(B4+C4=0, "", B4+C4+D4) | F4: =IF(E4="","", IF(AND(B4 >=8,C4>=17,D4>=8),"Pass","Fail")) | G4: =(IF(E4="","",IF(F4="Fail","F",IF(E4>=80,"A+",IF(E4>=70,"A",IF(E4>=60,"A-",IF(E4>=50,"B",IF(E4>=40,"C",IF(E4>=33,"D","F"))))))))) | H4: =(IF(E4="","",IF(G4="F",0,IF(E4>=80,5,IF(E4>=70,4,IF(E4>=60,3.5,IF(E4>=50,3,IF(E4>=40,2,IF(E4>=33,1,0)))))))))
A5: ='Student Basic Info'!A5 -> 704 | B5: 14 | C5: 12 | D5: 22 | E5: =IF(B5+C5=0, "", B5+C5+D5) -> 48 | F5: =IF(E5="","", IF(AND(B5 >=8,C5>=17,D5>=8),"Pass","Fail")) -> Fail | G5: =(IF(E5="","",IF(F5="Fail","F",IF(E5>=80,"A+",IF(E5>=70,"A",IF(E5>=60,"A-",IF(E5>=50,"B",IF(E5>=40,"C",IF(E5>=33,"D","F"))))))))) -> F | H5: =(IF(E5="","",IF(G5="F",0,IF(E5>=80,5,IF(E5>=70,4,IF(E5>=60,3.5,IF(E5>=50,3,IF(E5>=40,2,IF(E5>=33,1,0))))))))) -> 0
A6: ='Student Basic Info'!A6 -> 705 | B6: 7 | C6: 12 | D6: 8 | E6: =IF(B6+C6=0, "", B6+C6+D6) -> 27 | F6: =IF(E6="","", IF(AND(B6 >=8,C6>=17,D6>=8),"Pass","Fail")) -> Fail | G6: =(IF(E6="","",IF(F6="Fail","F",IF(E6>=80,"A+",IF(E6>=70,"A",IF(E6>=60,"A-",IF(E6>=50,"B",IF(E6>=40,"C",IF(E6>=33,"D","F"))))))))) -> F | H6: =(IF(E6="","",IF(G6="F",0,IF(E6>=80,5,IF(E6>=70,4,IF(E6>=60,3.5,IF(E6>=50,3,IF(E6>=40,2,IF(E6>=33,1,0))))))))) -> 0
A7: ='Student Basic Info'!A7 -> 706 | E7: =IF(B7+C7=0, "", B7+C7+D7) | F7: =IF(E7="","", IF(AND(B7 >=8,C7>=17,D7>=8),"Pass","Fail")) | G7: =(IF(E7="","",IF(F7="Fail","F",IF(E7>=80,"A+",IF(E7>=70,"A",IF(E7>=60,"A-",IF(E7>=50,"B",IF(E7>=40,"C",IF(E7>=33,"D","F"))))))))) | H7: =(IF(E7="","",IF(G7="F",0,IF(E7>=80,5,IF(E7>=70,4,IF(E7>=60,3.5,IF(E7>=50,3,IF(E7>=40,2,IF(E7>=33,1,0)))))))))
A8: ='Student Basic Info'!A8 -> 707 | E8: =IF(B8+C8=0, "", B8+C8+D8) | F8: =IF(E8="","", IF(AND(B8 >=8,C8>=17,D8>=8),"Pass","Fail")) | G8: =(IF(E8="","",IF(F8="Fail","F",IF(E8>=80,"A+",IF(E8>=70,"A",IF(E8>=60,"A-",IF(E8>=50,"B",IF(E8>=40,"C",IF(E8>=33,"D","F"))))))))) | H8: =(IF(E8="","",IF(G8="F",0,IF(E8>=80,5,IF(E8>=70,4,IF(E8>=60,3.5,IF(E8>=50,3,IF(E8>=40,2,IF(E8>=33,1,0)))))))))
A9: ='Student Basic Info'!A9 -> 708 | B9: 15 | C9: 8 | D9: 20 | E9: =IF(B9+C9=0, "", B9+C9+D9) -> 43 | F9: =IF(E9="","", IF(AND(B9 >=8,C9>=17,D9>=8),"Pass","Fail")) -> Fail | G9: =(IF(E9="","",IF(F9="Fail","F",IF(E9>=80,"A+",IF(E9>=70,"A",IF(E9>=60,"A-",IF(E9>=50,"B",IF(E9>=40,"C",IF(E9>=33,"D","F"))))))))) -> F | H9: =(IF(E9="","",IF(G9="F",0,IF(E9>=80,5,IF(E9>=70,4,IF(E9>=60,3.5,IF(E9>=50,3,IF(E9>=40,2,IF(E9>=33,1,0))))))))) -> 0
A10: ='Student Basic Info'!A10 -> 709 | B10: 12 | C10: 7 | D10: 18 | E10: =IF(B10+C10=0, "", B10+C10+D10) -> 37 | F10: =IF(E10="","", IF(AND(B10 >=8,C10>=17,D10>=8),"Pass","Fail")) -> Fail | G10: =(IF(E10="","",IF(F10="Fail","F",IF(E10>=80,"A+",IF(E10>=70,"A",IF(E10>=60,"A-",IF(E10>=50,"B",IF(E10>=40,"C",IF(E10>=33,"D","F"))))))))) -> F | H10: =(IF(E10="","",IF(G10="F",0,IF(E10>=80,5,IF(E10>=70,4,IF(E10>=60,3.5,IF(E10>=50,3,IF(E10>=40,2,IF(E10>=33,1,0))))))))) -> 0
A11: ='Student Basic Info'!A11 -> 710 | B11: 9 | C11: 17 | D11: 24 | E11: =IF(B11+C11=0, "", B11+C11+D11) -> 50 | F11: =IF(E11="","", IF(AND(B11 >=8,C11>=17,D11>=8),"Pass","Fail")) -> Pass | G11: =(IF(E11="","",IF(F11="Fail","F",IF(E11>=80,"A+",IF(E11>=70,"A",IF(E11>=60,"A-",IF(E11>=50,"B",IF(E11>=40,"C",IF(E11>=33,"D","F"))))))))) -> B | H11: =(IF(E11="","",IF(G11="F",0,IF(E11>=80,5,IF(E11>=70,4,IF(E11>=60,3.5,IF(E11>=50,3,IF(E11>=40,2,IF(E11>=33,1,0))))))))) -> 3
A12: ='Student Basic Info'!A12 -> 711 | E12: =IF(B12+C12=0, "", B12+C12+D12) | F12: =IF(E12="","", IF(AND(B12 >=8,C12>=17,D12>=8),"Pass","Fail")) | G12: =(IF(E12="","",IF(F12="Fail","F",IF(E12>=80,"A+",IF(E12>=70,"A",IF(E12>=60,"A-",IF(E12>=50,"B",IF(E12>=40,"C",IF(E12>=33,"D","F"))))))))) | H12: =(IF(E12="","",IF(G12="F",0,IF(E12>=80,5,IF(E12>=70,4,IF(E12>=60,3.5,IF(E12>=50,3,IF(E12>=40,2,IF(E12>=33,1,0)))))))))
A13: ='Student Basic Info'!A13 -> 712 | B13: 10 | C13: 17 | D13: 20 | E13: =IF(B13+C13=0, "", B13+C13+D13) -> 47 | F13: =IF(E13="","", IF(AND(B13 >=8,C13>=17,D13>=8),"Pass","Fail")) -> Pass | G13: =(IF(E13="","",IF(F13="Fail","F",IF(E13>=80,"A+",IF(E13>=70,"A",IF(E13>=60,"A-",IF(E13>=50,"B",IF(E13>=40,"C",IF(E13>=33,"D","F"))))))))) -> C | H13: =(IF(E13="","",IF(G13="F",0,IF(E13>=80,5,IF(E13>=70,4,IF(E13>=60,3.5,IF(E13>=50,3,IF(E13>=40,2,IF(E13>=33,1,0))))))))) -> 2
A14: ='Student Basic Info'!A14 -> 713 | B14: 16 | C14: 21 | D14: 25 | E14: =IF(B14+C14=0, "", B14+C14+D14) -> 62 | F14: =IF(E14="","", IF(AND(B14 >=8,C14>=17,D14>=8),"Pass","Fail")) -> Pass | G14: =(IF(E14="","",IF(F14="Fail","F",IF(E14>=80,"A+",IF(E14>=70,"A",IF(E14>=60,"A-",IF(E14>=50,"B",IF(E14>=40,"C",IF(E14>=33,"D","F"))))))))) -> A- | H14: =(IF(E14="","",IF(G14="F",0,IF(E14>=80,5,IF(E14>=70,4,IF(E14>=60,3.5,IF(E14>=50,3,IF(E14>=40,2,IF(E14>=33,1,0))))))))) -> 3.5
A15: ='Student Basic Info'!A15 -> 714 | B15: 19 | C15: 31 | D15: 22 | E15: =IF(B15+C15=0, "", B15+C15+D15) -> 72 | F15: =IF(E15="","", IF(AND(B15 >=8,C15>=17,D15>=8),"Pass","Fail")) -> Pass | G15: =(IF(E15="","",IF(F15="Fail","F",IF(E15>=80,"A+",IF(E15>=70,"A",IF(E15>=60,"A-",IF(E15>=50,"B",IF(E15>=40,"C",IF(E15>=33,"D","F"))))))))) -> A | H15: =(IF(E15="","",IF(G15="F",0,IF(E15>=80,5,IF(E15>=70,4,IF(E15>=60,3.5,IF(E15>=50,3,IF(E15>=40,2,IF(E15>=33,1,0))))))))) -> 4
A16: ='Student Basic Info'!A16 -> 715 | B16: 13 | C16: 8 | D16: 18 | E16: =IF(B16+C16=0, "", B16+C16+D16) -> 39 | F16: =IF(E16="","", IF(AND(B16 >=8,C16>=17,D16>=8),"Pass","Fail")) -> Fail | G16: =(IF(E16="","",IF(F16="Fail","F",IF(E16>=80,"A+",IF(E16>=70,"A",IF(E16>=60,"A-",IF(E16>=50,"B",IF(E16>=40,"C",IF(E16>=33,"D","F"))))))))) -> F | H16: =(IF(E16="","",IF(G16="F",0,IF(E16>=80,5,IF(E16>=70,4,IF(E16>=60,3.5,IF(E16>=50,3,IF(E16>=40,2,IF(E16>=33,1,0))))))))) -> 0
A17: ='Student Basic Info'!A17 -> 716 | B17: 9 | C17: 10 | D17: 20 | E17: =IF(B17+C17=0, "", B17+C17+D17) -> 39 | F17: =IF(E17="","", IF(AND(B17 >=8,C17>=17,D17>=8),"Pass","Fail")) -> Fail | G17: =(IF(E17="","",IF(F17="Fail","F",IF(E17>=80,"A+",IF(E17>=70,"A",IF(E17>=60,"A-",IF(E17>=50,"B",IF(E17>=40,"C",IF(E17>=33,"D","F"))))))))) -> F | H17: =(IF(E17="","",IF(G17="F",0,IF(E17>=80,5,IF(E17>=70,4,IF(E17>=60,3.5,IF(E17>=50,3,IF(E17>=40,2,IF(E17>=33,1,0))))))))) -> 0
A18: ='Student Basic Info'!A18 -> 717 | B18: 10 | C18: 9 | D18: 8 | E18: =IF(B18+C18=0, "", B18+C18+D18) -> 27 | F18: =IF(E18="","", IF(AND(B18 >=8,C18>=17,D18>=8),"Pass","Fail")) -> Fail | G18: =(IF(E18="","",IF(F18="Fail","F",IF(E18>=80,"A+",IF(E18>=70,"A",IF(E18>=60,"A-",IF(E18>=50,"B",IF(E18>=40,"C",IF(E18>=33,"D","F"))))))))) -> F | H18: =(IF(E18="","",IF(G18="F",0,IF(E18>=80,5,IF(E18>=70,4,IF(E18>=60,3.5,IF(E18>=50,3,IF(E18>=40,2,IF(E18>=33,1,0))))))))) -> 0
A19: ='Student Basic Info'!A19 -> 718 | E19: =IF(B19+C19=0, "", B19+C19+D19) | F19: =IF(E19="","", IF(AND(B19 >=8,C19>=17,D19>=8),"Pass","Fail")) | G19: =(IF(E19="","",IF(F19="Fail","F",IF(E19>=80,"A+",IF(E19>=70,"A",IF(E19>=60,"A-",IF(E19>=50,"B",IF(E19>=40,"C",IF(E19>=33,"D","F"))))))))) | H19: =(IF(E19="","",IF(G19="F",0,IF(E19>=80,5,IF(E19>=70,4,IF(E19>=60,3.5,IF(E19>=50,3,IF(E19>=40,2,IF(E19>=33,1,0)))))))))
A20: ='Student Basic Info'!A20 -> 719 | B20: 12 | C20: 11 | D20: 18 | E20: =IF(B20+C20=0, "", B20+C20+D20) -> 41 | F20: =IF(E20="","", IF(AND(B20 >=8,C20>=17,D20>=8),"Pass","Fail")) -> Fail | G20: =(IF(E20="","",IF(F20="Fail","F",IF(E20>=80,"A+",IF(E20>=70,"A",IF(E20>=60,"A-",IF(E20>=50,"B",IF(E20>=40,"C",IF(E20>=33,"D","F"))))))))) -> F | H20: =(IF(E20="","",IF(G20="F",0,IF(E20>=80,5,IF(E20>=70,4,IF(E20>=60,3.5,IF(E20>=50,3,IF(E20>=40,2,IF(E20>=33,1,0))))))))) -> 0
A21: ='Student Basic Info'!A21 -> 720 | B21: 9 | C21: 8 | D21: 20 | E21: =IF(B21+C21=0, "", B21+C21+D21) -> 37 | F21: =IF(E21="","", IF(AND(B21 >=8,C21>=17,D21>=8),"Pass","Fail")) -> Fail | G21: =(IF(E21="","",IF(F21="Fail","F",IF(E21>=80,"A+",IF(E21>=70,"A",IF(E21>=60,"A-",IF(E21>=50,"B",IF(E21>=40,"C",IF(E21>=33,"D","F"))))))))) -> F | H21: =(IF(E21="","",IF(G21="F",0,IF(E21>=80,5,IF(E21>=70,4,IF(E21>=60,3.5,IF(E21>=50,3,IF(E21>=40,2,IF(E21>=33,1,0))))))))) -> 0
A22: ='Student Basic Info'!A22 -> 721 | E22: =IF(B22+C22=0, "", B22+C22+D22) | F22: =IF(E22="","", IF(AND(B22 >=8,C22>=17,D22>=8),"Pass","Fail")) | G22: =(IF(E22="","",IF(F22="Fail","F",IF(E22>=80,"A+",IF(E22>=70,"A",IF(E22>=60,"A-",IF(E22>=50,"B",IF(E22>=40,"C",IF(E22>=33,"D","F"))))))))) | H22: =(IF(E22="","",IF(G22="F",0,IF(E22>=80,5,IF(E22>=70,4,IF(E22>=60,3.5,IF(E22>=50,3,IF(E22>=40,2,IF(E22>=33,1,0)))))))))
A23: ='Student Basic Info'!A23 -> 722 | B23: 12 | C23: 2 | D23: 22 | E23: =IF(B23+C23=0, "", B23+C23+D23) -> 36 | F23: =IF(E23="","", IF(AND(B23 >=8,C23>=17,D23>=8),"Pass","Fail")) -> Fail | G23: =(IF(E23="","",IF(F23="Fail","F",IF(E23>=80,"A+",IF(E23>=70,"A",IF(E23>=60,"A-",IF(E23>=50,"B",IF(E23>=40,"C",IF(E23>=33,"D","F"))))))))) -> F | H23: =(IF(E23="","",IF(G23="F",0,IF(E23>=80,5,IF(E23>=70,4,IF(E23>=60,3.5,IF(E23>=50,3,IF(E23>=40,2,IF(E23>=33,1,0))))))))) -> 0
A24: ='Student Basic Info'!A24 -> 723 | B24: 23 | C24: 43 | D24: 25 | E24: =IF(B24+C24=0, "", B24+C24+D24) -> 91 | F24: =IF(E24="","", IF(AND(B24 >=8,C24>=17,D24>=8),"Pass","Fail")) -> Pass | G24: =(IF(E24="","",IF(F24="Fail","F",IF(E24>=80,"A+",IF(E24>=70,"A",IF(E24>=60,"A-",IF(E24>=50,"B",IF(E24>=40,"C",IF(E24>=33,"D","F"))))))))) -> A+ | H24: =(IF(E24="","",IF(G24="F",0,IF(E24>=80,5,IF(E24>=70,4,IF(E24>=60,3.5,IF(E24>=50,3,IF(E24>=40,2,IF(E24>=33,1,0))))))))) -> 5
A25: ='Student Basic Info'!A25 -> 724 | B25: 22 | C25: 9 | D25: 25 | E25: =IF(B25+C25=0, "", B25+C25+D25) -> 56 | F25: =IF(E25="","", IF(AND(B25 >=8,C25>=17,D25>=8),"Pass","Fail")) -> Fail | G25: =(IF(E25="","",IF(F25="Fail","F",IF(E25>=80,"A+",IF(E25>=70,"A",IF(E25>=60,"A-",IF(E25>=50,"B",IF(E25>=40,"C",IF(E25>=33,"D","F"))))))))) -> F | H25: =(IF(E25="","",IF(G25="F",0,IF(E25>=80,5,IF(E25>=70,4,IF(E25>=60,3.5,IF(E25>=50,3,IF(E25>=40,2,IF(E25>=33,1,0))))))))) -> 0
A26: ='Student Basic Info'!A26 -> 725 | B26: 11 | C26: 8 | D26: 8 | E26: =IF(B26+C26=0, "", B26+C26+D26) -> 27 | F26: =IF(E26="","", IF(AND(B26 >=8,C26>=17,D26>=8),"Pass","Fail")) -> Fail | G26: =(IF(E26="","",IF(F26="Fail","F",IF(E26>=80,"A+",IF(E26>=70,"A",IF(E26>=60,"A-",IF(E26>=50,"B",IF(E26>=40,"C",IF(E26>=33,"D","F"))))))))) -> F | H26: =(IF(E26="","",IF(G26="F",0,IF(E26>=80,5,IF(E26>=70,4,IF(E26>=60,3.5,IF(E26>=50,3,IF(E26>=40,2,IF(E26>=33,1,0))))))))) -> 0
A27: ='Student Basic Info'!A27 -> 726 | E27: =IF(B27+C27=0, "", B27+C27+D27) | F27: =IF(E27="","", IF(AND(B27 >=8,C27>=17,D27>=8),"Pass","Fail")) | G27: =(IF(E27="","",IF(F27="Fail","F",IF(E27>=80,"A+",IF(E27>=70,"A",IF(E27>=60,"A-",IF(E27>=50,"B",IF(E27>=40,"C",IF(E27>=33,"D","F"))))))))) | H27: =(IF(E27="","",IF(G27="F",0,IF(E27>=80,5,IF(E27>=70,4,IF(E27>=60,3.5,IF(E27>=50,3,IF(E27>=40,2,IF(E27>=33,1,0)))))))))
A28: ='Student Basic Info'!A28 -> 727 | B28: 21 | C28: 38 | D28: 25 | E28: =IF(B28+C28=0, "", B28+C28+D28) -> 84 | F28: =IF(E28="","", IF(AND(B28 >=8,C28>=17,D28>=8),"Pass","Fail")) -> Pass | G28: =(IF(E28="","",IF(F28="Fail","F",IF(E28>=80,"A+",IF(E28>=70,"A",IF(E28>=60,"A-",IF(E28>=50,"B",IF(E28>=40,"C",IF(E28>=33,"D","F"))))))))) -> A+ | H28: =(IF(E28="","",IF(G28="F",0,IF(E28>=80,5,IF(E28>=70,4,IF(E28>=60,3.5,IF(E28>=50,3,IF(E28>=40,2,IF(E28>=33,1,0))))))))) -> 5
A29: ='Student Basic Info'!A29 -> 728 | B29: 13 | C29: 6 | D29: 24 | E29: =IF(B29+C29=0, "", B29+C29+D29) -> 43 | F29: =IF(E29="","", IF(AND(B29 >=8,C29>=17,D29>=8),"Pass","Fail")) -> Fail | G29: =(IF(E29="","",IF(F29="Fail","F",IF(E29>=80,"A+",IF(E29>=70,"A",IF(E29>=60,"A-",IF(E29>=50,"B",IF(E29>=40,"C",IF(E29>=33,"D","F"))))))))) -> F | H29: =(IF(E29="","",IF(G29="F",0,IF(E29>=80,5,IF(E29>=70,4,IF(E29>=60,3.5,IF(E29>=50,3,IF(E29>=40,2,IF(E29>=33,1,0))))))))) -> 0
A30: ='Student Basic Info'!A30 -> 729 | B30: 13 | C30: 8 | D30: 24 | E30: =IF(B30+C30=0, "", B30+C30+D30) -> 45 | F30: =IF(E30="","", IF(AND(B30 >=8,C30>=17,D30>=8),"Pass","Fail")) -> Fail | G30: =(IF(E30="","",IF(F30="Fail","F",IF(E30>=80,"A+",IF(E30>=70,"A",IF(E30>=60,"A-",IF(E30>=50,"B",IF(E30>=40,"C",IF(E30>=33,"D","F"))))))))) -> F | H30: =(IF(E30="","",IF(G30="F",0,IF(E30>=80,5,IF(E30>=70,4,IF(E30>=60,3.5,IF(E30>=50,3,IF(E30>=40,2,IF(E30>=33,1,0))))))))) -> 0
A31: ='Student Basic Info'!A31 -> 730 | B31: 8 | C31: 1 | D31: 24 | E31: =IF(B31+C31=0, "", B31+C31+D31) -> 33 | F31: =IF(E31="","", IF(AND(B31 >=8,C31>=17,D31>=8),"Pass","Fail")) -> Fail | G31: =(IF(E31="","",IF(F31="Fail","F",IF(E31>=80,"A+",IF(E31>=70,"A",IF(E31>=60,"A-",IF(E31>=50,"B",IF(E31>=40,"C",IF(E31>=33,"D","F"))))))))) -> F | H31: =(IF(E31="","",IF(G31="F",0,IF(E31>=80,5,IF(E31>=70,4,IF(E31>=60,3.5,IF(E31>=50,3,IF(E31>=40,2,IF(E31>=33,1,0))))))))) -> 0
A32: ='Student Basic Info'!A32 -> 731 | B32: 8 | C32: 8 | D32: 20 | E32: =IF(B32+C32=0, "", B32+C32+D32) -> 36 | F32: =IF(E32="","", IF(AND(B32 >=8,C32>=17,D32>=8),"Pass","Fail")) -> Fail | G32: =(IF(E32="","",IF(F32="Fail","F",IF(E32>=80,"A+",IF(E32>=70,"A",IF(E32>=60,"A-",IF(E32>=50,"B",IF(E32>=40,"C",IF(E32>=33,"D","F"))))))))) -> F | H32: =(IF(E32="","",IF(G32="F",0,IF(E32>=80,5,IF(E32>=70,4,IF(E32>=60,3.5,IF(E32>=50,3,IF(E32>=40,2,IF(E32>=33,1,0))))))))) -> 0
A33: ='Student Basic Info'!A33 -> 732 | B33: 12 | C33: 12 | D33: 22 | E33: =IF(B33+C33=0, "", B33+C33+D33) -> 46 | F33: =IF(E33="","", IF(AND(B33 >=8,C33>=17,D33>=8),"Pass","Fail")) -> Fail | G33: =(IF(E33="","",IF(F33="Fail","F",IF(E33>=80,"A+",IF(E33>=70,"A",IF(E33>=60,"A-",IF(E33>=50,"B",IF(E33>=40,"C",IF(E33>=33,"D","F"))))))))) -> F | H33: =(IF(E33="","",IF(G33="F",0,IF(E33>=80,5,IF(E33>=70,4,IF(E33>=60,3.5,IF(E33>=50,3,IF(E33>=40,2,IF(E33>=33,1,0))))))))) -> 0
A34: ='Student Basic Info'!A34 -> 733 | B34: 7 | C34: 8 | D34: 20 | E34: =IF(B34+C34=0, "", B34+C34+D34) -> 35 | F34: =IF(E34="","", IF(AND(B34 >=8,C34>=17,D34>=8),"Pass","Fail")) -> Fail | G34: =(IF(E34="","",IF(F34="Fail","F",IF(E34>=80,"A+",IF(E34>=70,"A",IF(E34>=60,"A-",IF(E34>=50,"B",IF(E34>=40,"C",IF(E34>=33,"D","F"))))))))) -> F | H34: =(IF(E34="","",IF(G34="F",0,IF(E34>=80,5,IF(E34>=70,4,IF(E34>=60,3.5,IF(E34>=50,3,IF(E34>=40,2,IF(E34>=33,1,0))))))))) -> 0
