Workbook

Sheet Introduction
D8: RESULT PROCESSING SYSTEM Developed by ALI HOSSAIN
D9: BSc. in Computer Science & Enginnering, University of Chittagong
D10: Lecturer in Information & Communication Technology, Bamni Degree College

Sheet Inputs
A2: Title of Exam | C2: First Year - Term Exam 2024
A4: Number of Science Students
A6: Number of Commerce Students
A8: Number of Arts Students
A10: Total Number of Students | C10: =C4+C6+C8 -> 0
A12: MCQ Mark | C12: 25
A14: CQ Mark | C14: 50
A16: Practical Mark | C16: 25
A18: Total Marks | C18: =C12+C14+C16 -> 100

Sheet Sheet1
A1: Group | B1: Roll | C1: Subject1 | D1: Subject2 | E1: Subject3 | F1: Subject4
A2: Science | B2: 701
A3: Science | B3: 702
A4: Science | B4: 703
A5: Science | B5: 704
A6: Science | B6: 705
A7: Science | B7: 706
A8: Science | B8: 707
A9: Science | B9: 708
A10: Science | B10: 709
A11: Science | B11: 710
A12: Commerce
A13: Commerce
A14: Commerce
A15: Commerce
A16: Commerce
A17: Arts
A18: Arts
A19: Arts
A20: Arts
A21: Arts

Sheet Student Basic Info
A1: Roll | B1: Group | C1: Name | D1: Father | E1: Mother | F1: Gender | G1: Religion | H1: Address | I1: Contact | J1: Session | K1: Remarks
A2: 501 | B2: Business Studies | C2: Robiul Sani | D2: Md. Mobarok Hosain | E2: Sweety Begum | F2: Male | G2: Islam | H2: Bamni Bank Road, Companiganj, Noakhali | I2: 01737859493 | J2: 2023-24
A3: 502 | B3: Business Studies | C3: Shakhawat Hosain | D3: Abdul Sattar | E3: Nur Zanan Begum | F3: Male | G3: Islam | H3: Bamni Bank Road, Companiganj, Noakhali | I3: 01737859493 | J3: 2023-24
A4: 503 | B4: Business Studies | C4: Nusrat Sultana | D4: Golan Sarwar | E4: Anowara Begum | F4: Female | G4: Islam | H4: Bamni Bank Road, Companiganj, Noakhali | I4: 01737859493 | J4: 2023-24
A5: 504 | B5: Business Studies | C5: Nusrat Zahan | D5: Md. Ibrahim | E5: Mst. Marjahan | F5: Female | G5: Islam | H5: Bamni Bank Road, Companiganj, Noakhali | I5: 01737859493 | J5: 2023-24
A6: 505 | B6: Business Studies | C6: Istiaque Mahmud | D6: Samsuddin Rumu | E6: Nur Nahar Begum | F6: Male | G6: Islam | H6: Bamni Bank Road, Companiganj, Noakhali | I6: 01737859493 | J6: 2023-24
A7: 506 | B7: Business Studies | C7: Naznin Aktar | D7: Ruhul Amin | E7: Hasina Aktar | F7: Female | G7: Islam | H7: Bamni Bank Road, Companiganj, Noakhali | I7: 01737859493 | J7: 2023-24
A8: 507 | B8: Business Studies | C8: Fariha Islam | D8: Mohammad Selim | E8: Parvin Aktar | F8: Female | G8: Islam | H8: Bamni Bank Road, Companiganj, Noakhali | I8: 01737859493 | J8: 2023-24
A9: 508 | B9: Business Studies | C9: Suraiya Aktar | D9: Nur Alom | E9: Selina Aktar | F9: Female | G9: Islam | H9: Bamni Bank Road, Companiganj, Noakhali | I9: 01737859493 | J9: 2023-24
A10: 509 | B10: Business Studies | C10: Muntasir Ahamml Siyam | D10: Hannan Ahmed | E10: Nilufa Yeasmin | F10: Male | G10: Islam | H10: Bamni Bank Road, Companiganj, Noakhali | I10: 01737859493 | J10: 2023-24
A11: 510 | B11: Business Studies | C11: Tanbir Ahammed Alif | D11: Daud Ahamod | E11: Shokhina Khatun | F11: Male | G11: Islam | H11: Bamni Bank Road, Companiganj, Noakhali | I11: 01737859493 | J11: 2023-24
A12: 511 | B12: Business Studies | C12: Asifuz Zaman | D12: Abul Hosain | E12: Arzu Begum | F12: Male | G12: Islam | H12: Bamni Bank Road, Companiganj, Noakhali | I12: 01737859494 | J12: 2023-24
A13: 512 | B13: Business Studies | C13: Md. Arfatuzzaman | D13: Md. Alomgir | E13: Joinob Bibi | F13: Male | G13: Islam | H13: Bamni Bank Road, Companiganj, Noakhali | I13: 01737859495 | J13: 2023-24
... A141: 640 | B141: Business Studies | C141: Sazzad Hossain Sanzid | D141: Md. Shohel | E141: Nazmun Nahar Shopna | F141: Male | G141: Islam | H141: Bamni Bank Road, Companiganj, Noakhali | I141: 01737859623 | J141: 2023-144
A142: 641 | B142: Business Studies | C142: Md. Sohrab Hossain | F142: Male | G142: Islam | H142: Bamni Bank Road, Companiganj, Noakhali | I142: 01737859624 | J142: 2023-145
A143: 642 | B143: Business Studies | C143: Jannatul Nure Hafsa | H143: Bamni Bank Road, Companiganj, Noakhali | I143: 01737859625 | J143: 2023-146
A144: 643 | B144: Business Studies | F144: Female | G144: Islam | H144: Bamni Bank Road, Companiganj, Noakhali | I144: 01737859626 | J144: 2023-147
A145: 644 | B145: Business Studies | C145: Khadiza Aktar | F145: Female | G145: Islam | H145: Bamni Bank Road, Companiganj, Noakhali | I145: 01737859627 | J145: 2023-148

Sheet Prev. Academic
A1: ID | B1: Institution Name | C1: Group | D1: Session | E1: GPA | F1: Board Name | G1: Roll | H1: Reg No
A2: ='Student Basic Info'!A2 -> 501 | B2: Bamni High School | C2: Commerce | D2: 2022-23 | E2: 5 | F2: Cumilla | H2: 2111897195
A3: ='Student Basic Info'!A3 -> 502 | B3: Bamni High School | C3: Commerce | D3: 2022-24 | E3: 5 | F3: Cumilla | H3: 2111897230
A4: ='Student Basic Info'!A4 -> 503 | B4: Bamni High School | C4: Commerce | D4: 2022-25 | E4: 5 | F4: Cumilla | H4: 2111896557
A5: ='Student Basic Info'!A5 -> 504 | B5: Bamni High School | C5: Commerce | D5: 2022-26 | E5: 5 | F5: Cumilla | H5: 2011600400
A6: ='Student Basic Info'!A6 -> 505 | B6: Bamni High School | C6: Commerce | D6: 2022-27 | E6: 5 | F6: Cumilla | H6: 2111896454
A7: ='Student Basic Info'!A7 -> 506 | B7: Bamni High School | C7: Commerce | D7: 2022-28 | E7: 5 | F7: Cumilla | H7: 2111897040
A8: ='Student Basic Info'!A8 -> 507 | B8: Bamni High School | C8: Commerce | D8: 2022-29 | E8: 5 | F8: Cumilla | H8: 2111895023
A9: ='Student Basic Info'!A9 -> 508 | B9: Bamni High School | C9: Commerce | D9: 2022-30 | E9: 5 | F9: Cumilla | H9: 2011602371
A10: ='Student Basic Info'!A10 -> 509 | B10: Bamni High School | C10: Commerce | D10: 2022-31 | E10: 5 | F10: Cumilla | H10: 2011600444
A11: ='Student Basic Info'!A11 -> 510 | B11: Bamni High School | C11: Commerce | D11: 2022-32 | E11: 5 | F11: Cumilla | H11: 2111895048
A12: ='Student Basic Info'!A12 -> 511 | B12: Bamni High School | C12: Commerce | D12: 2022-33 | E12: 5 | F12: Cumilla | H12: 2011600142
A13: ='Student Basic Info'!A13 -> 512 | B13: Bamni High School | C13: Commerce | D13: 2022-34 | E13: 5 | F13: Cumilla | H13: 2111897198
... A88: ='Student Basic Info'!A88 -> 587 | B88: Bamni High School | C88: Commerce | D88: 2022-109 | E88: 5 | F88: Cumilla | H88: 2011601550
A89: ='Student Basic Info'!A89 -> 588 | C89: Commerce | H89: 2011601552
A90: ='Student Basic Info'!A90 -> 589 | C90: Commerce | H90: 2011601562
A91: ='Student Basic Info'!A91 -> 590 | C91: Commerce | H91: 2111897242
A92: ='Student Basic Info'!A92 -> 591 | C92: Commerce | H92: 2011599834
A93: ='Student Basic Info'!A93 -> 592 | C93: Commerce | H93: 2111897172
A94: ='Student Basic Info'!A94 -> 593 | C94: Commerce | H94: 2111896300
A95: ='Student Basic Info'!A95 -> 594 | C95: Commerce | H95: 2011602370
A96: ='Student Basic Info'!A96 -> 595 | C96: Commerce | H96: 2011600458
A97: ='Student Basic Info'!A97 -> 596 | C97: Commerce | H97: 2111896294
A98: ='Student Basic Info'!A98 -> 597 | C98: Commerce | H98: 2111849077
A99: ='Student Basic Info'!A99 -> 598 | C99: Commerce | H99: 2111897012
A100: ='Student Basic Info'!A100 -> 599 | C100: Commerce | H100: 2011602540
... A130: ='Student Basic Info'!A130 -> 629 | C130: Commerce | H130: 2011602105

Sheet SubjectList
A1: ID | B1: Compulsory1 | C1: Compulsory2 | D1: Compulsory3 | E1: Subject1 | F1: Subject2 | G1: Subject3 | H1: Subject4 | I1: Optioinal
A2: ='Student Basic Info'!A2 -> 501 | B2: Bangla | C2: English | D2: ICT | E2: Accounting | F2: Business Organization | G2: Finance | H2: Production | I2: =H2 -> Production
A3: ='Student Basic Info'!A3 -> 502 | B3: Bangla | C3: English | D3: ICT | E3: Accounting | F3: Business Organization | G3: Finance | H3: Economics | I3: =H3 -> Economics
A4: ='Student Basic Info'!A4 -> 503 | B4: Bangla | C4: English | D4: ICT | E4: Accounting | F4: Business Organization | G4: Production | H4: Economics | I4: =H4 -> Economics
A5: ='Student Basic Info'!A5 -> 504 | B5: Bangla | C5: English | D5: ICT | E5: Accounting | F5: Business Organization | G5: Production | H5: Economics | I5: =H5 -> Economics
A6: ='Student Basic Info'!A6 -> 505 | B6: Bangla | C6: English | D6: ICT | E6: Accounting | F6: Business Organization | G6: Finance | H6: Economics | I6: =H6 -> Economics
A7: ='Student Basic Info'!A7 -> 506 | B7: Bangla | C7: English | D7: ICT | E7: Accounting | F7: Business Organization | G7: Finance | H7: Economics | I7: =H7 -> Economics
A8: ='Student Basic Info'!A8 -> 507 | B8: Bangla | C8: English | D8: ICT | E8: Accounting | F8: Business Organization | G8: Finance | H8: Production | I8: =H8 -> Production
A9: ='Student Basic Info'!A9 -> 508 | B9: Bangla | C9: English | D9: ICT | E9: Accounting | F9: Business Organization | G9: Production | H9: Finance | I9: =H9 -> Finance
A10: ='Student Basic Info'!A10 -> 509 | B10: Bangla | C10: English | D10: ICT | E10: Accounting | F10: Business Organization | G10: Finance | H10: Production | I10: =H10 -> Production
A11: ='Student Basic Info'!A11 -> 510 | B11: Bangla | C11: English | D11: ICT | E11: Accounting | F11: Business Organization | G11: Finance | H11: Production | I11: =H11 -> Production
A12: ='Student Basic Info'!A12 -> 511 | B12: Bangla | C12: English | D12: ICT | E12: Accounting | F12: Business Organization | G12: Production | H12: Finance | I12: =H12 -> Finance
A13: ='Student Basic Info'!A13 -> 512 | B13: Bangla | C13: English | D13: ICT | E13: Accounting | F13: Business Organization | G13: Finance | H13: Production | I13: =H13 -> Production
... A145: ='Student Basic Info'!A145 -> 644 | B145: Bangla | C145: English | D145: ICT | E145: Accounting | F145: Business Organization | G145: Finance | H145: Production | I145: =H145 -> Production

Sheet Bangla
A1: Roll | B1: Marks MCQ | C1: Marks CQ | D1: Total Marks | E1: Result | F1: Grade | G1: GPA
A2: ='Student Basic Info'!A2 -> 501 | D2: =IF(B2+C2=0, "", B2+C2) | E2: =IF(D2="","", IF(C2>=33,"Pass","Fail")) | F2: =(IF(D2="","",IF(E2="Fail","F",IF(D2>=80,"A+",IF(D2>=70,"A",IF(D2>=60,"A-",IF(D2>=50,"B",IF(D2>=40,"C",IF(D2>=33,"D","F"))))))))) | G2: =(IF(D2="","",IF(F2="F",0,IF(D2>=80,5,IF(D2>=70,4,IF(D2>=60,3.5,IF(D2>=50,3,IF(D2>=40,2,IF(D2>=33,1,0)))))))))
A3: ='Student Basic Info'!A3 -> 502 | D3: =IF(B3+C3=0, "", B3+C3) | E3: =IF(D3="","", IF(C3>=33,"Pass","Fail")) | F3: =(IF(D3="","",IF(E3="Fail","F",IF(D3>=80,"A+",IF(D3>=70,"A",IF(D3>=60,"A-",IF(D3>=50,"B",IF(D3>=40,"C",IF(D3>=33,"D","F"))))))))) | G3: =(IF(D3="","",IF(F3="F",0,IF(D3>=80,5,IF(D3>=70,4,IF(D3>=60,3.5,IF(D3>=50,3,IF(D3>=40,2,IF(D3>=33,1,0)))))))))
A4: ='Student Basic Info'!A4 -> 503 | C4: 50 | D4: =IF(B4+C4=0, "", B4+C4) -> 50 | E4: =IF(D4="","", IF(C4>=33,"Pass","Fail")) -> Pass | F4: =(IF(D4="","",IF(E4="Fail","F",IF(D4>=80,"A+",IF(D4>=70,"A",IF(D4>=60,"A-",IF(D4>=50,"B",IF(D4>=40,"C",IF(D4>=33,"D","F"))))))))) -> B | G4: =(IF(D4="","",IF(F4="F",0,IF(D4>=80,5,IF(D4>=70,4,IF(D4>=60,3.5,IF(D4>=50,3,IF(D4>=40,2,IF(D4>=33,1,0))))))))) -> 3
A5: ='Student Basic Info'!A5 -> 504 | C5: 56 | D5: =IF(B5+C5=0, "", B5+C5) -> 56 | E5: =IF(D5="","", IF(C5>=33,"Pass","Fail")) -> Pass | F5: =(IF(D5="","",IF(E5="Fail","F",IF(D5>=80,"A+",IF(D5>=70,"A",IF(D5>=60,"A-",IF(D5>=50,"B",IF(D5>=40,"C",IF(D5>=33,"D","F"))))))))) -> B | G5: =(IF(D5="","",IF(F5="F",0,IF(D5>=80,5,IF(D5>=70,4,IF(D5>=60,3.5,IF(D5>=50,3,IF(D5>=40,2,IF(D5>=33,1,0))))))))) -> 3
A6: ='Student Basic Info'!A6 -> 505 | D6: =IF(B6+C6=0, "", B6+C6) | E6: =IF(D6="","", IF(C6>=33,"Pass","Fail")) | F6: =(IF(D6="","",IF(E6="Fail","F",IF(D6>=80,"A+",IF(D6>=70,"A",IF(D6>=60,"A-",IF(D6>=50,"B",IF(D6>=40,"C",IF(D6>=33,"D","F"))))))))) | G6: =(IF(D6="","",IF(F6="F",0,IF(D6>=80,5,IF(D6>=70,4,IF(D6>=60,3.5,IF(D6>=50,3,IF(D6>=40,2,IF(D6>=33,1,0)))))))))
A7: ='Student Basic Info'!A7 -> 506 | D7: =IF(B7+C7=0, "", B7+C7) | E7: =IF(D7="","", IF(C7>=33,"Pass","Fail")) | F7: =(IF(D7="","",IF(E7="Fail","F",IF(D7>=80,"A+",IF(D7>=70,"A",IF(D7>=60,"A-",IF(D7>=50,"B",IF(D7>=40,"C",IF(D7>=33,"D","F"))))))))) | G7: =(IF(D7="","",IF(F7="F",0,IF(D7>=80,5,IF(D7>=70,4,IF(D7>=60,3.5,IF(D7>=50,3,IF(D7>=40,2,IF(D7>=33,1,0)))))))))
A8: ='Student Basic Info'!A8 -> 507 | C8: 60 | D8: =IF(B8+C8=0, "", B8+C8) -> 60 | E8: =IF(D8="","", IF(C8>=33,"Pass","Fail")) -> Pass | F8: =(IF(D8="","",IF(E8="Fail","F",IF(D8>=80,"A+",IF(D8>=70,"A",IF(D8>=60,"A-",IF(D8>=50,"B",IF(D8>=40,"C",IF(D8>=33,"D","F"))))))))) -> A- | G8: =(IF(D8="","",IF(F8="F",0,IF(D8>=80,5,IF(D8>=70,4,IF(D8>=60,3.5,IF(D8>=50,3,IF(D8>=40,2,IF(D8>=33,1,0))))))))) -> 3.5
A9: ='Student Basic Info'!A9 -> 508 | C9: 50 | D9: =IF(B9+C9=0, "", B9+C9) -> 50 | E9: =IF(D9="","", IF(C9>=33,"Pass","Fail")) -> Pass | F9: =(IF(D9="","",IF(E9="Fail","F",IF(D9>=80,"A+",IF(D9>=70,"A",IF(D9>=60,"A-",IF(D9>=50,"B",IF(D9>=40,"C",IF(D9>=33,"D","F"))))))))) -> B | G9: =(IF(D9="","",IF(F9="F",0,IF(D9>=80,5,IF(D9>=70,4,IF(D9>=60,3.5,IF(D9>=50,3,IF(D9>=40,2,IF(D9>=33,1,0))))))))) -> 3
A10: ='Student Basic Info'!A10 -> 509 | C10: 33 | D10: =IF(B10+C10=0, "", B10+C10) -> 33 | E10: =IF(D10="","", IF(C10>=33,"Pass","Fail")) -> Pass | F10: =(IF(D10="","",IF(E10="Fail","F",IF(D10>=80,"A+",IF(D10>=70,"A",IF(D10>=60,"A-",IF(D10>=50,"B",IF(D10>=40,"C",IF(D10>=33,"D","F"))))))))) -> D | G10: =(IF(D10="","",IF(F10="F",0,IF(D10>=80,5,IF(D10>=70,4,IF(D10>=60,3.5,IF(D10>=50,3,IF(D10>=40,2,IF(D10>=33,1,0))))))))) -> 1
A11: ='Student Basic Info'!A11 -> 510 | D11: =IF(B11+C11=0, "", B11+C11) | E11: =IF(D11="","", IF(C11>=33,"Pass","Fail")) | F11: =(IF(D11="","",IF(E11="Fail","F",IF(D11>=80,"A+",IF(D11>=70,"A",IF(D11>=60,"A-",IF(D11>=50,"B",IF(D11>=40,"C",IF(D11>=33,"D","F"))))))))) | G11: =(IF(D11="","",IF(F11="F",0,IF(D11>=80,5,IF(D11>=70,4,IF(D11>=60,3.5,IF(D11>=50,3,IF(D11>=40,2,IF(D11>=33,1,0)))))))))
A12: ='Student Basic Info'!A12 -> 511 | C12: 41 | D12: =IF(B12+C12=0, "", B12+C12) -> 41 | E12: =IF(D12="","", IF(C12>=33,"Pass","Fail")) -> Pass | F12: =(IF(D12="","",IF(E12="Fail","F",IF(D12>=80,"A+",IF(D12>=70,"A",IF(D12>=60,"A-",IF(D12>=50,"B",IF(D12>=40,"C",IF(D12>=33,"D","F"))))))))) -> C | G12: =(IF(D12="","",IF(F12="F",0,IF(D12>=80,5,IF(D12>=70,4,IF(D12>=60,3.5,IF(D12>=50,3,IF(D12>=40,2,IF(D12>=33,1,0))))))))) -> 2
A13: ='Student Basic Info'!A13 -> 512 | C13: 34 | D13: =IF(B13+C13=0, "", B13+C13) -> 34 | E13: =IF(D13="","", IF(C13>=33,"Pass","Fail")) -> Pass | F13: =(IF(D13="","",IF(E13="Fail","F",IF(D13>=80,"A+",IF(D13>=70,"A",IF(D13>=60,"A-",IF(D13>=50,"B",IF(D13>=40,"C",IF(D13>=33,"D","F"))))))))) -> D | G13: =(IF(D13="","",IF(F13="F",0,IF(D13>=80,5,IF(D13>=70,4,IF(D13>=60,3.5,IF(D13>=50,3,IF(D13>=40,2,IF(D13>=33,1,0))))))))) -> 1
A14: ='Student Basic Info'!A14 -> 513 | C14: 36 | D14: =IF(B14+C14=0, "", B14+C14) -> 36 | E14: =IF(D14="","", IF(C14>=33,"Pass","Fail")) -> Pass | F14: =(IF(D14="","",IF(E14="Fail","F",IF(D14>=80,"A+",IF(D14>=70,"A",IF(D14>=60,"A-",IF(D14>=50,"B",IF(D14>=40,"C",IF(D14>=33,"D","F"))))))))) -> D | G14: =(IF(D14="","",IF(F14="F",0,IF(D14>=80,5,IF(D14>=70,4,IF(D14>=60,3.5,IF(D14>=50,3,IF(D14>=40,2,IF(D14>=33,1,0))))))))) -> 1
A15: ='Student Basic Info'!A15 -> 514 | D15: =IF(B15+C15=0, "", B15+C15) | E15: =IF(D15="","", IF(C15>=33,"Pass","Fail")) | F15: =(IF(D15="","",IF(E15="Fail","F",IF(D15>=80,"A+",IF(D15>=70,"A",IF(D15>=60,"A-",IF(D15>=50,"B",IF(D15>=40,"C",IF(D15>=33,"D","F"))))))))) | G15: =(IF(D15="","",IF(F15="F",0,IF(D15>=80,5,IF(D15>=70,4,IF(D15>=60,3.5,IF(D15>=50,3,IF(D15>=40,2,IF(D15>=33,1,0)))))))))
A16: ='Student Basic Info'!A16 -> 515 | C16: 60 | D16: =IF(B16+C16=0, "", B16+C16) -> 60 | E16: =IF(D16="","", IF(C16>=33,"Pass","Fail")) -> Pass | F16: =(IF(D16="","",IF(E16="Fail","F",IF(D16>=80,"A+",IF(D16>=70,"A",IF(D16>=60,"A-",IF(D16>=50,"B",IF(D16>=40,"C",IF(D16>=33,"D","F"))))))))) -> A- | G16: =(IF(D16="","",IF(F16="F",0,IF(D16>=80,5,IF(D16>=70,4,IF(D16>=60,3.5,IF(D16>=50,3,IF(D16>=40,2,IF(D16>=33,1,0))))))))) -> 3.5
A17: ='Student Basic Info'!A17 -> 516 | C17: 66 | D17: =IF(B17+C17=0, "", B17+C17) -> 66 | E17: =IF(D17="","", IF(C17>=33,"Pass","Fail")) -> Pass | F17: =(IF(D17="","",IF(E17="Fail","F",IF(D17>=80,"A+",IF(D17>=70,"A",IF(D17>=60,"A-",IF(D17>=50,"B",IF(D17>=40,"C",IF(D17>=33,"D","F"))))))))) -> A- | G17: =(IF(D17="","",IF(F17="F",0,IF(D17>=80,5,IF(D17>=70,4,IF(D17>=60,3.5,IF(D17>=50,3,IF(D17>=40,2,IF(D17>=33,1,0))))))))) -> 3.5
A18: ='Student Basic Info'!A18 -> 517 | D18: =IF(B18+C18=0, "", B18+C18) | E18: =IF(D18="","", IF(C18>=33,"Pass","Fail")) | F18: =(IF(D18="","",IF(E18="Fail","F",IF(D18>=80,"A+",IF(D18>=70,"A",IF(D18>=60,"A-",IF(D18>=50,"B",IF(D18>=40,"C",IF(D18>=33,"D","F"))))))))) | G18: =(IF(D18="","",IF(F18="F",0,IF(D18>=80,5,IF(D18>=70,4,IF(D18>=60,3.5,IF(D18>=50,3,IF(D18>=40,2,IF(D18>=33,1,0)))))))))
A19: ='Student Basic Info'!A19 -> 518 | D19: =IF(B19+C19=0, "", B19+C19) | E19: =IF(D19="","", IF(C19>=33,"Pass","Fail")) | F19: =(IF(D19="","",IF(E19="Fail","F",IF(D19>=80,"A+",IF(D19>=70,"A",IF(D19>=60,"A-",IF(D19>=50,"B",IF(D19>=40,"C",IF(D19>=33,"D","F"))))))))) | G19: =(IF(D19="","",IF(F19="F",0,IF(D19>=80,5,IF(D19>=70,4,IF(D19>=60,3.5,IF(D19>=50,3,IF(D19>=40,2,IF(D19>=33,1,0)))))))))
A20: ='Student Basic Info'!A20 -> 519 | C20: 37 | D20: =IF(B20+C20=0, "", B20+C20) -> 37 | E20: =IF(D20="","", IF(C20>=33,"Pass","Fail")) -> Pass | F20: =(IF(D20="","",IF(E20="Fail","F",IF(D20>=80,"A+",IF(D20>=70,"A",IF(D20>=60,"A-",IF(D20>=50,"B",IF(D20>=40,"C",IF(D20>=33,"D","F"))))))))) -> D | G20: =(IF(D20="","",IF(F20="F",0,IF(D20>=80,5,IF(D20>=70,4,IF(D20>=60,3.5,IF(D20>=50,3,IF(D20>=40,2,IF(D20>=33,1,0))))))))) -> 1
A21: ='Student Basic Info'!A21 -> 520 | C21: 25 | D21: =IF(B21+C21=0, "", B21+C21) -> 25 | E21: =IF(D21="","", IF(C21>=33,"Pass","Fail")) -> Fail | F21: =(IF(D21="","",IF(E21="Fail","F",IF(D21>=80,"A+",IF(D21>=70,"A",IF(D21>=60,"A-",IF(D21>=50,"B",IF(D21>=40,"C",IF(D21>=33,"D","F"))))))))) -> F | G21: =(IF(D21="","",IF(F21="F",0,IF(D21>=80,5,IF(D21>=70,4,IF(D21>=60,3.5,IF(D21>=50,3,IF(D21>=40,2,IF(D21>=33,1,0))))))))) -> 0
A22: ='Student Basic Info'!A22 -> 521 | D22: =IF(B22+C22=0, "", B22+C22) | E22: =IF(D22="","", IF(C22>=33,"Pass","Fail")) | F22: =(IF(D22="","",IF(E22="Fail","F",IF(D22>=80,"A+",IF(D22>=70,"A",IF(D22>=60,"A-",IF(D22>=50,"B",IF(D22>=40,"C",IF(D22>=33,"D","F"))))))))) | G22: =(IF(D22="","",IF(F22="F",0,IF(D22>=80,5,IF(D22>=70,4,IF(D22>=60,3.5,IF(D22>=50,3,IF(D22>=40,2,IF(D22>=33,1,0)))))))))
A23: ='Student Basic Info'!A23 -> 522 | C23: 64 | D23: =IF(B23+C23=0, "", B23+C23) -> 64 | E23: =IF(D23="","", IF(C23>=33,"Pass","Fail")) -> Pass | F23: =(IF(D23="","",IF(E23="Fail","F",IF(D23>=80,"A+",IF(D23>=70,"A",IF(D23>=60,"A-",IF(D23>=50,"B",IF(D23>=40,"C",IF(D23>=33,"D","F"))))))))) -> A- | G23: =(IF(D23="","",IF(F23="F",0,IF(D23>=80,5,IF(D23>=70,4,IF(D23>=60,3.5,IF(D23>=50,3,IF(D23>=40,2,IF(D23>=33,1,0))))))))) -> 3.5
A24: ='Student Basic Info'!A24 -> 523 | C24: 43 | D24: =IF(B24+C24=0, "", B24+C24) -> 43 | E24: =IF(D24="","", IF(C24>=33,"Pass","Fail")) -> Pass | F24: =(IF(D24="","",IF(E24="Fail","F",IF(D24>=80,"A+",IF(D24>=70,"A",IF(D24>=60,"A-",IF(D24>=50,"B",IF(D24>=40,"C",IF(D24>=33,"D","F"))))))))) -> C | G24: =(IF(D24="","",IF(F24="F",0,IF(D24>=80,5,IF(D24>=70,4,IF(D24>=60,3.5,IF(D24>=50,3,IF(D24>=40,2,IF(D24>=33,1,0))))))))) -> 2
A25: ='Student Basic Info'!A25 -> 524 | C25: 60 | D25: =IF(B25+C25=0, "", B25+C25) -> 60 | E25: =IF(D25="","", IF(C25>=33,"Pass","Fail")) -> Pass | F25: =(IF(D25="","",IF(E25="Fail","F",IF(D25>=80,"A+",IF(D25>=70,"A",IF(D25>=60,"A-",IF(D25>=50,"B",IF(D25>=40,"C",IF(D25>=33,"D","F"))))))))) -> A- | G25: =(IF(D25="","",IF(F25="F",0,IF(D25>=80,5,IF(D25>=70,4,IF(D25>=60,3.5,IF(D25>=50,3,IF(D25>=40,2,IF(D25>=33,1,0))))))))) -> 3.5
A26: ='Student Basic Info'!A26 -> 525 | D26: =IF(B26+C26=0, "", B26+C26) | E26: =IF(D26="","", IF(C26>=33,"Pass","Fail")) | F26: =(IF(D26="","",IF(E26="Fail","F",IF(D26>=80,"A+",IF(D26>=70,"A",IF(D26>=60,"A-",IF(D26>=50,"B",IF(D26>=40,"C",IF(D26>=33,"D","F"))))))))) | G26: =(IF(D26="","",IF(F26="F",0,IF(D26>=80,5,IF(D26>=70,4,IF(D26>=60,3.5,IF(D26>=50,3,IF(D26>=40,2,IF(D26>=33,1,0)))))))))
A27: ='Student Basic Info'!A27 -> 526 | C27: 57 | D27: =IF(B27+C27=0, "", B27+C27) -> 57 | E27: =IF(D27="","", IF(C27>=33,"Pass","Fail")) -> Pass | F27: =(IF(D27="","",IF(E27="Fail","F",IF(D27>=80,"A+",IF(D27>=70,"A",IF(D27>=60,"A-",IF(D27>=50,"B",IF(D27>=40,"C",IF(D27>=33,"D","F"))))))))) -> B | G27: =(IF(D27="","",IF(F27="F",0,IF(D27>=80,5,IF(D27>=70,4,IF(D27>=60,3.5,IF(D27>=50,3,IF(D27>=40,2,IF(D27>=33,1,0))))))))) -> 3
A28: ='Student Basic Info'!A28 -> 527 | D28: =IF(B28+C28=0, "", B28+C28) | E28: =IF(D28="","", IF(C28>=33,"Pass","Fail")) | F28: =(IF(D28="","",IF(E28="Fail","F",IF(D28>=80,"A+",IF(D28>=70,"A",IF(D28>=60,"A-",IF(D28>=50,"B",IF(D28>=40,"C",IF(D28>=33,"D","F"))))))))) | G28: =(IF(D28="","",IF(F28="F",0,IF(D28>=80,5,IF(D28>=70,4,IF(D28>=60,3.5,IF(D28>=50,3,IF(D28>=40,2,IF(D28>=33,1,0)))))))))
A29: ='Student Basic Info'!A29 -> 528 | C29: 60 | D29: =IF(B29+C29=0, "", B29+C29) -> 60 | E29: =IF(D29="","", IF(C29>=33,"Pass","Fail")) -> Pass | F29: =(IF(D29="","",IF(E29="Fail","F",IF(D29>=80,"A+",IF(D29>=70,"A",IF(D29>=60,"A-",IF(D29>=50,"B",IF(D29>=40,"C",IF(D29>=33,"D","F"))))))))) -> A- | G29: =(IF(D29="","",IF(F29="F",0,IF(D29>=80,5,IF(D29>=70,4,IF(D29>=60,3.5,IF(D29>=50,3,IF(D29>=40,2,IF(D29>=33,1,0))))))))) -> 3.5
A30: ='Student Basic Info'!A30 -> 529 | C30: 25 | D30: =IF(B30+C30=0, "", B30+C30) -> 25 | E30: =IF(D30="","", IF(C30>=33,"Pass","Fail")) -> Fail | F30: =(IF(D30="","",IF(E30="Fail","F",IF(D30>=80,"A+",IF(D30>=70,"A",IF(D30>=60,"A-",IF(D30>=50,"B",IF(D30>=40,"C",IF(D30>=33,"D","F"))))))))) -> F | G30: =(IF(D30="","",IF(F30="F",0,IF(D30>=80,5,IF(D30>=70,4,IF(D30>=60,3.5,IF(D30>=50,3,IF(D30>=40,2,IF(D30>=33,1,0))))))))) -> 0
A31: ='Student Basic Info'!A31 -> 530 | D31: =IF(B31+C31=0, "", B31+C31) | E31: =IF(D31="","", IF(C31>=33,"Pass","Fail")) | F31: =(IF(D31="","",IF(E31="Fail","F",IF(D31>=80,"A+",IF(D31>=70,"A",IF(D31>=60,"A-",IF(D31>=50,"B",IF(D31>=40,"C",IF(D31>=33,"D","F"))))))))) | G31: =(IF(D31="","",IF(F31="F",0,IF(D31>=80,5,IF(D31>=70,4,IF(D31>=60,3.5,IF(D31>=50,3,IF(D31>=40,2,IF(D31>=33,1,0)))))))))
A32: ='Student Basic Info'!A32 -> 531 | C32: 33 | D32: =IF(B32+C32=0, "", B32+C32) -> 33 | E32: =IF(D32="","", IF(C32>=33,"Pass","Fail")) -> Pass | F32: =(IF(D32="","",IF(E32="Fail","F",IF(D32>=80,"A+",IF(D32>=70,"A",IF(D32>=60,"A-",IF(D32>=50,"B",IF(D32>=40,"C",IF(D32>=33,"D","F"))))))))) -> D | G32: =(IF(D32="","",IF(F32="F",0,IF(D32>=80,5,IF(D32>=70,4,IF(D32>=60,3.5,IF(D32>=50,3,IF(D32>=40,2,IF(D32>=33,1,0))))))))) -> 1
A33: ='Student Basic Info'!A33 -> 532 | D33: =IF(B33+C33=0, "", B33+C33) | E33: =IF(D33="","", IF(C33>=33,"Pass","Fail")) | F33: =(IF(D33="","",IF(E33="Fail","F",IF(D33>=80,"A+",IF(D33>=70,"A",IF(D33>=60,"A-",IF(D33>=50,"B",IF(D33>=40,"C",IF(D33>=33,"D","F"))))))))) | G33: =(IF(D33="","",IF(F33="F",0,IF(D33>=80,5,IF(D33>=70,4,IF(D33>=60,3.5,IF(D33>=50,3,IF(D33>=40,2,IF(D33>=33,1,0)))))))))
A34: ='Student Basic Info'!A34 -> 533 | D34: =IF(B34+C34=0, "", B34+C34) | E34: =IF(D34="","", IF(C34>=33,"Pass","Fail")) | F34: =(IF(D34="","",IF(E34="Fail","F",IF(D34>=80,"A+",IF(D34>=70,"A",IF(D34>=60,"A-",IF(D34>=50,"B",IF(D34>=40,"C",IF(D34>=33,"D","F"))))))))) | G34: =(IF(D34="","",IF(F34="F",0,IF(D34>=80,5,IF(D34>=70,4,IF(D34>=60,3.5,IF(D34>=50,3,IF(D34>=40,2,IF(D34>=33,1,0)))))))))
A35: ='Student Basic Info'!A35 -> 534 | D35: =IF(B35+C35=0, "", B35+C35) | E35: =IF(D35="","", IF(C35>=33,"Pass","Fail")) | F35: =(IF(D35="","",IF(E35="Fail","F",IF(D35>=80,"A+",IF(D35>=70,"A",IF(D35>=60,"A-",IF(D35>=50,"B",IF(D35>=40,"C",IF(D35>=33,"D","F"))))))))) | G35: =(IF(D35="","",IF(F35="F",0,IF(D35>=80,5,IF(D35>=70,4,IF(D35>=60,3.5,IF(D35>=50,3,IF(D35>=40,2,IF(D35>=33,1,0)))))))))
A36: ='Student Basic Info'!A36 -> 535 | D36: =IF(B36+C36=0, "", B36+C36) | E36: =IF(D36="","", IF(C36>=33,"Pass","Fail")) | F36: =(IF(D36="","",IF(E36="Fail","F",IF(D36>=80,"A+",IF(D36>=70,"A",IF(D36>=60,"A-",IF(D36>=50,"B",IF(D36>=40,"C",IF(D36>=33,"D","F"))))))))) | G36: =(IF(D36="","",IF(F36="F",0,IF(D36>=80,5,IF(D36>=70,4,IF(D36>=60,3.5,IF(D36>=50,3,IF(D36>=40,2,IF(D36>=33,1,0)))))))))
A37: ='Student Basic Info'!A37 -> 536 | C37: 25 | D37: =IF(B37+C37=0, "", B37+C37) -> 25 | E37: =IF(D37="","", IF(C37>=33,"Pass","Fail")) -> Fail | F37: =(IF(D37="","",IF(E37="Fail","F",IF(D37>=80,"A+",IF(D37>=70,"A",IF(D37>=60,"A-",IF(D37>=50,"B",IF(D37>=40,"C",IF(D37>=33,"D","F"))))))))) -> F | G37: =(IF(D37="","",IF(F37="F",0,IF(D37>=80,5,IF(D37>=70,4,IF(D37>=60,3.5,IF(D37>=50,3,IF(D37>=40,2,IF(D37>=33,1,0))))))))) -> 0
A38: ='Student Basic Info'!A38 -> 537 | C38: 22 | D38: =IF(B38+C38=0, "", B38+C38) -> 22 | E38: =IF(D38="","", IF(C38>=33,"Pass","Fail")) -> Fail | F38: =(IF(D38="","",IF(E38="Fail","F",IF(D38>=80,"A+",IF(D38>=70,"A",IF(D38>=60,"A-",IF(D38>=50,"B",IF(D38>=40,"C",IF(D38>=33,"D","F"))))))))) -> F | G38: =(IF(D38="","",IF(F38="F",0,IF(D38>=80,5,IF(D38>=70,4,IF(D38>=60,3.5,IF(D38>=50,3,IF(D38>=40,2,IF(D38>=33,1,0))))))))) -> 0
A39: ='Student Basic Info'!A39 -> 538 | C39: 33 | D39: =IF(B39+C39=0, "", B39+C39) -> 33 | E39: =IF(D39="","", IF(C39>=33,"Pass","Fail")) -> Pass | F39: =(IF(D39="","",IF(E39="Fail","F",IF(D39>=80,"A+",IF(D39>=70,"A",IF(D39>=60,"A-",IF(D39>=50,"B",IF(D39>=40,"C",IF(D39>=33,"D","F"))))))))) -> D | G39: =(IF(D39="","",IF(F39="F",0,IF(D39>=80,5,IF(D39>=70,4,IF(D39>=60,3.5,IF(D39>=50,3,IF(D39>=40,2,IF(D39>=33,1,0))))))))) -> 1
A40: ='Student Basic Info'!A40 -> 539 | C40: 21 | D40: =IF(B40+C40=0, "", B40+C40) -> 21 | E40: =IF(D40="","", IF(C40>=33,"Pass","Fail")) -> Fail | F40: =(IF(D40="","",IF(E40="Fail","F",IF(D40>=80,"A+",IF(D40>=70,"A",IF(D40>=60,"A-",IF(D40>=50,"B",IF(D40>=40,"C",IF(D40>=33,"D","F"))))))))) -> F | G40: =(IF(D40="","",IF(F40="F",0,IF(D40>=80,5,IF(D40>=70,4,IF(D40>=60,3.5,IF(D40>=50,3,IF(D40>=40,2,IF(D40>=33,1,0))))))))) -> 0
...

Sheet English
A1: Roll | B1: Marks CQ | C1: Total Marks | D1: Result | E1: Grade | F1: GPA
A2: ='Student Basic Info'!A2 -> 501 | C2: =IF(B2=0, "",B2) | D2: =IF(C2="","", IF(C2>=33,"Pass","Fail")) | E2: =(IF(C2="","",IF(D2="Fail","F",IF(C2>=80,"A+",IF(C2>=70,"A",IF(C2>=60,"A-",IF(C2>=50,"B",IF(C2>=40,"C",IF(C2>=33,"D","F"))))))))) | F2: =(IF(C2="","",IF(E2="F",0,IF(C2>=80,5,IF(C2>=70,4,IF(C2>=60,3.5,IF(C2>=50,3,IF(C2>=40,2,IF(C2>=33,1,0)))))))))
A3: ='Student Basic Info'!A3 -> 502 | C3: =IF(B3=0, "",B3) | D3: =IF(C3="","", IF(C3>=33,"Pass","Fail")) | E3: =(IF(C3="","",IF(D3="Fail","F",IF(C3>=80,"A+",IF(C3>=70,"A",IF(C3>=60,"A-",IF(C3>=50,"B",IF(C3>=40,"C",IF(C3>=33,"D","F"))))))))) | F3: =(IF(C3="","",IF(E3="F",0,IF(C3>=80,5,IF(C3>=70,4,IF(C3>=60,3.5,IF(C3>=50,3,IF(C3>=40,2,IF(C3>=33,1,0)))))))))
A4: ='Student Basic Info'!A4 -> 503 | B4: 33 | C4: =IF(B4=0, "",B4) -> 33 | D4: =IF(C4="","", IF(C4>=33,"Pass","Fail")) -> Pass | E4: =(IF(C4="","",IF(D4="Fail","F",IF(C4>=80,"A+",IF(C4>=70,"A",IF(C4>=60,"A-",IF(C4>=50,"B",IF(C4>=40,"C",IF(C4>=33,"D","F"))))))))) -> D | F4: =(IF(C4="","",IF(E4="F",0,IF(C4>=80,5,IF(C4>=70,4,IF(C4>=60,3.5,IF(C4>=50,3,IF(C4>=40,2,IF(C4>=33,1,0))))))))) -> 1
A5: ='Student Basic Info'!A5 -> 504 | B5: 21 | C5: =IF(B5=0, "",B5) -> 21 | D5: =IF(C5="","", IF(C5>=33,"Pass","Fail")) -> Fail | E5: =(IF(C5="","",IF(D5="Fail","F",IF(C5>=80,"A+",IF(C5>=70,"A",IF(C5>=60,"A-",IF(C5>=50,"B",IF(C5>=40,"C",IF(C5>=33,"D","F"))))))))) -> F | F5: =(IF(C5="","",IF(E5="F",0,IF(C5>=80,5,IF(C5>=70,4,IF(C5>=60,3.5,IF(C5>=50,3,IF(C5>=40,2,IF(C5>=33,1,0))))))))) -> 0
A6: ='Student Basic Info'!A6 -> 505 | C6: =IF(B6=0, "",B6) | D6: =IF(C6="","", IF(C6>=33,"Pass","Fail")) | E6: =(IF(C6="","",IF(D6="Fail","F",IF(C6>=80,"A+",IF(C6>=70,"A",IF(C6>=60,"A-",IF(C6>=50,"B",IF(C6>=40,"C",IF(C6>=33,"D","F"))))))))) | F6: =(IF(C6="","",IF(E6="F",0,IF(C6>=80,5,IF(C6>=70,4,IF(C6>=60,3.5,IF(C6>=50,3,IF(C6>=40,2,IF(C6>=33,1,0)))))))))
A7: ='Student Basic Info'!A7 -> 506 | C7: =IF(B7=0, "",B7) | D7: =IF(C7="","", IF(C7>=33,"Pass","Fail")) | E7: =(IF(C7="","",IF(D7="Fail","F",IF(C7>=80,"A+",IF(C7>=70,"A",IF(C7>=60,"A-",IF(C7>=50,"B",IF(C7>=40,"C",IF(C7>=33,"D","F"))))))))) | F7: =(IF(C7="","",IF(E7="F",0,IF(C7>=80,5,IF(C7>=70,4,IF(C7>=60,3.5,IF(C7>=50,3,IF(C7>=40,2,IF(C7>=33,1,0)))))))))
A8: ='Student Basic Info'!A8 -> 507 | B8: 44 | C8: =IF(B8=0, "",B8) -> 44 | D8: =IF(C8="","", IF(C8>=33,"Pass","Fail")) -> Pass | E8: =(IF(C8="","",IF(D8="Fail","F",IF(C8>=80,"A+",IF(C8>=70,"A",IF(C8>=60,"A-",IF(C8>=50,"B",IF(C8>=40,"C",IF(C8>=33,"D","F"))))))))) -> C | F8: =(IF(C8="","",IF(E8="F",0,IF(C8>=80,5,IF(C8>=70,4,IF(C8>=60,3.5,IF(C8>=50,3,IF(C8>=40,2,IF(C8>=33,1,0))))))))) -> 2
A9: ='Student Basic Info'!A9 -> 508 | B9: 33 | C9: =IF(B9=0, "",B9) -> 33 | D9: =IF(C9="","", IF(C9>=33,"Pass","Fail")) -> Pass | E9: =(IF(C9="","",IF(D9="Fail","F",IF(C9>=80,"A+",IF(C9>=70,"A",IF(C9>=60,"A-",IF(C9>=50,"B",IF(C9>=40,"C",IF(C9>=33,"D","F"))))))))) -> D | F9: =(IF(C9="","",IF(E9="F",0,IF(C9>=80,5,IF(C9>=70,4,IF(C9>=60,3.5,IF(C9>=50,3,IF(C9>=40,2,IF(C9>=33,1,0))))))))) -> 1
A10: ='Student Basic Info'!A10 -> 509 | B10: 21 | C10: =IF(B10=0, "",B10) -> 21 | D10: =IF(C10="","", IF(C10>=33,"Pass","Fail")) -> Fail | E10: =(IF(C10="","",IF(D10="Fail","F",IF(C10>=80,"A+",IF(C10>=70,"A",IF(C10>=60,"A-",IF(C10>=50,"B",IF(C10>=40,"C",IF(C10>=33,"D","F"))))))))) -> F | F10: =(IF(C10="","",IF(E10="F",0,IF(C10>=80,5,IF(C10>=70,4,IF(C10>=60,3.5,IF(C10>=50,3,IF(C10>=40,2,IF(C10>=33,1,0))))))))) -> 0
A11: ='Student Basic Info'!A11 -> 510 | C11: =IF(B11=0, "",B11) | D11: =IF(C11="","", IF(C11>=33,"Pass","Fail")) | E11: =(IF(C11="","",IF(D11="Fail","F",IF(C11>=80,"A+",IF(C11>=70,"A",IF(C11>=60,"A-",IF(C11>=50,"B",IF(C11>=40,"C",IF(C11>=33,"D","F"))))))))) | F11: =(IF(C11="","",IF(E11="F",0,IF(C11>=80,5,IF(C11>=70,4,IF(C11>=60,3.5,IF(C11>=50,3,IF(C11>=40,2,IF(C11>=33,1,0)))))))))
A12: ='Student Basic Info'!A12 -> 511 | B12: 26 | C12: =IF(B12=0, "",B12) -> 26 | D12: =IF(C12="","", IF(C12>=33,"Pass","Fail")) -> Fail | E12: =(IF(C12="","",IF(D12="Fail","F",IF(C12>=80,"A+",IF(C12>=70,"A",IF(C12>=60,"A-",IF(C12>=50,"B",IF(C12>=40,"C",IF(C12>=33,"D","F"))))))))) -> F | F12: =(IF(C12="","",IF(E12="F",0,IF(C12>=80,5,IF(C12>=70,4,IF(C12>=60,3.5,IF(C12>=50,3,IF(C12>=40,2,IF(C12>=33,1,0))))))))) -> 0
A13: ='Student Basic Info'!A13 -> 512 | B13: 11 | C13: =IF(B13=0, "",B13) -> 11 | D13: =IF(C13="","", IF(C13>=33,"Pass","Fail")) -> Fail | E13: =(IF(C13="","",IF(D13="Fail","F",IF(C13>=80,"A+",IF(C13>=70,"A",IF(C13>=60,"A-",IF(C13>=50,"B",IF(C13>=40,"C",IF(C13>=33,"D","F"))))))))) -> F | F13: =(IF(C13="","",IF(E13="F",0,IF(C13>=80,5,IF(C13>=70,4,IF(C13>=60,3.5,IF(C13>=50,3,IF(C13>=40,2,IF(C13>=33,1,0))))))))) -> 0
A14: ='Student Basic Info'!A14 -> 513 | B14: 29 | C14: =IF(B14=0, "",B14) -> 29 | D14: =IF(C14="","", IF(C14>=33,"Pass","Fail")) -> Fail | E14: =(IF(C14="","",IF(D14="Fail","F",IF(C14>=80,"A+",IF(C14>=70,"A",IF(C14>=60,"A-",IF(C14>=50,"B",IF(C14>=40,"C",IF(C14>=33,"D","F"))))))))) -> F | F14: =(IF(C14="","",IF(E14="F",0,IF(C14>=80,5,IF(C14>=70,4,IF(C14>=60,3.5,IF(C14>=50,3,IF(C14>=40,2,IF(C14>=33,1,0))))))))) -> 0
A15: ='Student Basic Info'!A15 -> 514 | C15: =IF(B15=0, "",B15) | D15: =IF(C15="","", IF(C15>=33,"Pass","Fail")) | E15: =(IF(C15="","",IF(D15="Fail","F",IF(C15>=80,"A+",IF(C15>=70,"A",IF(C15>=60,"A-",IF(C15>=50,"B",IF(C15>=40,"C",IF(C15>=33,"D","F"))))))))) | F15: =(IF(C15="","",IF(E15="F",0,IF(C15>=80,5,IF(C15>=70,4,IF(C15>=60,3.5,IF(C15>=50,3,IF(C15>=40,2,IF(C15>=33,1,0)))))))))
A16: ='Student Basic Info'!A16 -> 515 | B16: 38 | C16: =IF(B16=0, "",B16) -> 38 | D16: =IF(C16="","", IF(C16>=33,"Pass","Fail")) -> Pass | E16: =(IF(C16="","",IF(D16="Fail","F",IF(C16>=80,"A+",IF(C16>=70,"A",IF(C16>=60,"A-",IF(C16>=50,"B",IF(C16>=40,"C",IF(C16>=33,"D","F"))))))))) -> D | F16: =(IF(C16="","",IF(E16="F",0,IF(C16>=80,5,IF(C16>=70,4,IF(C16>=60,3.5,IF(C16>=50,3,IF(C16>=40,2,IF(C16>=33,1,0))))))))) -> 1
A17: ='Student Basic Info'!A17 -> 516 | B17: 48 | C17: =IF(B17=0, "",B17) -> 48 | D17: =IF(C17="","", IF(C17>=33,"Pass","Fail")) -> Pass | E17: =(IF(C17="","",IF(D17="Fail","F",IF(C17>=80,"A+",IF(C17>=70,"A",IF(C17>=60,"A-",IF(C17>=50,"B",IF(C17>=40,"C",IF(C17>=33,"D","F"))))))))) -> C | F17: =(IF(C17="","",IF(E17="F",0,IF(C17>=80,5,IF(C17>=70,4,IF(C17>=60,3.5,IF(C17>=50,3,IF(C17>=40,2,IF(C17>=33,1,0))))))))) -> 2
A18: ='Student Basic Info'!A18 -> 517 | C18: =IF(B18=0, "",B18) | D18: =IF(C18="","", IF(C18>=33,"Pass","Fail")) | E18: =(IF(C18="","",IF(D18="Fail","F",IF(C18>=80,"A+",IF(C18>=70,"A",IF(C18>=60,"A-",IF(C18>=50,"B",IF(C18>=40,"C",IF(C18>=33,"D","F"))))))))) | F18: =(IF(C18="","",IF(E18="F",0,IF(C18>=80,5,IF(C18>=70,4,IF(C18>=60,3.5,IF(C18>=50,3,IF(C18>=40,2,IF(C18>=33,1,0)))))))))
A19: ='Student Basic Info'!A19 -> 518 | C19: =IF(B19=0, "",B19) | D19: =IF(C19="","", IF(C19>=33,"Pass","Fail")) | E19: =(IF(C19="","",IF(D19="Fail","F",IF(C19>=80,"A+",IF(C19>=70,"A",IF(C19>=60,"A-",IF(C19>=50,"B",IF(C19>=40,"C",IF(C19>=33,"D","F"))))))))) | F19: =(IF(C19="","",IF(E19="F",0,IF(C19>=80,5,IF(C19>=70,4,IF(C19>=60,3.5,IF(C19>=50,3,IF(C19>=40,2,IF(C19>=33,1,0)))))))))
A20: ='Student Basic Info'!A20 -> 519 | B20: 37 | C20: =IF(B20=0, "",B20) -> 37 | D20: =IF(C20="","", IF(C20>=33,"Pass","Fail")) -> Pass | E20: =(IF(C20="","",IF(D20="Fail","F",IF(C20>=80,"A+",IF(C20>=70,"A",IF(C20>=60,"A-",IF(C20>=50,"B",IF(C20>=40,"C",IF(C20>=33,"D","F"))))))))) -> D | F20: =(IF(C20="","",IF(E20="F",0,IF(C20>=80,5,IF(C20>=70,4,IF(C20>=60,3.5,IF(C20>=50,3,IF(C20>=40,2,IF(C20>=33,1,0))))))))) -> 1
A21: ='Student Basic Info'!A21 -> 520 | B21: 16 | C21: =IF(B21=0, "",B21) -> 16 | D21: =IF(C21="","", IF(C21>=33,"Pass","Fail")) -> Fail | E21: =(IF(C21="","",IF(D21="Fail","F",IF(C21>=80,"A+",IF(C21>=70,"A",IF(C21>=60,"A-",IF(C21>=50,"B",IF(C21>=40,"C",IF(C21>=33,"D","F"))))))))) -> F | F21: =(IF(C21="","",IF(E21="F",0,IF(C21>=80,5,IF(C21>=70,4,IF(C21>=60,3.5,IF(C21>=50,3,IF(C21>=40,2,IF(C21>=33,1,0))))))))) -> 0
A22: ='Student Basic Info'!A22 -> 521 | C22: =IF(B22=0, "",B22) | D22: =IF(C22="","", IF(C22>=33,"Pass","Fail")) | E22: =(IF(C22="","",IF(D22="Fail","F",IF(C22>=80,"A+",IF(C22>=70,"A",IF(C22>=60,"A-",IF(C22>=50,"B",IF(C22>=40,"C",IF(C22>=33,"D","F"))))))))) | F22: =(IF(C22="","",IF(E22="F",0,IF(C22>=80,5,IF(C22>=70,4,IF(C22>=60,3.5,IF(C22>=50,3,IF(C22>=40,2,IF(C22>=33,1,0)))))))))
A23: ='Student Basic Info'!A23 -> 522 | B23: 54 | C23: =IF(B23=0, "",B23) -> 54 | D23: =IF(C23="","", IF(C23>=33,"Pass","Fail")) -> Pass | E23: =(IF(C23="","",IF(D23="Fail","F",IF(C23>=80,"A+",IF(C23>=70,"A",IF(C23>=60,"A-",IF(C23>=50,"B",IF(C23>=40,"C",IF(C23>=33,"D","F"))))))))) -> B | F23: =(IF(C23="","",IF(E23="F",0,IF(C23>=80,5,IF(C23>=70,4,IF(C23>=60,3.5,IF(C23>=50,3,IF(C23>=40,2,IF(C23>=33,1,0))))))))) -> 3
A24: ='Student Basic Info'!A24 -> 523 | B24: 39 | C24: =IF(B24=0, "",B24) -> 39 | D24: =IF(C24="","", IF(C24>=33,"Pass","Fail")) -> Pass | E24: =(IF(C24="","",IF(D24="Fail","F",IF(C24>=80,"A+",IF(C24>=70,"A",IF(C24>=60,"A-",IF(C24>=50,"B",IF(C24>=40,"C",IF(C24>=33,"D","F"))))))))) -> D | F24: =(IF(C24="","",IF(E24="F",0,IF(C24>=80,5,IF(C24>=70,4,IF(C24>=60,3.5,IF(C24>=50,3,IF(C24>=40,2,IF(C24>=33,1,0))))))))) -> 1
A25: ='Student Basic Info'!A25 -> 524 | B25: 38 | C25: =IF(B25=0, "",B25) -> 38 | D25: =IF(C25="","", IF(C25>=33,"Pass","Fail")) -> Pass | E25: =(IF(C25="","",IF(D25="Fail","F",IF(C25>=80,"A+",IF(C25>=70,"A",IF(C25>=60,"A-",IF(C25>=50,"B",IF(C25>=40,"C",IF(C25>=33,"D","F"))))))))) -> D | F25: =(IF(C25="","",IF(E25="F",0,IF(C25>=80,5,IF(C25>=70,4,IF(C25>=60,3.5,IF(C25>=50,3,IF(C25>=40,2,IF(C25>=33,1,0))))))))) -> 1
A26: ='Student Basic Info'!A26 -> 525 | C26: =IF(B26=0, "",B26) | D26: =IF(C26="","", IF(C26>=33,"Pass","Fail")) | E26: =(IF(C26="","",IF(D26="Fail","F",IF(C26>=80,"A+",IF(C26>=70,"A",IF(C26>=60,"A-",IF(C26>=50,"B",IF(C26>=40,"C",IF(C26>=33,"D","F"))))))))) | F26: =(IF(C26="","",IF(E26="F",0,IF(C26>=80,5,IF(C26>=70,4,IF(C26>=60,3.5,IF(C26>=50,3,IF(C26>=40,2,IF(C26>=33,1,0)))))))))
A27: ='Student Basic Info'!A27 -> 526 | B27: 34 | C27: =IF(B27=0, "",B27) -> 34 | D27: =IF(C27="","", IF(C27>=33,"Pass","Fail")) -> Pass | E27: =(IF(C27="","",IF(D27="Fail","F",IF(C27>=80,"A+",IF(C27>=70,"A",IF(C27>=60,"A-",IF(C27>=50,"B",IF(C27>=40,"C",IF(C27>=33,"D","F"))))))))) -> D | F27: =(IF(C27="","",IF(E27="F",0,IF(C27>=80,5,IF(C27>=70,4,IF(C27>=60,3.5,IF(C27>=50,3,IF(C27>=40,2,IF(C27>=33,1,0))))))))) -> 1
A28: ='Student Basic Info'!A28 -> 527 | C28: =IF(B28=0, "",B28) | D28: =IF(C28="","", IF(C28>=33,"Pass","Fail")) | E28: =(IF(C28="","",IF(D28="Fail","F",IF(C28>=80,"A+",IF(C28>=70,"A",IF(C28>=60,"A-",IF(C28>=50,"B",IF(C28>=40,"C",IF(C28>=33,"D","F"))))))))) | F28: =(IF(C28="","",IF(E28="F",0,IF(C28>=80,5,IF(C28>=70,4,IF(C28>=60,3.5,IF(C28>=50,3,IF(C28>=40,2,IF(C28>=33,1,0)))))))))
A29: ='Student Basic Info'!A29 -> 528 | B29: 42 | C29: =IF(B29=0, "",B29) -> 42 | D29: =IF(C29="","", IF(C29>=33,"Pass","Fail")) -> Pass | E29: =(IF(C29="","",IF(D29="Fail","F",IF(C29>=80,"A+",IF(C29>=70,"A",IF(C29>=60,"A-",IF(C29>=50,"B",IF(C29>=40,"C",IF(C29>=33,"D","F"))))))))) -> C | F29: =(IF(C29="","",IF(E29="F",0,IF(C29>=80,5,IF(C29>=70,4,IF(C29>=60,3.5,IF(C29>=50,3,IF(C29>=40,2,IF(C29>=33,1,0))))))))) -> 2
A30: ='Student Basic Info'!A30 -> 529 | B30: 14 | C30: =IF(B30=0, "",B30) -> 14 | D30: =IF(C30="","", IF(C30>=33,"Pass","Fail")) -> Fail | E30: =(IF(C30="","",IF(D30="Fail","F",IF(C30>=80,"A+",IF(C30>=70,"A",IF(C30>=60,"A-",IF(C30>=50,"B",IF(C30>=40,"C",IF(C30>=33,"D","F"))))))))) -> F | F30: =(IF(C30="","",IF(E30="F",0,IF(C30>=80,5,IF(C30>=70,4,IF(C30>=60,3.5,IF(C30>=50,3,IF(C30>=40,2,IF(C30>=33,1,0))))))))) -> 0
A31: ='Student Basic Info'!A31 -> 530 | C31: =IF(B31=0, "",B31) | D31: =IF(C31="","", IF(C31>=33,"Pass","Fail")) | E31: =(IF(C31="","",IF(D31="Fail","F",IF(C31>=80,"A+",IF(C31>=70,"A",IF(C31>=60,"A-",IF(C31>=50,"B",IF(C31>=40,"C",IF(C31>=33,"D","F"))))))))) | F31: =(IF(C31="","",IF(E31="F",0,IF(C31>=80,5,IF(C31>=70,4,IF(C31>=60,3.5,IF(C31>=50,3,IF(C31>=40,2,IF(C31>=33,1,0)))))))))
A32: ='Student Basic Info'!A32 -> 531 | B32: 17 | C32: =IF(B32=0, "",B32) -> 17 | D32: =IF(C32="","", IF(C32>=33,"Pass","Fail")) -> Fail | E32: =(IF(C32="","",IF(D32="Fail","F",IF(C32>=80,"A+",IF(C32>=70,"A",IF(C32>=60,"A-",IF(C32>=50,"B",IF(C32>=40,"C",IF(C32>=33,"D","F"))))))))) -> F | F32: =(IF(C32="","",IF(E32="F",0,IF(C32>=80,5,IF(C32>=70,4,IF(C32>=60,3.5,IF(C32>=50,3,IF(C32>=40,2,IF(C32>=33,1,0))))))))) -> 0
A33: ='Student Basic Info'!A33 -> 532 | C33: =IF(B33=0, "",B33) | D33: =IF(C33="","", IF(C33>=33,"Pass","Fail")) | E33: =(IF(C33="","",IF(D33="Fail","F",IF(C33>=80,"A+",IF(C33>=70,"A",IF(C33>=60,"A-",IF(C33>=50,"B",IF(C33>=40,"C",IF(C33>=33,"D","F"))))))))) | F33: =(IF(C33="","",IF(E33="F",0,IF(C33>=80,5,IF(C33>=70,4,IF(C33>=60,3.5,IF(C33>=50,3,IF(C33>=40,2,IF(C33>=33,1,0)))))))))
A34: ='Student Basic Info'!A34 -> 533 | C34: =IF(B34=0, "",B34) | D34: =IF(C34="","", IF(C34>=33,"Pass","Fail")) | E34: =(IF(C34="","",IF(D34="Fail","F",IF(C34>=80,"A+",IF(C34>=70,"A",IF(C34>=60,"A-",IF(C34>=50,"B",IF(C34>=40,"C",IF(C34>=33,"D","F"))))))))) | F34: =(IF(C34="","",IF(E34="F",0,IF(C34>=80,5,IF(C34>=70,4,IF(C34>=60,3.5,IF(C34>=50,3,IF(C34>=40,2,IF(C34>=33,1,0)))))))))
A35: ='Student Basic Info'!A35 -> 534 | C35: =IF(B35=0, "",B35) | D35: =IF(C35="","", IF(C35>=33,"Pass","Fail")) | E35: =(IF(C35="","",IF(D35="Fail","F",IF(C35>=80,"A+",IF(C35>=70,"A",IF(C35>=60,"A-",IF(C35>=50,"B",IF(C35>=40,"C",IF(C35>=33,"D","F"))))))))) | F35: =(IF(C35="","",IF(E35="F",0,IF(C35>=80,5,IF(C35>=70,4,IF(C35>=60,3.5,IF(C35>=50,3,IF(C35>=40,2,IF(C35>=33,1,0)))))))))
A36: ='Student Basic Info'!A36 -> 535 | C36: =IF(B36=0, "",B36) | D36: =IF(C36="","", IF(C36>=33,"Pass","Fail")) | E36: =(IF(C36="","",IF(D36="Fail","F",IF(C36>=80,"A+",IF(C36>=70,"A",IF(C36>=60,"A-",IF(C36>=50,"B",IF(C36>=40,"C",IF(C36>=33,"D","F"))))))))) | F36: =(IF(C36="","",IF(E36="F",0,IF(C36>=80,5,IF(C36>=70,4,IF(C36>=60,3.5,IF(C36>=50,3,IF(C36>=40,2,IF(C36>=33,1,0)))))))))
A37: ='Student Basic Info'!A37 -> 536 | B37: 24 | C37: =IF(B37=0, "",B37) -> 24 | D37: =IF(C37="","", IF(C37>=33,"Pass","Fail")) -> Fail | E37: =(IF(C37="","",IF(D37="Fail","F",IF(C37>=80,"A+",IF(C37>=70,"A",IF(C37>=60,"A-",IF(C37>=50,"B",IF(C37>=40,"C",IF(C37>=33,"D","F"))))))))) -> F | F37: =(IF(C37="","",IF(E37="F",0,IF(C37>=80,5,IF(C37>=70,4,IF(C37>=60,3.5,IF(C37>=50,3,IF(C37>=40,2,IF(C37>=33,1,0))))))))) -> 0
A38: ='Student Basic Info'!A38 -> 537 | B38: 21 | C38: =IF(B38=0, "",B38) -> 21 | D38: =IF(C38="","", IF(C38>=33,"Pass","Fail")) -> Fail | E38: =(IF(C38="","",IF(D38="Fail","F",IF(C38>=80,"A+",IF(C38>=70,"A",IF(C38>=60,"A-",IF(C38>=50,"B",IF(C38>=40,"C",IF(C38>=33,"D","F"))))))))) -> F | F38: =(IF(C38="","",IF(E38="F",0,IF(C38>=80,5,IF(C38>=70,4,IF(C38>=60,3.5,IF(C38>=50,3,IF(C38>=40,2,IF(C38>=33,1,0))))))))) -> 0
A39: ='Student Basic Info'!A39 -> 538 | B39: 10 | C39: =IF(B39=0, "",B39) -> 10 | D39: =IF(C39="","", IF(C39>=33,"Pass","Fail")) -> Fail | E39: =(IF(C39="","",IF(D39="Fail","F",IF(C39>=80,"A+",IF(C39>=70,"A",IF(C39>=60,"A-",IF(C39>=50,"B",IF(C39>=40,"C",IF(C39>=33,"D","F"))))))))) -> F | F39: =(IF(C39="","",IF(E39="F",0,IF(C39>=80,5,IF(C39>=70,4,IF(C39>=60,3.5,IF(C39>=50,3,IF(C39>=40,2,IF(C39>=33,1,0))))))))) -> 0
A40: ='Student Basic Info'!A40 -> 539 | B40: 15 | C40: =IF(B40=0, "",B40) -> 15 | D40: =IF(C40="","", IF(C40>=33,"Pass","Fail")) -> Fail | E40: =(IF(C40="","",IF(D40="Fail","F",IF(C40>=80,"A+",IF(C40>=70,"A",IF(C40>=60,"A-",IF(C40>=50,"B",IF(C40>=40,"C",IF(C40>=33,"D","F"))))))))) -> F | F40: =(IF(C40="","",IF(E40="F",0,IF(C40>=80,5,IF(C40>=70,4,IF(C40>=60,3.5,IF(C40>=50,3,IF(C40>=40,2,IF(C40>=33,1,0))))))))) -> 0
...

Sheet ICT
A1: Roll | B1: Marks MCQ | C1: Marks CQ | D1: Practical | E1: Total Marks | F1: Result | G1: Grade | H1: GPA
A2: ='Student Basic Info'!A2 -> 501 | E2: =IF(B2+C2+D2=0, "", B2+C2+D2) | F2: =IF(E2="","", IF(AND(B2 >=8,C2>=17,D2>=8),"Pass","Fail")) | G2: =(IF(E2="","",IF(F2="Fail","F",IF(E2>=80,"A+",IF(E2>=70,"A",IF(E2>=60,"A-",IF(E2>=50,"B",IF(E2>=40,"C",IF(E2>=33,"D","F"))))))))) | H2: =(IF(E2="","",IF(G2="F",0,IF(E2>=80,5,IF(E2>=70,4,IF(E2>=60,3.5,IF(E2>=50,3,IF(E2>=40,2,IF(E2>=33,1,0)))))))))
A3: ='Student Basic Info'!A3 -> 502 | E3: =IF(B3+C3+D3=0, "", B3+C3+D3) | F3: =IF(E3="","", IF(AND(B3 >=8,C3>=17,D3>=8),"Pass","Fail")) | G3: =(IF(E3="","",IF(F3="Fail","F",IF(E3>=80,"A+",IF(E3>=70,"A",IF(E3>=60,"A-",IF(E3>=50,"B",IF(E3>=40,"C",IF(E3>=33,"D","F"))))))))) | H3: =(IF(E3="","",IF(G3="F",0,IF(E3>=80,5,IF(E3>=70,4,IF(E3>=60,3.5,IF(E3>=50,3,IF(E3>=40,2,IF(E3>=33,1,0)))))))))
A4: ='Student Basic Info'!A4 -> 503 | B4: 8 | C4: 18 | D4: 20 | E4: =IF(B4+C4+D4=0, "", B4+C4+D4) -> 46 | F4: =IF(E4="","", IF(AND(B4 >=8,C4>=17,D4>=8),"Pass","Fail")) -> Pass | G4: =(IF(E4="","",IF(F4="Fail","F",IF(E4>=80,"A+",IF(E4>=70,"A",IF(E4>=60,"A-",IF(E4>=50,"B",IF(E4>=40,"C",IF(E4>=33,"D","F"))))))))) -> C | H4: =(IF(E4="","",IF(G4="F",0,IF(E4>=80,5,IF(E4>=70,4,IF(E4>=60,3.5,IF(E4>=50,3,IF(E4>=40,2,IF(E4>=33,1,0))))))))) -> 2
A5: ='Student Basic Info'!A5 -> 504 | B5: 7 | C5: 17 | D5: 20 | E5: =IF(B5+C5+D5=0, "", B5+C5+D5) -> 44 | F5: =IF(E5="","", IF(AND(B5 >=8,C5>=17,D5>=8),"Pass","Fail")) -> Fail | G5: =(IF(E5="","",IF(F5="Fail","F",IF(E5>=80,"A+",IF(E5>=70,"A",IF(E5>=60,"A-",IF(E5>=50,"B",IF(E5>=40,"C",IF(E5>=33,"D","F"))))))))) -> F | H5: =(IF(E5="","",IF(G5="F",0,IF(E5>=80,5,IF(E5>=70,4,IF(E5>=60,3.5,IF(E5>=50,3,IF(E5>=40,2,IF(E5>=33,1,0))))))))) -> 0
A6: ='Student Basic Info'!A6 -> 505 | E6: =IF(B6+C6+D6=0, "", B6+C6+D6) | F6: =IF(E6="","", IF(AND(B6 >=8,C6>=17,D6>=8),"Pass","Fail")) | G6: =(IF(E6="","",IF(F6="Fail","F",IF(E6>=80,"A+",IF(E6>=70,"A",IF(E6>=60,"A-",IF(E6>=50,"B",IF(E6>=40,"C",IF(E6>=33,"D","F"))))))))) | H6: =(IF(E6="","",IF(G6="F",0,IF(E6>=80,5,IF(E6>=70,4,IF(E6>=60,3.5,IF(E6>=50,3,IF(E6>=40,2,IF(E6>=33,1,0)))))))))
A7: ='Student Basic Info'!A7 -> 506 | E7: =IF(B7+C7+D7=0, "", B7+C7+D7) | F7: =IF(E7="","", IF(AND(B7 >=8,C7>=17,D7>=8),"Pass","Fail")) | G7: =(IF(E7="","",IF(F7="Fail","F",IF(E7>=80,"A+",IF(E7>=70,"A",IF(E7>=60,"A-",IF(E7>=50,"B",IF(E7>=40,"C",IF(E7>=33,"D","F"))))))))) | H7: =(IF(E7="","",IF(G7="F",0,IF(E7>=80,5,IF(E7>=70,4,IF(E7>=60,3.5,IF(E7>=50,3,IF(E7>=40,2,IF(E7>=33,1,0)))))))))
A8: ='Student Basic Info'!A8 -> 507 | B8: 16 | C8: 30 | D8: 24 | E8: =IF(B8+C8+D8=0, "", B8+C8+D8) -> 70 | F8: =IF(E8="","", IF(AND(B8 >=8,C8>=17,D8>=8),"Pass","Fail")) -> Pass | G8: =(IF(E8="","",IF(F8="Fail","F",IF(E8>=80,"A+",IF(E8>=70,"A",IF(E8>=60,"A-",IF(E8>=50,"B",IF(E8>=40,"C",IF(E8>=33,"D","F"))))))))) -> A | H8: =(IF(E8="","",IF(G8="F",0,IF(E8>=80,5,IF(E8>=70,4,IF(E8>=60,3.5,IF(E8>=50,3,IF(E8>=40,2,IF(E8>=33,1,0))))))))) -> 4
A9: ='Student Basic Info'!A9 -> 508 | B9: 11 | C9: 19 | D9: 20 | E9: =IF(B9+C9+D9=0, "", B9+C9+D9) -> 50 | F9: =IF(E9="","", IF(AND(B9 >=8,C9>=17,D9>=8),"Pass","Fail")) -> Pass | G9: =(IF(E9="","",IF(F9="Fail","F",IF(E9>=80,"A+",IF(E9>=70,"A",IF(E9>=60,"A-",IF(E9>=50,"B",IF(E9>=40,"C",IF(E9>=33,"D","F"))))))))) -> B | H9: =(IF(E9="","",IF(G9="F",0,IF(E9>=80,5,IF(E9>=70,4,IF(E9>=60,3.5,IF(E9>=50,3,IF(E9>=40,2,IF(E9>=33,1,0))))))))) -> 3
A10: ='Student Basic Info'!A10 -> 509 | B10: 12 | C10: 16 | D10: 22 | E10: =IF(B10+C10+D10=0, "", B10+C10+D10) -> 50 | F10: =IF(E10="","", IF(AND(B10 >=8,C10>=17,D10>=8),"Pass","Fail")) -> Fail | G10: =(IF(E10="","",IF(F10="Fail","F",IF(E10>=80,"A+",IF(E10>=70,"A",IF(E10>=60,"A-",IF(E10>=50,"B",IF(E10>=40,"C",IF(E10>=33,"D","F"))))))))) -> F | H10: =(IF(E10="","",IF(G10="F",0,IF(E10>=80,5,IF(E10>=70,4,IF(E10>=60,3.5,IF(E10>=50,3,IF(E10>=40,2,IF(E10>=33,1,0))))))))) -> 0
A11: ='Student Basic Info'!A11 -> 510 | E11: =IF(B11+C11+D11=0, "", B11+C11+D11) | F11: =IF(E11="","", IF(AND(B11 >=8,C11>=17,D11>=8),"Pass","Fail")) | G11: =(IF(E11="","",IF(F11="Fail","F",IF(E11>=80,"A+",IF(E11>=70,"A",IF(E11>=60,"A-",IF(E11>=50,"B",IF(E11>=40,"C",IF(E11>=33,"D","F"))))))))) | H11: =(IF(E11="","",IF(G11="F",0,IF(E11>=80,5,IF(E11>=70,4,IF(E11>=60,3.5,IF(E11>=50,3,IF(E11>=40,2,IF(E11>=33,1,0)))))))))
A12: ='Student Basic Info'!A12 -> 511 | B12: 12 | C12: 7 | D12: 24 | E12: =IF(B12+C12+D12=0, "", B12+C12+D12) -> 43 | F12: =IF(E12="","", IF(AND(B12 >=8,C12>=17,D12>=8),"Pass","Fail")) -> Fail | G12: =(IF(E12="","",IF(F12="Fail","F",IF(E12>=80,"A+",IF(E12>=70,"A",IF(E12>=60,"A-",IF(E12>=50,"B",IF(E12>=40,"C",IF(E12>=33,"D","F"))))))))) -> F | H12: =(IF(E12="","",IF(G12="F",0,IF(E12>=80,5,IF(E12>=70,4,IF(E12>=60,3.5,IF(E12>=50,3,IF(E12>=40,2,IF(E12>=33,1,0))))))))) -> 0
A13: ='Student Basic Info'!A13 -> 512 | B13: 7 | C13: 6 | D13: 20 | E13: =IF(B13+C13+D13=0, "", B13+C13+D13) -> 33 | F13: =IF(E13="","", IF(AND(B13 >=8,C13>=17,D13>=8),"Pass","Fail")) -> Fail | G13: =(IF(E13="","",IF(F13="Fail","F",IF(E13>=80,"A+",IF(E13>=70,"A",IF(E13>=60,"A-",IF(E13>=50,"B",IF(E13>=40,"C",IF(E13>=33,"D","F"))))))))) -> F | H13: =(IF(E13="","",IF(G13="F",0,IF(E13>=80,5,IF(E13>=70,4,IF(E13>=60,3.5,IF(E13>=50,3,IF(E13>=40,2,IF(E13>=33,1,0))))))))) -> 0
A14: ='Student Basic Info'!A14 -> 513 | B14: 13 | C14: 8 | D14: 24 | E14: =IF(B14+C14+D14=0, "", B14+C14+D14) -> 45 | F14: =IF(E14="","", IF(AND(B14 >=8,C14>=17,D14>=8),"Pass","Fail")) -> Fail | G14: =(IF(E14="","",IF(F14="Fail","F",IF(E14>=80,"A+",IF(E14>=70,"A",IF(E14>=60,"A-",IF(E14>=50,"B",IF(E14>=40,"C",IF(E14>=33,"D","F"))))))))) -> F | H14: =(IF(E14="","",IF(G14="F",0,IF(E14>=80,5,IF(E14>=70,4,IF(E14>=60,3.5,IF(E14>=50,3,IF(E14>=40,2,IF(E14>=33,1,0))))))))) -> 0
A15: ='Student Basic Info'!A15 -> 514 | E15: =IF(B15+C15+D15=0, "", B15+C15+D15) | F15: =IF(E15="","", IF(AND(B15 >=8,C15>=17,D15>=8),"Pass","Fail")) | G15: =(IF(E15="","",IF(F15="Fail","F",IF(E15>=80,"A+",IF(E15>=70,"A",IF(E15>=60,"A-",IF(E15>=50,"B",IF(E15>=40,"C",IF(E15>=33,"D","F"))))))))) | H15: =(IF(E15="","",IF(G15="F",0,IF(E15>=80,5,IF(E15>=70,4,IF(E15>=60,3.5,IF(E15>=50,3,IF(E15>=40,2,IF(E15>=33,1,0)))))))))
A16: ='Student Basic Info'!A16 -> 515 | B16: 12 | C16: 27 | D16: 18 | E16: =IF(B16+C16+D16=0, "", B16+C16+D16) -> 57 | F16: =IF(E16="","", IF(AND(B16 >=8,C16>=17,D16>=8),"Pass","Fail")) -> Pass | G16: =(IF(E16="","",IF(F16="Fail","F",IF(E16>=80,"A+",IF(E16>=70,"A",IF(E16>=60,"A-",IF(E16>=50,"B",IF(E16>=40,"C",IF(E16>=33,"D","F"))))))))) -> B | H16: =(IF(E16="","",IF(G16="F",0,IF(E16>=80,5,IF(E16>=70,4,IF(E16>=60,3.5,IF(E16>=50,3,IF(E16>=40,2,IF(E16>=33,1,0))))))))) -> 3
A17: ='Student Basic Info'!A17 -> 516 | B17: 15 | C17: 39 | D17: 24 | E17: =IF(B17+C17+D17=0, "", B17+C17+D17) -> 78 | F17: =IF(E17="","", IF(AND(B17 >=8,C17>=17,D17>=8),"Pass","Fail")) -> Pass | G17: =(IF(E17="","",IF(F17="Fail","F",IF(E17>=80,"A+",IF(E17>=70,"A",IF(E17>=60,"A-",IF(E17>=50,"B",IF(E17>=40,"C",IF(E17>=33,"D","F"))))))))) -> A | H17: =(IF(E17="","",IF(G17="F",0,IF(E17>=80,5,IF(E17>=70,4,IF(E17>=60,3.5,IF(E17>=50,3,IF(E17>=40,2,IF(E17>=33,1,0))))))))) -> 4
A18: ='Student Basic Info'!A18 -> 517 | E18: =IF(B18+C18+D18=0, "", B18+C18+D18) | F18: =IF(E18="","", IF(AND(B18 >=8,C18>=17,D18>=8),"Pass","Fail")) | G18: =(IF(E18="","",IF(F18="Fail","F",IF(E18>=80,"A+",IF(E18>=70,"A",IF(E18>=60,"A-",IF(E18>=50,"B",IF(E18>=40,"C",IF(E18>=33,"D","F"))))))))) | H18: =(IF(E18="","",IF(G18="F",0,IF(E18>=80,5,IF(E18>=70,4,IF(E18>=60,3.5,IF(E18>=50,3,IF(E18>=40,2,IF(E18>=33,1,0)))))))))
A19: ='Student Basic Info'!A19 -> 518 | E19: =IF(B19+C19+D19=0, "", B19+C19+D19) | F19: =IF(E19="","", IF(AND(B19 >=8,C19>=17,D19>=8),"Pass","Fail")) | G19: =(IF(E19="","",IF(F19="Fail","F",IF(E19>=80,"A+",IF(E19>=70,"A",IF(E19>=60,"A-",IF(E19>=50,"B",IF(E19>=40,"C",IF(E19>=33,"D","F"))))))))) | H19: =(IF(E19="","",IF(G19="F",0,IF(E19>=80,5,IF(E19>=70,4,IF(E19>=60,3.5,IF(E19>=50,3,IF(E19>=40,2,IF(E19>=33,1,0)))))))))
A20: ='Student Basic Info'!A20 -> 519 | B20: 15 | C20: 17 | D20: 23 | E20: =IF(B20+C20+D20=0, "", B20+C20+D20) -> 55 | F20: =IF(E20="","", IF(AND(B20 >=8,C20>=17,D20>=8),"Pass","Fail")) -> Pass | G20: =(IF(E20="","",IF(F20="Fail","F",IF(E20>=80,"A+",IF(E20>=70,"A",IF(E20>=60,"A-",IF(E20>=50,"B",IF(E20>=40,"C",IF(E20>=33,"D","F"))))))))) -> B | H20: =(IF(E20="","",IF(G20="F",0,IF(E20>=80,5,IF(E20>=70,4,IF(E20>=60,3.5,IF(E20>=50,3,IF(E20>=40,2,IF(E20>=33,1,0))))))))) -> 3
A21: ='Student Basic Info'!A21 -> 520 | B21: 14 | C21: 2 | D21: 24 | E21: =IF(B21+C21+D21=0, "", B21+C21+D21) -> 40 | F21: =IF(E21="","", IF(AND(B21 >=8,C21>=17,D21>=8),"Pass","Fail")) -> Fail | G21: =(IF(E21="","",IF(F21="Fail","F",IF(E21>=80,"A+",IF(E21>=70,"A",IF(E21>=60,"A-",IF(E21>=50,"B",IF(E21>=40,"C",IF(E21>=33,"D","F"))))))))) -> F | H21: =(IF(E21="","",IF(G21="F",0,IF(E21>=80,5,IF(E21>=70,4,IF(E21>=60,3.5,IF(E21>=50,3,IF(E21>=40,2,IF(E21>=33,1,0))))))))) -> 0
A22: ='Student Basic Info'!A22 -> 521 | E22: =IF(B22+C22+D22=0, "", B22+C22+D22) | F22: =IF(E22="","", IF(AND(B22 >=8,C22>=17,D22>=8),"Pass","Fail")) | G22: =(IF(E22="","",IF(F22="Fail","F",IF(E22>=80,"A+",IF(E22>=70,"A",IF(E22>=60,"A-",IF(E22>=50,"B",IF(E22>=40,"C",IF(E22>=33,"D","F"))))))))) | H22: =(IF(E22="","",IF(G22="F",0,IF(E22>=80,5,IF(E22>=70,4,IF(E22>=60,3.5,IF(E22>=50,3,IF(E22>=40,2,IF(E22>=33,1,0)))))))))
A23: ='Student Basic Info'!A23 -> 522 | B23: 19 | C23: 40 | D23: 24 | E23: =IF(B23+C23+D23=0, "", B23+C23+D23) -> 83 | F23: =IF(E23="","", IF(AND(B23 >=8,C23>=17,D23>=8),"Pass","Fail")) -> Pass | G23: =(IF(E23="","",IF(F23="Fail","F",IF(E23>=80,"A+",IF(E23>=70,"A",IF(E23>=60,"A-",IF(E23>=50,"B",IF(E23>=40,"C",IF(E23>=33,"D","F"))))))))) -> A+ | H23: =(IF(E23="","",IF(G23="F",0,IF(E23>=80,5,IF(E23>=70,4,IF(E23>=60,3.5,IF(E23>=50,3,IF(E23>=40,2,IF(E23>=33,1,0))))))))) -> 5
A24: ='Student Basic Info'!A24 -> 523 | B24: 10 | C24: 11 | D24: 20 | E24: =IF(B24+C24+D24=0, "", B24+C24+D24) -> 41 | F24: =IF(E24="","", IF(AND(B24 >=8,C24>=17,D24>=8),"Pass","Fail")) -> Fail | G24: =(IF(E24="","",IF(F24="Fail","F",IF(E24>=80,"A+",IF(E24>=70,"A",IF(E24>=60,"A-",IF(E24>=50,"B",IF(E24>=40,"C",IF(E24>=33,"D","F"))))))))) -> F | H24: =(IF(E24="","",IF(G24="F",0,IF(E24>=80,5,IF(E24>=70,4,IF(E24>=60,3.5,IF(E24>=50,3,IF(E24>=40,2,IF(E24>=33,1,0))))))))) -> 0
A25: ='Student Basic Info'!A25 -> 524 | B25: 13 | C25: 21 | D25: 20 | E25: =IF(B25+C25+D25=0, "", B25+C25+D25) -> 54 | F25: =IF(E25="","", IF(AND(B25 >=8,C25>=17,D25>=8),"Pass","Fail")) -> Pass | G25: =(IF(E25="","",IF(F25="Fail","F",IF(E25>=80,"A+",IF(E25>=70,"A",IF(E25>=60,"A-",IF(E25>=50,"B",IF(E25>=40,"C",IF(E25>=33,"D","F"))))))))) -> B | H25: =(IF(E25="","",IF(G25="F",0,IF(E25>=80,5,IF(E25>=70,4,IF(E25>=60,3.5,IF(E25>=50,3,IF(E25>=40,2,IF(E25>=33,1,0))))))))) -> 3
A26: ='Student Basic Info'!A26 -> 525 | E26: =IF(B26+C26+D26=0, "", B26+C26+D26) | F26: =IF(E26="","", IF(AND(B26 >=8,C26>=17,D26>=8),"Pass","Fail")) | G26: =(IF(E26="","",IF(F26="Fail","F",IF(E26>=80,"A+",IF(E26>=70,"A",IF(E26>=60,"A-",IF(E26>=50,"B",IF(E26>=40,"C",IF(E26>=33,"D","F"))))))))) | H26: =(IF(E26="","",IF(G26="F",0,IF(E26>=80,5,IF(E26>=70,4,IF(E26>=60,3.5,IF(E26>=50,3,IF(E26>=40,2,IF(E26>=33,1,0)))))))))
A27: ='Student Basic Info'!A27 -> 526 | B27: 16 | C27: 19 | D27: 18 | E27: =IF(B27+C27+D27=0, "", B27+C27+D27) -> 53 | F27: =IF(E27="","", IF(AND(B27 >=8,C27>=17,D27>=8),"Pass","Fail")) -> Pass | G27: =(IF(E27="","",IF(F27="Fail","F",IF(E27>=80,"A+",IF(E27>=70,"A",IF(E27>=60,"A-",IF(E27>=50,"B",IF(E27>=40,"C",IF(E27>=33,"D","F"))))))))) -> B | H27: =(IF(E27="","",IF(G27="F",0,IF(E27>=80,5,IF(E27>=70,4,IF(E27>=60,3.5,IF(E27>=50,3,IF(E27>=40,2,IF(E27>=33,1,0))))))))) -> 3
A28: ='Student Basic Info'!A28 -> 527 | E28: =IF(B28+C28+D28=0, "", B28+C28+D28) | F28: =IF(E28="","", IF(AND(B28 >=8,C28>=17,D28>=8),"Pass","Fail")) | G28: =(IF(E28="","",IF(F28="Fail","F",IF(E28>=80,"A+",IF(E28>=70,"A",IF(E28>=60,"A-",IF(E28>=50,"B",IF(E28>=40,"C",IF(E28>=33,"D","F"))))))))) | H28: =(IF(E28="","",IF(G28="F",0,IF(E28>=80,5,IF(E28>=70,4,IF(E28>=60,3.5,IF(E28>=50,3,IF(E28>=40,2,IF(E28>=33,1,0)))))))))
A29: ='Student Basic Info'!A29 -> 528 | B29: 16 | C29: 36 | D29: 20 | E29: =IF(B29+C29+D29=0, "", B29+C29+D29) -> 72 | F29: =IF(E29="","", IF(AND(B29 >=8,C29>=17,D29>=8),"Pass","Fail")) -> Pass | G29: =(IF(E29="","",IF(F29="Fail","F",IF(E29>=80,"A+",IF(E29>=70,"A",IF(E29>=60,"A-",IF(E29>=50,"B",IF(E29>=40,"C",IF(E29>=33,"D","F"))))))))) -> A | H29: =(IF(E29="","",IF(G29="F",0,IF(E29>=80,5,IF(E29>=70,4,IF(E29>=60,3.5,IF(E29>=50,3,IF(E29>=40,2,IF(E29>=33,1,0))))))))) -> 4
A30: ='Student Basic Info'!A30 -> 529 | B30: 15 | C30: 2 | D30: 24 | E30: =IF(B30+C30+D30=0, "", B30+C30+D30) -> 41 | F30: =IF(E30="","", IF(AND(B30 >=8,C30>=17,D30>=8),"Pass","Fail")) -> Fail | G30: =(IF(E30="","",IF(F30="Fail","F",IF(E30>=80,"A+",IF(E30>=70,"A",IF(E30>=60,"A-",IF(E30>=50,"B",IF(E30>=40,"C",IF(E30>=33,"D","F"))))))))) -> F | H30: =(IF(E30="","",IF(G30="F",0,IF(E30>=80,5,IF(E30>=70,4,IF(E30>=60,3.5,IF(E30>=50,3,IF(E30>=40,2,IF(E30>=33,1,0))))))))) -> 0
A31: ='Student Basic Info'!A31 -> 530 | E31: =IF(B31+C31+D31=0, "", B31+C31+D31) | F31: =IF(E31="","", IF(AND(B31 >=8,C31>=17,D31>=8),"Pass","Fail")) | G31: =(IF(E31="","",IF(F31="Fail","F",IF(E31>=80,"A+",IF(E31>=70,"A",IF(E31>=60,"A-",IF(E31>=50,"B",IF(E31>=40,"C",IF(E31>=33,"D","F"))))))))) | H31: =(IF(E31="","",IF(G31="F",0,IF(E31>=80,5,IF(E31>=70,4,IF(E31>=60,3.5,IF(E31>=50,3,IF(E31>=40,2,IF(E31>=33,1,0)))))))))
A32: ='Student Basic Info'!A32 -> 531 | B32: 9 | C32: 8 | D32: 8 | E32: =IF(B32+C32+D32=0, "", B32+C32+D32) -> 25 | F32: =IF(E32="","", IF(AND(B32 >=8,C32>=17,D32>=8),"Pass","Fail")) -> Fail | G32: =(IF(E32="","",IF(F32="Fail","F",IF(E32>=80,"A+",IF(E32>=70,"A",IF(E32>=60,"A-",IF(E32>=50,"B",IF(E32>=40,"C",IF(E32>=33,"D","F"))))))))) -> F | H32: =(IF(E32="","",IF(G32="F",0,IF(E32>=80,5,IF(E32>=70,4,IF(E32>=60,3.5,IF(E32>=50,3,IF(E32>=40,2,IF(E32>=33,1,0))))))))) -> 0
A33: ='Student Basic Info'!A33 -> 532 | E33: =IF(B33+C33+D33=0, "", B33+C33+D33) | F33: =IF(E33="","", IF(AND(B33 >=8,C33>=17,D33>=8),"Pass","Fail")) | G33: =(IF(E33="","",IF(F33="Fail","F",IF(E33>=80,"A+",IF(E33>=70,"A",IF(E33>=60,"A-",IF(E33>=50,"B",IF(E33>=40,"C",IF(E33>=33,"D","F"))))))))) | H33: =(IF(E33="","",IF(G33="F",0,IF(E33>=80,5,IF(E33>=70,4,IF(E33>=60,3.5,IF(E33>=50,3,IF(E33>=40,2,IF(E33>=33,1,0)))))))))
A34: ='Student Basic Info'!A34 -> 533 | E34: =IF(B34+C34+D34=0, "", B34+C34+D34) | F34: =IF(E34="","", IF(AND(B34 >=8,C34>=17,D34>=8),"Pass","Fail")) | G34: =(IF(E34="","",IF(F34="Fail","F",IF(E34>=80,"A+",IF(E34>=70,"A",IF(E34>=60,"A-",IF(E34>=50,"B",IF(E34>=40,"C",IF(E34>=33,"D","F"))))))))) | H34: =(IF(E34="","",IF(G34="F",0,IF(E34>=80,5,IF(E34>=70,4,IF(E34>=60,3.5,IF(E34>=50,3,IF(E34>=40,2,IF(E34>=33,1,0)))))))))
A35: ='Student Basic Info'!A35 -> 534 | E35: =IF(B35+C35+D35=0, "", B35+C35+D35) | F35: =IF(E35="","", IF(AND(B35 >=8,C35>=17,D35>=8),"Pass","Fail")) | G35: =(IF(E35="","",IF(F35="Fail","F",IF(E35>=80,"A+",IF(E35>=70,"A",IF(E35>=60,"A-",IF(E35>=50,"B",IF(E35>=40,"C",IF(E35>=33,"D","F"))))))))) | H35: =(IF(E35="","",IF(G35="F",0,IF(E35>=80,5,IF(E35>=70,4,IF(E35>=60,3.5,IF(E35>=50,3,IF(E35>=40,2,IF(E35>=33,1,0)))))))))
A36: ='Student Basic Info'!A36 -> 535 | E36: =IF(B36+C36+D36=0, "", B36+C36+D36) | F36: =IF(E36="","", IF(AND(B36 >=8,C36>=17,D36>=8),"Pass","Fail")) | G36: =(IF(E36="","",IF(F36="Fail","F",IF(E36>=80,"A+",IF(E36>=70,"A",IF(E36>=60,"A-",IF(E36>=50,"B",IF(E36>=40,"C",IF(E36>=33,"D","F"))))))))) | H36: =(IF(E36="","",IF(G36="F",0,IF(E36>=80,5,IF(E36>=70,4,IF(E36>=60,3.5,IF(E36>=50,3,IF(E36>=40,2,IF(E36>=33,1,0)))))))))
A37: ='Student Basic Info'!A37 -> 536 | B37: 9 | C37: 6 | D37: 25 | E37: =IF(B37+C37+D37=0, "", B37+C37+D37) -> 40 | F37: =IF(E37="","", IF(AND(B37 >=8,C37>=17,D37>=8),"Pass","Fail")) -> Fail | G37: =(IF(E37="","",IF(F37="Fail","F",IF(E37>=80,"A+",IF(E37>=70,"A",IF(E37>=60,"A-",IF(E37>=50,"B",IF(E37>=40,"C",IF(E37>=33,"D","F"))))))))) -> F | H37: =(IF(E37="","",IF(G37="F",0,IF(E37>=80,5,IF(E37>=70,4,IF(E37>=60,3.5,IF(E37>=50,3,IF(E37>=40,2,IF(E37>=33,1,0))))))))) -> 0
A38: ='Student Basic Info'!A38 -> 537 | B38: 12 | C38: 9 | D38: 8 | E38: =IF(B38+C38+D38=0, "", B38+C38+D38) -> 29 | F38: =IF(E38="","", IF(AND(B38 >=8,C38>=17,D38>=8),"Pass","Fail")) -> Fail | G38: =(IF(E38="","",IF(F38="Fail","F",IF(E38>=80,"A+",IF(E38>=70,"A",IF(E38>=60,"A-",IF(E38>=50,"B",IF(E38>=40,"C",IF(E38>=33,"D","F"))))))))) -> F | H38: =(IF(E38="","",IF(G38="F",0,IF(E38>=80,5,IF(E38>=70,4,IF(E38>=60,3.5,IF(E38>=50,3,IF(E38>=40,2,IF(E38>=33,1,0))))))))) -> 0
A39: ='Student Basic Info'!A39 -> 538 | B39: 12 | C39: 7 | D39: 24 | E39: =IF(B39+C39+D39=0, "", B39+C39+D39) -> 43 | F39: =IF(E39="","", IF(AND(B39 >=8,C39>=17,D39>=8),"Pass","Fail")) -> Fail | G39: =(IF(E39="","",IF(F39="Fail","F",IF(E39>=80,"A+",IF(E39>=70,"A",IF(E39>=60,"A-",IF(E39>=50,"B",IF(E39>=40,"C",IF(E39>=33,"D","F"))))))))) -> F | H39: =(IF(E39="","",IF(G39="F",0,IF(E39>=80,5,IF(E39>=70,4,IF(E39>=60,3.5,IF(E39>=50,3,IF(E39>=40,2,IF(E39>=33,1,0))))))))) -> 0
A40: ='Student Basic Info'!A40 -> 539 | B40: 10 | C40: 4 | D40: 8 | E40: =IF(B40+C40+D40=0, "", B40+C40+D40) -> 22 | F40: =IF(E40="","", IF(AND(B40 >=8,C40>=17,D40>=8),"Pass","Fail")) -> Fail | G40: =(IF(E40="","",IF(F40="Fail","F",IF(E40>=80,"A+",IF(E40>=70,"A",IF(E40>=60,"A-",IF(E40>=50,"B",IF(E40>=40,"C",IF(E40>=33,"D","F"))))))))) -> F | H40: =(IF(E40="","",IF(G40="F",0,IF(E40>=80,5,IF(E40>=70,4,IF(E40>=60,3.5,IF(E40>=50,3,IF(E40>=40,2,IF(E40>=33,1,0))))))))) -> 0
...

Sheet Accounting
A1: Roll | B1: Marks MCQ | C1: Marks CQ | D1: Total Marks | E1: Result | F1: Grade | G1: GPA
A2: ='Student Basic Info'!A2 -> 501 | D2: =IF(B2+C2=0, "", B2+C2) | E2: =IF(D2="","", IF(AND(B2 >=10,C2>=23),"Pass","Fail")) | F2: =(IF(D2="","",IF(E2="Fail","F",IF(D2>=80,"A+",IF(D2>=70,"A",IF(D2>=60,"A-",IF(D2>=50,"B",IF(D2>=40,"C",IF(D2>=33,"D","F"))))))))) | G2: =(IF(D2="","",IF(F2="F",0,IF(D2>=80,5,IF(D2>=70,4,IF(D2>=60,3.5,IF(D2>=50,3,IF(D2>=40,2,IF(D2>=33,1,0)))))))))
A3: ='Student Basic Info'!A3 -> 502 | D3: =IF(B3+C3=0, "", B3+C3) | E3: =IF(D3="","", IF(AND(B3 >=10,C3>=23),"Pass","Fail")) | F3: =(IF(D3="","",IF(E3="Fail","F",IF(D3>=80,"A+",IF(D3>=70,"A",IF(D3>=60,"A-",IF(D3>=50,"B",IF(D3>=40,"C",IF(D3>=33,"D","F"))))))))) | G3: =(IF(D3="","",IF(F3="F",0,IF(D3>=80,5,IF(D3>=70,4,IF(D3>=60,3.5,IF(D3>=50,3,IF(D3>=40,2,IF(D3>=33,1,0)))))))))
